2025-06-29 21:41:46,971 - database - DEBUG - Creating new database session
2025-06-29 21:41:46,996 - database - ERROR - Error in database session: 401: Could not validate credentials
Traceback (most recent call last):
  File "C:\Users\Dhanush\FASTAPI\app\core\security.py", line 93, in decode_token
    payload = jwt.decode(token, settings.SECRET_KEY, algorithms=[settings.ALGORITHM])
  File "C:\Users\Dhanush\FASTAPI\venv\Lib\site-packages\jose\jwt.py", line 174, in decode
    _validate_claims(
    ~~~~~~~~~~~~~~~~^
        claims,
        ^^^^^^^
    ...<5 lines>...
        options=defaults,
        ^^^^^^^^^^^^^^^^^
    )
    ^
  File "C:\Users\Dhanush\FASTAPI\venv\Lib\site-packages\jose\jwt.py", line 497, in _validate_claims
    _validate_exp(claims, leeway=leeway)
    ~~~~~~~~~~~~~^^^^^^^^^^^^^^^^^^^^^^^
  File "C:\Users\Dhanush\FASTAPI\venv\Lib\site-packages\jose\jwt.py", line 331, in _validate_exp
    raise ExpiredSignatureError("Signature has expired.")
jose.exceptions.ExpiredSignatureError: Signature has expired.

During handling of the above exception, another exception occurred:

Traceback (most recent call last):
  File "C:\Users\Dhanush\FASTAPI\app\core\security.py", line 371, in get_user_from_service_or_user_token
    payload = decode_token(token)
  File "C:\Users\Dhanush\FASTAPI\app\core\security.py", line 98, in decode_token
    raise JWTError("Could not validate credentials")
jose.exceptions.JWTError: Could not validate credentials

During handling of the above exception, another exception occurred:

Traceback (most recent call last):
  File "C:\Users\Dhanush\FASTAPI\app\database\session.py", line 65, in get_db
    yield session
  File "C:\Users\Dhanush\FASTAPI\venv\Lib\site-packages\fastapi\routing.py", line 291, in app
    solved_result = await solve_dependencies(
                    ^^^^^^^^^^^^^^^^^^^^^^^^^
    ...<6 lines>...
    )
    ^
  File "C:\Users\Dhanush\FASTAPI\venv\Lib\site-packages\fastapi\dependencies\utils.py", line 638, in solve_dependencies
    solved = await call(**solved_result.values)
             ^^^^^^^^^^^^^^^^^^^^^^^^^^^^^^^^^^
  File "C:\Users\Dhanush\FASTAPI\app\core\security.py", line 424, in get_user_from_service_or_user_token
    raise HTTPException(
    ...<3 lines>...
    )
fastapi.exceptions.HTTPException: 401: Could not validate credentials
2025-06-29 21:41:47,023 - database - INFO - Session rolled back due to error
2025-06-29 21:41:47,023 - database - DEBUG - Closing database session
2025-06-29 21:41:47,032 - database - DEBUG - Creating new database session
2025-06-29 21:41:47,044 - database - ERROR - Error in database session: 401: Could not validate credentials
Traceback (most recent call last):
  File "C:\Users\Dhanush\FASTAPI\app\core\security.py", line 93, in decode_token
    payload = jwt.decode(token, settings.SECRET_KEY, algorithms=[settings.ALGORITHM])
  File "C:\Users\Dhanush\FASTAPI\venv\Lib\site-packages\jose\jwt.py", line 174, in decode
    _validate_claims(
    ~~~~~~~~~~~~~~~~^
        claims,
        ^^^^^^^
    ...<5 lines>...
        options=defaults,
        ^^^^^^^^^^^^^^^^^
    )
    ^
  File "C:\Users\Dhanush\FASTAPI\venv\Lib\site-packages\jose\jwt.py", line 497, in _validate_claims
    _validate_exp(claims, leeway=leeway)
    ~~~~~~~~~~~~~^^^^^^^^^^^^^^^^^^^^^^^
  File "C:\Users\Dhanush\FASTAPI\venv\Lib\site-packages\jose\jwt.py", line 331, in _validate_exp
    raise ExpiredSignatureError("Signature has expired.")
jose.exceptions.ExpiredSignatureError: Signature has expired.

During handling of the above exception, another exception occurred:

Traceback (most recent call last):
  File "C:\Users\Dhanush\FASTAPI\app\core\security.py", line 371, in get_user_from_service_or_user_token
    payload = decode_token(token)
  File "C:\Users\Dhanush\FASTAPI\app\core\security.py", line 98, in decode_token
    raise JWTError("Could not validate credentials")
jose.exceptions.JWTError: Could not validate credentials

During handling of the above exception, another exception occurred:

Traceback (most recent call last):
  File "C:\Users\Dhanush\FASTAPI\app\database\session.py", line 65, in get_db
    yield session
  File "C:\Users\Dhanush\FASTAPI\venv\Lib\site-packages\fastapi\routing.py", line 291, in app
    solved_result = await solve_dependencies(
                    ^^^^^^^^^^^^^^^^^^^^^^^^^
    ...<6 lines>...
    )
    ^
  File "C:\Users\Dhanush\FASTAPI\venv\Lib\site-packages\fastapi\dependencies\utils.py", line 638, in solve_dependencies
    solved = await call(**solved_result.values)
             ^^^^^^^^^^^^^^^^^^^^^^^^^^^^^^^^^^
  File "C:\Users\Dhanush\FASTAPI\app\core\security.py", line 424, in get_user_from_service_or_user_token
    raise HTTPException(
    ...<3 lines>...
    )
fastapi.exceptions.HTTPException: 401: Could not validate credentials
2025-06-29 21:41:47,066 - database - INFO - Session rolled back due to error
2025-06-29 21:41:47,071 - database - DEBUG - Closing database session
2025-06-29 21:41:47,084 - database - DEBUG - Creating new database session
2025-06-29 21:41:47,100 - database - ERROR - Error in database session: 401: Could not validate credentials
Traceback (most recent call last):
  File "C:\Users\Dhanush\FASTAPI\app\core\security.py", line 93, in decode_token
    payload = jwt.decode(token, settings.SECRET_KEY, algorithms=[settings.ALGORITHM])
  File "C:\Users\Dhanush\FASTAPI\venv\Lib\site-packages\jose\jwt.py", line 174, in decode
    _validate_claims(
    ~~~~~~~~~~~~~~~~^
        claims,
        ^^^^^^^
    ...<5 lines>...
        options=defaults,
        ^^^^^^^^^^^^^^^^^
    )
    ^
  File "C:\Users\Dhanush\FASTAPI\venv\Lib\site-packages\jose\jwt.py", line 497, in _validate_claims
    _validate_exp(claims, leeway=leeway)
    ~~~~~~~~~~~~~^^^^^^^^^^^^^^^^^^^^^^^
  File "C:\Users\Dhanush\FASTAPI\venv\Lib\site-packages\jose\jwt.py", line 331, in _validate_exp
    raise ExpiredSignatureError("Signature has expired.")
jose.exceptions.ExpiredSignatureError: Signature has expired.

During handling of the above exception, another exception occurred:

Traceback (most recent call last):
  File "C:\Users\Dhanush\FASTAPI\app\core\security.py", line 281, in get_current_user
    payload = decode_token(token)
  File "C:\Users\Dhanush\FASTAPI\app\core\security.py", line 98, in decode_token
    raise JWTError("Could not validate credentials")
jose.exceptions.JWTError: Could not validate credentials

During handling of the above exception, another exception occurred:

Traceback (most recent call last):
  File "C:\Users\Dhanush\FASTAPI\app\database\session.py", line 65, in get_db
    yield session
  File "C:\Users\Dhanush\FASTAPI\venv\Lib\site-packages\fastapi\routing.py", line 291, in app
    solved_result = await solve_dependencies(
                    ^^^^^^^^^^^^^^^^^^^^^^^^^
    ...<6 lines>...
    )
    ^
  File "C:\Users\Dhanush\FASTAPI\venv\Lib\site-packages\fastapi\dependencies\utils.py", line 638, in solve_dependencies
    solved = await call(**solved_result.values)
             ^^^^^^^^^^^^^^^^^^^^^^^^^^^^^^^^^^
  File "C:\Users\Dhanush\FASTAPI\app\core\security.py", line 326, in get_current_user
    raise credentials_exception
fastapi.exceptions.HTTPException: 401: Could not validate credentials
2025-06-29 21:41:47,113 - database - INFO - Session rolled back due to error
2025-06-29 21:41:47,113 - database - DEBUG - Closing database session
2025-06-29 21:41:47,125 - database - DEBUG - Creating new database session
2025-06-29 21:41:47,135 - database - ERROR - Error in database session: 401: Could not validate credentials
Traceback (most recent call last):
  File "C:\Users\Dhanush\FASTAPI\app\core\security.py", line 93, in decode_token
    payload = jwt.decode(token, settings.SECRET_KEY, algorithms=[settings.ALGORITHM])
  File "C:\Users\Dhanush\FASTAPI\venv\Lib\site-packages\jose\jwt.py", line 174, in decode
    _validate_claims(
    ~~~~~~~~~~~~~~~~^
        claims,
        ^^^^^^^
    ...<5 lines>...
        options=defaults,
        ^^^^^^^^^^^^^^^^^
    )
    ^
  File "C:\Users\Dhanush\FASTAPI\venv\Lib\site-packages\jose\jwt.py", line 497, in _validate_claims
    _validate_exp(claims, leeway=leeway)
    ~~~~~~~~~~~~~^^^^^^^^^^^^^^^^^^^^^^^
  File "C:\Users\Dhanush\FASTAPI\venv\Lib\site-packages\jose\jwt.py", line 331, in _validate_exp
    raise ExpiredSignatureError("Signature has expired.")
jose.exceptions.ExpiredSignatureError: Signature has expired.

During handling of the above exception, another exception occurred:

Traceback (most recent call last):
  File "C:\Users\Dhanush\FASTAPI\app\core\security.py", line 281, in get_current_user
    payload = decode_token(token)
  File "C:\Users\Dhanush\FASTAPI\app\core\security.py", line 98, in decode_token
    raise JWTError("Could not validate credentials")
jose.exceptions.JWTError: Could not validate credentials

During handling of the above exception, another exception occurred:

Traceback (most recent call last):
  File "C:\Users\Dhanush\FASTAPI\app\database\session.py", line 65, in get_db
    yield session
  File "C:\Users\Dhanush\FASTAPI\venv\Lib\site-packages\fastapi\routing.py", line 291, in app
    solved_result = await solve_dependencies(
                    ^^^^^^^^^^^^^^^^^^^^^^^^^
    ...<6 lines>...
    )
    ^
  File "C:\Users\Dhanush\FASTAPI\venv\Lib\site-packages\fastapi\dependencies\utils.py", line 638, in solve_dependencies
    solved = await call(**solved_result.values)
             ^^^^^^^^^^^^^^^^^^^^^^^^^^^^^^^^^^
  File "C:\Users\Dhanush\FASTAPI\app\core\security.py", line 326, in get_current_user
    raise credentials_exception
fastapi.exceptions.HTTPException: 401: Could not validate credentials
2025-06-29 21:41:47,154 - database - INFO - Session rolled back due to error
2025-06-29 21:41:47,154 - database - DEBUG - Closing database session
2025-06-29 21:41:50,403 - database - DEBUG - Creating new database session
2025-06-29 21:41:51,269 - database - DEBUG - Database session used successfully
2025-06-29 21:41:51,270 - database - DEBUG - Closing database session
2025-06-29 21:41:52,370 - database - DEBUG - Creating new database session
2025-06-29 21:41:52,395 - database - DEBUG - Database session used successfully
2025-06-29 21:41:52,398 - database - DEBUG - Closing database session
2025-06-29 21:41:52,418 - database - DEBUG - Creating new database session
2025-06-29 21:41:52,447 - database - DEBUG - Creating new database session
2025-06-29 21:41:52,476 - database - DEBUG - Database session used successfully
2025-06-29 21:41:52,479 - database - DEBUG - Closing database session
2025-06-29 21:41:52,704 - database - DEBUG - Creating new database session
2025-06-29 21:41:52,821 - database - DEBUG - Database session used successfully
2025-06-29 21:41:52,823 - database - DEBUG - Closing database session
2025-06-29 21:41:53,996 - database - DEBUG - Database session used successfully
2025-06-29 21:41:54,001 - database - DEBUG - Closing database session
2025-06-29 21:41:54,047 - database - DEBUG - Creating new database session
2025-06-29 21:41:54,371 - database - DEBUG - Creating new database session
2025-06-29 21:41:55,999 - database - DEBUG - Database session used successfully
2025-06-29 21:41:56,000 - database - DEBUG - Closing database session
2025-06-29 21:41:56,240 - database - DEBUG - Creating new database session
2025-06-29 21:41:56,312 - database - DEBUG - Database session used successfully
2025-06-29 21:41:56,322 - database - DEBUG - Closing database session
2025-06-29 21:42:52,082 - database - DEBUG - Database session used successfully
2025-06-29 21:42:52,082 - database - DEBUG - Closing database session
2025-06-29 21:42:58,677 - database - DEBUG - Creating new database session
2025-06-29 21:42:58,683 - database - DEBUG - Creating new database session
2025-06-29 21:42:58,707 - database - DEBUG - Closing database session
2025-06-29 21:42:58,709 - database - DEBUG - Closing database session
2025-06-29 21:43:03,262 - database - DEBUG - Creating new database session
2025-06-29 21:43:03,266 - database - DEBUG - Creating new database session
2025-06-29 21:43:03,504 - database - DEBUG - Database session used successfully
2025-06-29 21:43:03,505 - database - DEBUG - Closing database session
2025-06-29 21:43:03,518 - database - DEBUG - Database session used successfully
2025-06-29 21:43:03,519 - database - DEBUG - Closing database session
2025-06-29 21:43:03,524 - database - DEBUG - Creating new database session
2025-06-29 21:43:03,537 - database - DEBUG - Database session used successfully
2025-06-29 21:43:03,538 - database - DEBUG - Closing database session
2025-06-29 21:43:03,606 - database - DEBUG - Creating new database session
2025-06-29 21:43:04,126 - database - DEBUG - Database session used successfully
2025-06-29 21:43:04,127 - database - DEBUG - Closing database session
2025-06-29 21:43:04,139 - database - DEBUG - Creating new database session
2025-06-29 21:43:04,477 - database - DEBUG - Creating new database session
2025-06-29 21:43:04,682 - database - DEBUG - Database session used successfully
2025-06-29 21:43:04,682 - database - DEBUG - Closing database session
2025-06-29 21:43:04,695 - database - DEBUG - Creating new database session
2025-06-29 21:43:04,711 - database - DEBUG - Database session used successfully
2025-06-29 21:43:04,712 - database - DEBUG - Closing database session
2025-06-29 21:43:16,268 - database - DEBUG - Database session used successfully
2025-06-29 21:43:16,268 - database - DEBUG - Closing database session
2025-06-29 21:50:44,437 - database - DEBUG - Creating new database session
2025-06-29 21:50:44,441 - database - DEBUG - Creating new database session
2025-06-29 21:50:44,580 - database - DEBUG - Database session used successfully
2025-06-29 21:50:44,580 - database - DEBUG - Closing database session
2025-06-29 21:51:03,435 - database - DEBUG - Creating new database session
2025-06-29 21:51:03,440 - database - ERROR - Error in database session: 500: An error occurred while refreshing token.
Traceback (most recent call last):
  File "C:\Users\Dhanush\FASTAPI\app\api\v1\endpoints\users.py", line 310, in refresh_access_token
     raise HTTPException(
    ...<3 lines>...
    )
fastapi.exceptions.HTTPException: 401: Invalid or expired refresh token

During handling of the above exception, another exception occurred:

Traceback (most recent call last):
  File "C:\Users\Dhanush\FASTAPI\app\database\session.py", line 65, in get_db
    yield session
  File "C:\Users\Dhanush\FASTAPI\venv\Lib\site-packages\fastapi\routing.py", line 301, in app
    raw_response = await run_endpoint_function(
                   ^^^^^^^^^^^^^^^^^^^^^^^^^^^^
    ...<3 lines>...
    )
    ^
  File "C:\Users\Dhanush\FASTAPI\venv\Lib\site-packages\fastapi\routing.py", line 212, in run_endpoint_function
    return await dependant.call(**values)
           ^^^^^^^^^^^^^^^^^^^^^^^^^^^^^^
  File "C:\Users\Dhanush\FASTAPI\app\api\v1\endpoints\users.py", line 360, in refresh_access_token
    raise HTTPException(
    ...<2 lines>...
    )
fastapi.exceptions.HTTPException: 500: An error occurred while refreshing token.
2025-06-29 21:51:03,442 - database - INFO - Session rolled back due to error
2025-06-29 21:51:03,442 - database - DEBUG - Closing database session
2025-06-29 21:52:01,795 - database - DEBUG - Creating new database session
2025-06-29 21:52:01,804 - database - DEBUG - Database session used successfully
2025-06-29 21:52:01,804 - database - DEBUG - Closing database session
2025-06-29 21:52:39,960 - database - DEBUG - Database session used successfully
2025-06-29 21:52:39,960 - database - DEBUG - Closing database session
2025-06-29 21:58:49,386 - database - DEBUG - Creating new database session
2025-06-29 21:58:50,819 - database - DEBUG - Creating new database session
2025-06-29 21:58:50,829 - database - ERROR - Error in database session: 500: An error occurred while refreshing token.
Traceback (most recent call last):
  File "C:\Users\Dhanush\FASTAPI\app\api\v1\endpoints\users.py", line 310, in refresh_access_token
     raise HTTPException(
    ...<3 lines>...
    )
fastapi.exceptions.HTTPException: 401: Invalid or expired refresh token

During handling of the above exception, another exception occurred:

Traceback (most recent call last):
  File "C:\Users\Dhanush\FASTAPI\app\database\session.py", line 65, in get_db
    yield session
  File "C:\Users\Dhanush\FASTAPI\venv\Lib\site-packages\fastapi\routing.py", line 301, in app
    raw_response = await run_endpoint_function(
                   ^^^^^^^^^^^^^^^^^^^^^^^^^^^^
    ...<3 lines>...
    )
    ^
  File "C:\Users\Dhanush\FASTAPI\venv\Lib\site-packages\fastapi\routing.py", line 212, in run_endpoint_function
    return await dependant.call(**values)
           ^^^^^^^^^^^^^^^^^^^^^^^^^^^^^^
  File "C:\Users\Dhanush\FASTAPI\app\api\v1\endpoints\users.py", line 360, in refresh_access_token
    raise HTTPException(
    ...<2 lines>...
    )
fastapi.exceptions.HTTPException: 500: An error occurred while refreshing token.
2025-06-29 21:58:50,839 - database - INFO - Session rolled back due to error
2025-06-29 21:58:50,840 - database - DEBUG - Closing database session
2025-06-29 21:59:12,753 - database - DEBUG - Database session used successfully
2025-06-29 21:59:12,753 - database - DEBUG - Closing database session
2025-06-29 21:59:34,401 - database - DEBUG - Creating new database session
2025-06-29 21:59:42,566 - database - DEBUG - Creating new database session
2025-06-29 21:59:42,608 - database - DEBUG - Database session used successfully
2025-06-29 21:59:42,609 - database - DEBUG - Closing database session
2025-06-29 21:59:56,370 - database - DEBUG - Creating new database session
2025-06-29 21:59:56,383 - database - ERROR - Error in database session: 500: An error occurred while refreshing token.
Traceback (most recent call last):
  File "C:\Users\Dhanush\FASTAPI\app\api\v1\endpoints\users.py", line 310, in refresh_access_token
     raise HTTPException(
    ...<3 lines>...
    )
fastapi.exceptions.HTTPException: 401: Invalid or expired refresh token

During handling of the above exception, another exception occurred:

Traceback (most recent call last):
  File "C:\Users\Dhanush\FASTAPI\app\database\session.py", line 65, in get_db
    yield session
  File "C:\Users\Dhanush\FASTAPI\venv\Lib\site-packages\fastapi\routing.py", line 301, in app
    raw_response = await run_endpoint_function(
                   ^^^^^^^^^^^^^^^^^^^^^^^^^^^^
    ...<3 lines>...
    )
    ^
  File "C:\Users\Dhanush\FASTAPI\venv\Lib\site-packages\fastapi\routing.py", line 212, in run_endpoint_function
    return await dependant.call(**values)
           ^^^^^^^^^^^^^^^^^^^^^^^^^^^^^^
  File "C:\Users\Dhanush\FASTAPI\app\api\v1\endpoints\users.py", line 360, in refresh_access_token
    raise HTTPException(
    ...<2 lines>...
    )
fastapi.exceptions.HTTPException: 500: An error occurred while refreshing token.
2025-06-29 21:59:56,396 - database - INFO - Session rolled back due to error
2025-06-29 21:59:56,397 - database - DEBUG - Closing database session
2025-06-29 22:00:43,397 - database - DEBUG - Creating new database session
2025-06-29 22:00:43,423 - database - DEBUG - Database session used successfully
2025-06-29 22:00:43,424 - database - DEBUG - Closing database session
2025-06-29 22:01:18,491 - database - DEBUG - Creating new database session
2025-06-29 22:01:18,514 - database - DEBUG - Database session used successfully
2025-06-29 22:01:18,516 - database - DEBUG - Closing database session
2025-06-29 22:02:02,371 - database - DEBUG - Creating new database session
2025-06-29 22:02:02,386 - database - DEBUG - Database session used successfully
2025-06-29 22:02:02,386 - database - DEBUG - Closing database session
2025-06-29 22:02:09,481 - database - DEBUG - Database session used successfully
2025-06-29 22:02:09,481 - database - DEBUG - Closing database session
2025-06-29 22:04:23,382 - database - DEBUG - Creating new database session
2025-06-29 22:04:25,779 - database - DEBUG - Creating new database session
2025-06-29 22:04:25,797 - database - ERROR - Error in database session: 500: An error occurred while refreshing token.
Traceback (most recent call last):
  File "C:\Users\Dhanush\FASTAPI\app\api\v1\endpoints\users.py", line 310, in refresh_access_token
     raise HTTPException(
    ...<3 lines>...
    )
fastapi.exceptions.HTTPException: 401: Invalid or expired refresh token

During handling of the above exception, another exception occurred:

Traceback (most recent call last):
  File "C:\Users\Dhanush\FASTAPI\app\database\session.py", line 65, in get_db
    yield session
  File "C:\Users\Dhanush\FASTAPI\venv\Lib\site-packages\fastapi\routing.py", line 301, in app
    raw_response = await run_endpoint_function(
                   ^^^^^^^^^^^^^^^^^^^^^^^^^^^^
    ...<3 lines>...
    )
    ^
  File "C:\Users\Dhanush\FASTAPI\venv\Lib\site-packages\fastapi\routing.py", line 212, in run_endpoint_function
    return await dependant.call(**values)
           ^^^^^^^^^^^^^^^^^^^^^^^^^^^^^^
  File "C:\Users\Dhanush\FASTAPI\app\api\v1\endpoints\users.py", line 360, in refresh_access_token
    raise HTTPException(
    ...<2 lines>...
    )
fastapi.exceptions.HTTPException: 500: An error occurred while refreshing token.
2025-06-29 22:04:25,806 - database - INFO - Session rolled back due to error
2025-06-29 22:04:25,806 - database - DEBUG - Closing database session
2025-06-29 22:04:35,105 - database - DEBUG - Creating new database session
2025-06-29 22:04:35,220 - database - DEBUG - Database session used successfully
2025-06-29 22:04:35,222 - database - DEBUG - Closing database session
2025-06-29 22:05:08,647 - database - DEBUG - Creating new database session
2025-06-29 22:05:08,659 - database - DEBUG - Database session used successfully
2025-06-29 22:05:08,660 - database - DEBUG - Closing database session
2025-06-29 22:05:22,228 - database - DEBUG - Creating new database session
2025-06-29 22:05:22,233 - database - ERROR - Error in database session: 500: An error occurred while refreshing token.
Traceback (most recent call last):
  File "C:\Users\Dhanush\FASTAPI\app\api\v1\endpoints\users.py", line 310, in refresh_access_token
     raise HTTPException(
    ...<3 lines>...
    )
fastapi.exceptions.HTTPException: 401: Invalid or expired refresh token

During handling of the above exception, another exception occurred:

Traceback (most recent call last):
  File "C:\Users\Dhanush\FASTAPI\app\database\session.py", line 65, in get_db
    yield session
  File "C:\Users\Dhanush\FASTAPI\venv\Lib\site-packages\fastapi\routing.py", line 301, in app
    raw_response = await run_endpoint_function(
                   ^^^^^^^^^^^^^^^^^^^^^^^^^^^^
    ...<3 lines>...
    )
    ^
  File "C:\Users\Dhanush\FASTAPI\venv\Lib\site-packages\fastapi\routing.py", line 212, in run_endpoint_function
    return await dependant.call(**values)
           ^^^^^^^^^^^^^^^^^^^^^^^^^^^^^^
  File "C:\Users\Dhanush\FASTAPI\app\api\v1\endpoints\users.py", line 360, in refresh_access_token
    raise HTTPException(
    ...<2 lines>...
    )
fastapi.exceptions.HTTPException: 500: An error occurred while refreshing token.
2025-06-29 22:05:22,235 - database - INFO - Session rolled back due to error
2025-06-29 22:05:22,235 - database - DEBUG - Closing database session
2025-06-29 22:05:31,647 - database - DEBUG - Creating new database session
2025-06-29 22:05:31,705 - database - DEBUG - Database session used successfully
2025-06-29 22:05:31,708 - database - DEBUG - Closing database session
2025-06-29 22:05:44,434 - database - DEBUG - Creating new database session
2025-06-29 22:05:45,200 - database - DEBUG - Database session used successfully
2025-06-29 22:05:45,204 - database - DEBUG - Closing database session
2025-06-29 22:05:50,474 - database - DEBUG - Creating new database session
2025-06-29 22:05:50,732 - database - DEBUG - Database session used successfully
2025-06-29 22:05:50,737 - database - DEBUG - Closing database session
2025-06-29 22:06:26,868 - database - DEBUG - Creating new database session
2025-06-29 22:06:26,918 - database - DEBUG - Database session used successfully
2025-06-29 22:06:26,928 - database - DEBUG - Closing database session
2025-06-29 22:06:41,432 - database - DEBUG - Creating new database session
2025-06-29 22:06:41,528 - database - ERROR - Error in database session: 500: An error occurred while refreshing token.
Traceback (most recent call last):
  File "C:\Users\Dhanush\FASTAPI\app\api\v1\endpoints\users.py", line 310, in refresh_access_token
     raise HTTPException(
    ...<3 lines>...
    )
fastapi.exceptions.HTTPException: 401: Invalid or expired refresh token

During handling of the above exception, another exception occurred:

Traceback (most recent call last):
  File "C:\Users\Dhanush\FASTAPI\app\database\session.py", line 65, in get_db
    yield session
  File "C:\Users\Dhanush\FASTAPI\venv\Lib\site-packages\fastapi\routing.py", line 301, in app
    raw_response = await run_endpoint_function(
                   ^^^^^^^^^^^^^^^^^^^^^^^^^^^^
    ...<3 lines>...
    )
    ^
  File "C:\Users\Dhanush\FASTAPI\venv\Lib\site-packages\fastapi\routing.py", line 212, in run_endpoint_function
    return await dependant.call(**values)
           ^^^^^^^^^^^^^^^^^^^^^^^^^^^^^^
  File "C:\Users\Dhanush\FASTAPI\app\api\v1\endpoints\users.py", line 360, in refresh_access_token
    raise HTTPException(
    ...<2 lines>...
    )
fastapi.exceptions.HTTPException: 500: An error occurred while refreshing token.
2025-06-29 22:06:41,550 - database - INFO - Session rolled back due to error
2025-06-29 22:06:41,553 - database - DEBUG - Closing database session
2025-06-29 22:06:49,568 - database - DEBUG - Creating new database session
2025-06-29 22:06:49,656 - database - DEBUG - Database session used successfully
2025-06-29 22:06:49,658 - database - DEBUG - Closing database session
2025-06-29 22:06:54,496 - database - DEBUG - Creating new database session
2025-06-29 22:06:55,560 - database - DEBUG - Database session used successfully
2025-06-29 22:06:55,563 - database - DEBUG - Closing database session
2025-06-29 22:07:09,519 - database - DEBUG - Creating new database session
2025-06-29 22:07:09,594 - database - DEBUG - Database session used successfully
2025-06-29 22:07:09,595 - database - DEBUG - Closing database session
2025-06-29 22:07:24,683 - database - DEBUG - Creating new database session
2025-06-29 22:07:24,727 - database - ERROR - Error in database session: 500: An error occurred while refreshing token.
Traceback (most recent call last):
  File "C:\Users\Dhanush\FASTAPI\app\api\v1\endpoints\users.py", line 310, in refresh_access_token
     raise HTTPException(
    ...<3 lines>...
    )
fastapi.exceptions.HTTPException: 401: Invalid or expired refresh token

During handling of the above exception, another exception occurred:

Traceback (most recent call last):
  File "C:\Users\Dhanush\FASTAPI\app\database\session.py", line 65, in get_db
    yield session
  File "C:\Users\Dhanush\FASTAPI\venv\Lib\site-packages\fastapi\routing.py", line 301, in app
    raw_response = await run_endpoint_function(
                   ^^^^^^^^^^^^^^^^^^^^^^^^^^^^
    ...<3 lines>...
    )
    ^
  File "C:\Users\Dhanush\FASTAPI\venv\Lib\site-packages\fastapi\routing.py", line 212, in run_endpoint_function
    return await dependant.call(**values)
           ^^^^^^^^^^^^^^^^^^^^^^^^^^^^^^
  File "C:\Users\Dhanush\FASTAPI\app\api\v1\endpoints\users.py", line 360, in refresh_access_token
    raise HTTPException(
    ...<2 lines>...
    )
fastapi.exceptions.HTTPException: 500: An error occurred while refreshing token.
2025-06-29 22:07:24,746 - database - INFO - Session rolled back due to error
2025-06-29 22:07:24,751 - database - DEBUG - Closing database session
2025-06-29 22:07:26,633 - database - DEBUG - Creating new database session
2025-06-29 22:07:26,747 - database - DEBUG - Database session used successfully
2025-06-29 22:07:26,748 - database - DEBUG - Closing database session
2025-06-29 22:07:26,947 - database - DEBUG - Database session used successfully
2025-06-29 22:07:26,951 - database - DEBUG - Closing database session
2025-06-29 22:07:28,559 - database - DEBUG - Creating new database session
2025-06-29 22:07:29,467 - database - DEBUG - Database session used successfully
2025-06-29 22:07:29,469 - database - DEBUG - Closing database session
2025-06-29 22:07:30,678 - database - DEBUG - Creating new database session
2025-06-29 22:07:30,748 - database - DEBUG - Database session used successfully
2025-06-29 22:07:30,755 - database - DEBUG - Closing database session
2025-06-29 22:07:30,807 - database - DEBUG - Creating new database session
2025-06-29 22:07:30,877 - database - DEBUG - Database session used successfully
2025-06-29 22:07:30,882 - database - DEBUG - Closing database session
2025-06-29 22:07:30,898 - database - DEBUG - Creating new database session
2025-06-29 22:07:32,971 - database - DEBUG - Creating new database session
2025-06-29 22:07:33,159 - database - DEBUG - Database session used successfully
2025-06-29 22:07:33,161 - database - DEBUG - Closing database session
2025-06-29 22:07:33,223 - database - DEBUG - Database session used successfully
2025-06-29 22:07:33,225 - database - DEBUG - Closing database session
2025-06-29 22:07:33,287 - database - DEBUG - Creating new database session
2025-06-29 22:07:33,980 - database - DEBUG - Creating new database session
2025-06-29 22:07:37,332 - database - DEBUG - Creating new database session
2025-06-29 22:07:37,517 - database - DEBUG - Database session used successfully
2025-06-29 22:07:37,527 - database - DEBUG - Closing database session
2025-06-29 22:07:37,820 - database - DEBUG - Database session used successfully
2025-06-29 22:07:37,823 - database - DEBUG - Closing database session
2025-06-29 22:07:37,928 - database - DEBUG - Creating new database session
2025-06-29 22:07:38,097 - database - DEBUG - Database session used successfully
2025-06-29 22:07:38,098 - database - DEBUG - Closing database session
2025-06-29 22:07:47,810 - database - DEBUG - Creating new database session
2025-06-29 22:07:48,405 - database - DEBUG - Database session used successfully
2025-06-29 22:07:48,406 - database - DEBUG - Closing database session
2025-06-29 22:07:58,701 - database - DEBUG - Database session used successfully
2025-06-29 22:07:58,705 - database - DEBUG - Closing database session
2025-06-29 22:14:06,617 - database - DEBUG - Creating new database session
2025-06-29 22:14:06,621 - database - ERROR - Error in database session: 500: An error occurred while refreshing token.
Traceback (most recent call last):
  File "C:\Users\Dhanush\FASTAPI\app\api\v1\endpoints\users.py", line 310, in refresh_access_token
     raise HTTPException(
    ...<3 lines>...
    )
fastapi.exceptions.HTTPException: 401: Invalid or expired refresh token

During handling of the above exception, another exception occurred:

Traceback (most recent call last):
  File "C:\Users\Dhanush\FASTAPI\app\database\session.py", line 65, in get_db
    yield session
  File "C:\Users\Dhanush\FASTAPI\venv\Lib\site-packages\fastapi\routing.py", line 301, in app
    raw_response = await run_endpoint_function(
                   ^^^^^^^^^^^^^^^^^^^^^^^^^^^^
    ...<3 lines>...
    )
    ^
  File "C:\Users\Dhanush\FASTAPI\venv\Lib\site-packages\fastapi\routing.py", line 212, in run_endpoint_function
    return await dependant.call(**values)
           ^^^^^^^^^^^^^^^^^^^^^^^^^^^^^^
  File "C:\Users\Dhanush\FASTAPI\app\api\v1\endpoints\users.py", line 360, in refresh_access_token
    raise HTTPException(
    ...<2 lines>...
    )
fastapi.exceptions.HTTPException: 500: An error occurred while refreshing token.
2025-06-29 22:14:06,624 - database - INFO - Session rolled back due to error
2025-06-29 22:14:06,625 - database - DEBUG - Closing database session
2025-06-29 22:14:10,785 - database - DEBUG - Creating new database session
2025-06-29 22:14:11,183 - database - DEBUG - Database session used successfully
2025-06-29 22:14:11,185 - database - DEBUG - Closing database session
2025-06-29 22:14:11,766 - database - DEBUG - Creating new database session
2025-06-29 22:14:12,619 - database - DEBUG - Creating new database session
2025-06-29 22:14:13,327 - database - DEBUG - Database session used successfully
2025-06-29 22:14:13,331 - database - DEBUG - Closing database session
2025-06-29 22:14:24,196 - database - DEBUG - Database session used successfully
2025-06-29 22:14:24,197 - database - DEBUG - Closing database session
2025-06-29 22:14:26,868 - database - DEBUG - Creating new database session
2025-06-29 22:14:27,840 - database - DEBUG - Database session used successfully
2025-06-29 22:14:27,841 - database - DEBUG - Closing database session
2025-06-29 22:14:29,517 - database - DEBUG - Creating new database session
2025-06-29 22:14:29,531 - database - DEBUG - Database session used successfully
2025-06-29 22:14:29,532 - database - DEBUG - Closing database session
2025-06-29 22:14:29,549 - database - DEBUG - Creating new database session
2025-06-29 22:14:29,675 - database - DEBUG - Creating new database session
2025-06-29 22:14:29,873 - database - DEBUG - Database session used successfully
2025-06-29 22:14:29,882 - database - DEBUG - Closing database session
2025-06-29 22:14:30,928 - database - DEBUG - Creating new database session
2025-06-29 22:14:31,075 - database - DEBUG - Database session used successfully
2025-06-29 22:14:31,081 - database - DEBUG - Closing database session
2025-06-29 22:14:31,976 - database - DEBUG - Database session used successfully
2025-06-29 22:14:31,977 - database - DEBUG - Closing database session
2025-06-29 22:14:32,000 - database - DEBUG - Creating new database session
2025-06-29 22:14:33,112 - database - DEBUG - Database session used successfully
2025-06-29 22:14:33,114 - database - DEBUG - Closing database session
2025-06-29 22:14:34,893 - database - DEBUG - Creating new database session
2025-06-29 22:14:34,904 - database - DEBUG - Database session used successfully
2025-06-29 22:14:34,904 - database - DEBUG - Closing database session
2025-06-29 22:14:35,197 - database - DEBUG - Creating new database session
2025-06-29 22:14:42,358 - database - DEBUG - Creating new database session
2025-06-29 22:14:43,235 - database - DEBUG - Database session used successfully
2025-06-29 22:14:43,240 - database - DEBUG - Closing database session
2025-06-29 22:14:43,892 - database - DEBUG - Creating new database session
2025-06-29 22:14:45,220 - database - DEBUG - Database session used successfully
2025-06-29 22:14:45,221 - database - DEBUG - Closing database session
2025-06-29 22:14:45,873 - database - DEBUG - Creating new database session
2025-06-29 22:14:47,150 - database - DEBUG - Database session used successfully
2025-06-29 22:14:47,152 - database - DEBUG - Closing database session
2025-06-29 22:14:47,896 - database - DEBUG - Creating new database session
2025-06-29 22:14:49,102 - database - DEBUG - Database session used successfully
2025-06-29 22:14:49,103 - database - DEBUG - Closing database session
2025-06-29 22:15:09,079 - database - DEBUG - Creating new database session
2025-06-29 22:15:11,281 - database - DEBUG - Database session used successfully
2025-06-29 22:15:11,282 - database - DEBUG - Closing database session
2025-06-29 22:15:22,123 - database - DEBUG - Database session used successfully
2025-06-29 22:15:22,127 - database - DEBUG - Closing database session
2025-06-29 22:15:22,210 - database - DEBUG - Creating new database session
2025-06-29 22:15:22,228 - database - DEBUG - Database session used successfully
2025-06-29 22:15:22,230 - database - DEBUG - Closing database session
2025-06-29 22:15:22,272 - database - DEBUG - Creating new database session
2025-06-29 22:15:22,300 - database - DEBUG - Creating new database session
2025-06-29 22:15:22,346 - database - DEBUG - Database session used successfully
2025-06-29 22:15:22,348 - database - DEBUG - Closing database session
2025-06-29 22:15:22,406 - database - DEBUG - Creating new database session
2025-06-29 22:15:22,564 - database - DEBUG - Database session used successfully
2025-06-29 22:15:22,568 - database - DEBUG - Closing database session
2025-06-29 22:15:25,308 - database - DEBUG - Database session used successfully
2025-06-29 22:15:25,313 - database - DEBUG - Closing database session
2025-06-29 22:15:25,360 - database - DEBUG - Creating new database session
2025-06-29 22:15:25,805 - database - DEBUG - Creating new database session
2025-06-29 22:15:28,693 - database - DEBUG - Database session used successfully
2025-06-29 22:15:28,735 - database - DEBUG - Closing database session
2025-06-29 22:15:28,928 - database - DEBUG - Creating new database session
2025-06-29 22:15:29,025 - database - DEBUG - Database session used successfully
2025-06-29 22:15:29,028 - database - DEBUG - Closing database session
2025-06-29 22:16:22,533 - database - DEBUG - Creating new database session
2025-06-29 22:16:22,540 - database - ERROR - Error in database session: 500: An error occurred while refreshing token.
Traceback (most recent call last):
  File "C:\Users\Dhanush\FASTAPI\app\api\v1\endpoints\users.py", line 310, in refresh_access_token
     raise HTTPException(
    ...<3 lines>...
    )
fastapi.exceptions.HTTPException: 401: Invalid or expired refresh token

During handling of the above exception, another exception occurred:

Traceback (most recent call last):
  File "C:\Users\Dhanush\FASTAPI\app\database\session.py", line 65, in get_db
    yield session
  File "C:\Users\Dhanush\FASTAPI\venv\Lib\site-packages\fastapi\routing.py", line 301, in app
    raw_response = await run_endpoint_function(
                   ^^^^^^^^^^^^^^^^^^^^^^^^^^^^
    ...<3 lines>...
    )
    ^
  File "C:\Users\Dhanush\FASTAPI\venv\Lib\site-packages\fastapi\routing.py", line 212, in run_endpoint_function
    return await dependant.call(**values)
           ^^^^^^^^^^^^^^^^^^^^^^^^^^^^^^
  File "C:\Users\Dhanush\FASTAPI\app\api\v1\endpoints\users.py", line 360, in refresh_access_token
    raise HTTPException(
    ...<2 lines>...
    )
fastapi.exceptions.HTTPException: 500: An error occurred while refreshing token.
2025-06-29 22:16:22,548 - database - INFO - Session rolled back due to error
2025-06-29 22:16:22,551 - database - DEBUG - Closing database session
2025-06-29 22:16:36,749 - database - DEBUG - Creating new database session
2025-06-29 22:16:36,865 - database - DEBUG - Database session used successfully
2025-06-29 22:16:36,867 - database - DEBUG - Closing database session
2025-06-29 22:17:08,928 - database - DEBUG - Database session used successfully
2025-06-29 22:17:08,936 - database - DEBUG - Closing database session
2025-06-29 22:54:24,284 - database - DEBUG - Creating new database session
2025-06-29 22:54:24,764 - database - DEBUG - Database session used successfully
2025-06-29 22:54:24,766 - database - DEBUG - Closing database session
2025-06-29 22:54:25,909 - database - DEBUG - Creating new database session
2025-06-29 22:54:25,936 - database - DEBUG - Database session used successfully
2025-06-29 22:54:25,937 - database - DEBUG - Closing database session
2025-06-29 22:54:25,961 - database - DEBUG - Creating new database session
2025-06-29 22:54:26,016 - database - DEBUG - Database session used successfully
2025-06-29 22:54:26,021 - database - DEBUG - Closing database session
2025-06-29 22:54:26,031 - database - DEBUG - Creating new database session
2025-06-29 22:54:26,347 - database - DEBUG - Creating new database session
2025-06-29 22:54:26,403 - database - DEBUG - Database session used successfully
2025-06-29 22:54:26,404 - database - DEBUG - Closing database session
2025-06-29 22:54:27,236 - database - DEBUG - Database session used successfully
2025-06-29 22:54:27,237 - database - DEBUG - Closing database session
2025-06-29 22:54:27,256 - database - DEBUG - Creating new database session
2025-06-29 22:54:27,576 - database - DEBUG - Creating new database session
2025-06-29 22:54:28,149 - database - DEBUG - Database session used successfully
2025-06-29 22:54:28,149 - database - DEBUG - Closing database session
2025-06-29 22:54:28,176 - database - DEBUG - Creating new database session
2025-06-29 22:54:28,216 - database - DEBUG - Database session used successfully
2025-06-29 22:54:28,217 - database - DEBUG - Closing database session
2025-06-29 22:54:58,144 - database - DEBUG - Database session used successfully
2025-06-29 22:54:58,145 - database - DEBUG - Closing database session
2025-06-29 23:19:16,395 - database - DEBUG - Creating new database session
2025-06-29 23:19:20,547 - database - DEBUG - Creating new database session
2025-06-29 23:19:20,552 - database - ERROR - Error in database session: 500: An error occurred while refreshing token.
Traceback (most recent call last):
  File "C:\Users\Dhanush\FASTAPI\app\api\v1\endpoints\users.py", line 310, in refresh_access_token
     raise HTTPException(
    ...<3 lines>...
    )
fastapi.exceptions.HTTPException: 401: Invalid or expired refresh token

During handling of the above exception, another exception occurred:

Traceback (most recent call last):
  File "C:\Users\Dhanush\FASTAPI\app\database\session.py", line 65, in get_db
    yield session
  File "C:\Users\Dhanush\FASTAPI\venv\Lib\site-packages\fastapi\routing.py", line 301, in app
    raw_response = await run_endpoint_function(
                   ^^^^^^^^^^^^^^^^^^^^^^^^^^^^
    ...<3 lines>...
    )
    ^
  File "C:\Users\Dhanush\FASTAPI\venv\Lib\site-packages\fastapi\routing.py", line 212, in run_endpoint_function
    return await dependant.call(**values)
           ^^^^^^^^^^^^^^^^^^^^^^^^^^^^^^
  File "C:\Users\Dhanush\FASTAPI\app\api\v1\endpoints\users.py", line 360, in refresh_access_token
    raise HTTPException(
    ...<2 lines>...
    )
fastapi.exceptions.HTTPException: 500: An error occurred while refreshing token.
2025-06-29 23:19:20,553 - database - INFO - Session rolled back due to error
2025-06-29 23:19:20,554 - database - DEBUG - Closing database session
2025-06-29 23:19:27,907 - database - DEBUG - Creating new database session
2025-06-29 23:19:28,180 - database - DEBUG - Database session used successfully
2025-06-29 23:19:28,181 - database - DEBUG - Closing database session
2025-06-29 23:19:28,740 - database - DEBUG - Creating new database session
2025-06-29 23:19:28,969 - database - DEBUG - Database session used successfully
2025-06-29 23:19:28,969 - database - DEBUG - Closing database session
2025-06-29 23:19:29,554 - database - DEBUG - Creating new database session
2025-06-29 23:19:29,806 - database - DEBUG - Database session used successfully
2025-06-29 23:19:29,806 - database - DEBUG - Closing database session
2025-06-29 23:19:30,381 - database - DEBUG - Creating new database session
2025-06-29 23:19:30,700 - database - DEBUG - Database session used successfully
2025-06-29 23:19:30,700 - database - DEBUG - Closing database session
2025-06-29 23:19:31,683 - database - DEBUG - Creating new database session
2025-06-29 23:19:31,818 - database - DEBUG - Database session used successfully
2025-06-29 23:19:31,835 - database - DEBUG - Closing database session
2025-06-29 23:19:33,245 - database - DEBUG - Creating new database session
2025-06-29 23:19:33,280 - database - DEBUG - Database session used successfully
2025-06-29 23:19:33,281 - database - DEBUG - Closing database session
2025-06-29 23:19:38,863 - database - DEBUG - Creating new database session
2025-06-29 23:19:38,889 - database - DEBUG - Database session used successfully
2025-06-29 23:19:38,890 - database - DEBUG - Closing database session
2025-06-29 23:19:48,342 - database - DEBUG - Creating new database session
2025-06-29 23:19:48,558 - database - DEBUG - Database session used successfully
2025-06-29 23:19:48,559 - database - DEBUG - Closing database session
2025-06-29 23:20:05,942 - database - DEBUG - Creating new database session
2025-06-29 23:20:06,232 - database - DEBUG - Database session used successfully
2025-06-29 23:20:06,233 - database - DEBUG - Closing database session
2025-06-29 23:20:20,360 - database - DEBUG - Creating new database session
2025-06-29 23:20:20,366 - database - ERROR - Error in database session: 500: An error occurred while refreshing token.
Traceback (most recent call last):
  File "C:\Users\Dhanush\FASTAPI\app\api\v1\endpoints\users.py", line 310, in refresh_access_token
     raise HTTPException(
    ...<3 lines>...
    )
fastapi.exceptions.HTTPException: 401: Invalid or expired refresh token

During handling of the above exception, another exception occurred:

Traceback (most recent call last):
  File "C:\Users\Dhanush\FASTAPI\app\database\session.py", line 65, in get_db
    yield session
  File "C:\Users\Dhanush\FASTAPI\venv\Lib\site-packages\fastapi\routing.py", line 301, in app
    raw_response = await run_endpoint_function(
                   ^^^^^^^^^^^^^^^^^^^^^^^^^^^^
    ...<3 lines>...
    )
    ^
  File "C:\Users\Dhanush\FASTAPI\venv\Lib\site-packages\fastapi\routing.py", line 212, in run_endpoint_function
    return await dependant.call(**values)
           ^^^^^^^^^^^^^^^^^^^^^^^^^^^^^^
  File "C:\Users\Dhanush\FASTAPI\app\api\v1\endpoints\users.py", line 360, in refresh_access_token
    raise HTTPException(
    ...<2 lines>...
    )
fastapi.exceptions.HTTPException: 500: An error occurred while refreshing token.
2025-06-29 23:20:20,371 - database - INFO - Session rolled back due to error
2025-06-29 23:20:20,372 - database - DEBUG - Closing database session
2025-06-29 23:20:47,066 - database - DEBUG - Creating new database session
2025-06-29 23:20:47,073 - database - DEBUG - Database session used successfully
2025-06-29 23:20:47,074 - database - DEBUG - Closing database session
2025-06-29 23:20:51,059 - database - DEBUG - Creating new database session
2025-06-29 23:20:51,070 - database - DEBUG - Database session used successfully
2025-06-29 23:20:51,071 - database - DEBUG - Closing database session
2025-06-29 23:20:53,329 - database - DEBUG - Creating new database session
2025-06-29 23:20:53,336 - database - DEBUG - Database session used successfully
2025-06-29 23:20:53,336 - database - DEBUG - Closing database session
2025-06-29 23:20:55,603 - database - DEBUG - Database session used successfully
2025-06-29 23:20:55,604 - database - DEBUG - Closing database session
2025-06-29 23:21:25,371 - database - DEBUG - Creating new database session
2025-06-29 23:22:06,379 - database - DEBUG - Creating new database session
2025-06-29 23:22:06,393 - database - DEBUG - Database session used successfully
2025-06-29 23:22:06,393 - database - DEBUG - Closing database session
2025-06-29 23:22:08,164 - database - DEBUG - Creating new database session
2025-06-29 23:22:08,175 - database - DEBUG - Database session used successfully
2025-06-29 23:22:08,175 - database - DEBUG - Closing database session
2025-06-29 23:22:09,261 - database - DEBUG - Creating new database session
2025-06-29 23:22:09,280 - database - DEBUG - Database session used successfully
2025-06-29 23:22:09,281 - database - DEBUG - Closing database session
2025-06-29 23:22:56,806 - database - DEBUG - Database session used successfully
2025-06-29 23:22:56,807 - database - DEBUG - Closing database session
2025-06-29 23:23:02,391 - database - DEBUG - Creating new database session
2025-06-29 23:23:23,439 - database - DEBUG - Creating new database session
2025-06-29 23:23:23,460 - database - DEBUG - Database session used successfully
2025-06-29 23:23:23,461 - database - DEBUG - Closing database session
2025-06-29 23:23:23,469 - database - DEBUG - Creating new database session
2025-06-29 23:23:23,487 - database - DEBUG - Database session used successfully
2025-06-29 23:23:23,489 - database - DEBUG - Closing database session
2025-06-29 23:23:24,653 - database - DEBUG - Database session used successfully
2025-06-29 23:23:24,653 - database - DEBUG - Closing database session
2025-06-29 23:26:27,933 - database - DEBUG - Creating new database session
2025-06-29 23:26:27,938 - database - DEBUG - Database session used successfully
2025-06-29 23:26:27,938 - database - DEBUG - Closing database session
2025-06-29 23:26:30,734 - database - DEBUG - Creating new database session
2025-06-29 23:26:30,737 - database - ERROR - Error in database session: 401: Could not validate credentials
Traceback (most recent call last):
  File "C:\Users\Dhanush\FASTAPI\app\core\security.py", line 93, in decode_token
    payload = jwt.decode(token, settings.SECRET_KEY, algorithms=[settings.ALGORITHM])
  File "C:\Users\Dhanush\FASTAPI\venv\Lib\site-packages\jose\jwt.py", line 174, in decode
    _validate_claims(
    ~~~~~~~~~~~~~~~~^
        claims,
        ^^^^^^^
    ...<5 lines>...
        options=defaults,
        ^^^^^^^^^^^^^^^^^
    )
    ^
  File "C:\Users\Dhanush\FASTAPI\venv\Lib\site-packages\jose\jwt.py", line 497, in _validate_claims
    _validate_exp(claims, leeway=leeway)
    ~~~~~~~~~~~~~^^^^^^^^^^^^^^^^^^^^^^^
  File "C:\Users\Dhanush\FASTAPI\venv\Lib\site-packages\jose\jwt.py", line 331, in _validate_exp
    raise ExpiredSignatureError("Signature has expired.")
jose.exceptions.ExpiredSignatureError: Signature has expired.

During handling of the above exception, another exception occurred:

Traceback (most recent call last):
  File "C:\Users\Dhanush\FASTAPI\app\api\v1\endpoints\users.py", line 289, in refresh_access_token
    payload = decode_token(refresh_token)
  File "C:\Users\Dhanush\FASTAPI\app\core\security.py", line 98, in decode_token
    raise JWTError("Could not validate credentials")
jose.exceptions.JWTError: Could not validate credentials

During handling of the above exception, another exception occurred:

Traceback (most recent call last):
  File "C:\Users\Dhanush\FASTAPI\app\database\session.py", line 65, in get_db
    yield session
  File "C:\Users\Dhanush\FASTAPI\venv\Lib\site-packages\fastapi\routing.py", line 301, in app
    raw_response = await run_endpoint_function(
                   ^^^^^^^^^^^^^^^^^^^^^^^^^^^^
    ...<3 lines>...
    )
    ^
  File "C:\Users\Dhanush\FASTAPI\venv\Lib\site-packages\fastapi\routing.py", line 212, in run_endpoint_function
    return await dependant.call(**values)
           ^^^^^^^^^^^^^^^^^^^^^^^^^^^^^^
  File "C:\Users\Dhanush\FASTAPI\app\api\v1\endpoints\users.py", line 352, in refresh_access_token
    raise HTTPException(
    ...<3 lines>...
    )
fastapi.exceptions.HTTPException: 401: Could not validate credentials
2025-06-29 23:26:30,740 - database - INFO - Session rolled back due to error
2025-06-29 23:26:30,741 - database - DEBUG - Closing database session
2025-06-29 23:26:33,978 - database - DEBUG - Creating new database session
2025-06-29 23:26:34,242 - database - DEBUG - Database session used successfully
2025-06-29 23:26:34,242 - database - DEBUG - Closing database session
2025-06-29 23:26:35,351 - database - DEBUG - Creating new database session
2025-06-29 23:26:35,392 - database - DEBUG - Database session used successfully
2025-06-29 23:26:35,395 - database - DEBUG - Closing database session
2025-06-29 23:26:35,457 - database - DEBUG - Creating new database session
2025-06-29 23:26:35,509 - database - DEBUG - Creating new database session
2025-06-29 23:26:35,612 - database - DEBUG - Database session used successfully
2025-06-29 23:26:35,613 - database - DEBUG - Closing database session
2025-06-29 23:26:35,717 - database - DEBUG - Creating new database session
2025-06-29 23:26:35,811 - database - DEBUG - Database session used successfully
2025-06-29 23:26:35,813 - database - DEBUG - Closing database session
2025-06-29 23:26:38,241 - database - DEBUG - Database session used successfully
2025-06-29 23:26:38,242 - database - DEBUG - Closing database session
2025-06-29 23:26:38,271 - database - DEBUG - Creating new database session
2025-06-29 23:26:38,660 - database - DEBUG - Creating new database session
2025-06-29 23:26:41,550 - database - DEBUG - Database session used successfully
2025-06-29 23:26:41,553 - database - DEBUG - Closing database session
2025-06-29 23:26:44,060 - database - DEBUG - Creating new database session
2025-06-29 23:26:44,146 - database - DEBUG - Database session used successfully
2025-06-29 23:26:44,147 - database - DEBUG - Closing database session
2025-06-29 23:27:50,479 - database - DEBUG - Creating new database session
2025-06-29 23:27:50,489 - database - DEBUG - Database session used successfully
2025-06-29 23:27:50,490 - database - DEBUG - Closing database session
2025-06-29 23:28:24,022 - database - DEBUG - Database session used successfully
2025-06-29 23:28:24,022 - database - DEBUG - Closing database session
2025-06-29 23:28:29,371 - database - DEBUG - Creating new database session
2025-06-29 23:28:37,258 - database - DEBUG - Database session used successfully
2025-06-29 23:28:37,258 - database - DEBUG - Closing database session
2025-06-29 23:29:55,386 - database - DEBUG - Creating new database session
2025-06-29 23:30:07,847 - database - DEBUG - Creating new database session
2025-06-29 23:30:07,854 - database - ERROR - Error in database session: 500: An error occurred while refreshing token.
Traceback (most recent call last):
  File "C:\Users\Dhanush\FASTAPI\app\api\v1\endpoints\users.py", line 310, in refresh_access_token
     raise HTTPException(
    ...<3 lines>...
    )
fastapi.exceptions.HTTPException: 401: Invalid or expired refresh token

During handling of the above exception, another exception occurred:

Traceback (most recent call last):
  File "C:\Users\Dhanush\FASTAPI\app\database\session.py", line 65, in get_db
    yield session
  File "C:\Users\Dhanush\FASTAPI\venv\Lib\site-packages\fastapi\routing.py", line 301, in app
    raw_response = await run_endpoint_function(
                   ^^^^^^^^^^^^^^^^^^^^^^^^^^^^
    ...<3 lines>...
    )
    ^
  File "C:\Users\Dhanush\FASTAPI\venv\Lib\site-packages\fastapi\routing.py", line 212, in run_endpoint_function
    return await dependant.call(**values)
           ^^^^^^^^^^^^^^^^^^^^^^^^^^^^^^
  File "C:\Users\Dhanush\FASTAPI\app\api\v1\endpoints\users.py", line 360, in refresh_access_token
    raise HTTPException(
    ...<2 lines>...
    )
fastapi.exceptions.HTTPException: 500: An error occurred while refreshing token.
2025-06-29 23:30:07,858 - database - INFO - Session rolled back due to error
2025-06-29 23:30:07,858 - database - DEBUG - Closing database session
2025-06-29 23:30:13,855 - database - DEBUG - Creating new database session
2025-06-29 23:30:16,340 - database - DEBUG - Database session used successfully
2025-06-29 23:30:16,342 - database - DEBUG - Closing database session
2025-06-29 23:30:17,094 - database - DEBUG - Creating new database session
2025-06-29 23:30:19,396 - database - DEBUG - Database session used successfully
2025-06-29 23:30:19,397 - database - DEBUG - Closing database session
2025-06-29 23:30:20,487 - database - DEBUG - Creating new database session
2025-06-29 23:30:20,654 - database - DEBUG - Database session used successfully
2025-06-29 23:30:20,656 - database - DEBUG - Closing database session
2025-06-29 23:31:11,407 - database - DEBUG - Database session used successfully
2025-06-29 23:31:11,408 - database - DEBUG - Closing database session
2025-06-29 23:32:38,428 - database - DEBUG - Creating new database session
2025-06-29 23:32:45,599 - database - DEBUG - Creating new database session
2025-06-29 23:32:45,605 - database - ERROR - Error in database session: 500: An error occurred while refreshing token.
Traceback (most recent call last):
  File "C:\Users\Dhanush\FASTAPI\app\api\v1\endpoints\users.py", line 310, in refresh_access_token
     raise HTTPException(
    ...<3 lines>...
    )
fastapi.exceptions.HTTPException: 401: Invalid or expired refresh token

During handling of the above exception, another exception occurred:

Traceback (most recent call last):
  File "C:\Users\Dhanush\FASTAPI\app\database\session.py", line 65, in get_db
    yield session
  File "C:\Users\Dhanush\FASTAPI\venv\Lib\site-packages\fastapi\routing.py", line 301, in app
    raw_response = await run_endpoint_function(
                   ^^^^^^^^^^^^^^^^^^^^^^^^^^^^
    ...<3 lines>...
    )
    ^
  File "C:\Users\Dhanush\FASTAPI\venv\Lib\site-packages\fastapi\routing.py", line 212, in run_endpoint_function
    return await dependant.call(**values)
           ^^^^^^^^^^^^^^^^^^^^^^^^^^^^^^
  File "C:\Users\Dhanush\FASTAPI\app\api\v1\endpoints\users.py", line 360, in refresh_access_token
    raise HTTPException(
    ...<2 lines>...
    )
fastapi.exceptions.HTTPException: 500: An error occurred while refreshing token.
2025-06-29 23:32:45,610 - database - INFO - Session rolled back due to error
2025-06-29 23:32:45,610 - database - DEBUG - Closing database session
2025-06-29 23:32:48,239 - database - DEBUG - Creating new database session
2025-06-29 23:32:49,135 - database - DEBUG - Database session used successfully
2025-06-29 23:32:49,136 - database - DEBUG - Closing database session
2025-06-29 23:33:03,182 - database - DEBUG - Creating new database session
2025-06-29 23:33:03,566 - database - DEBUG - Database session used successfully
2025-06-29 23:33:03,567 - database - DEBUG - Closing database session
2025-06-29 23:33:39,951 - database - DEBUG - Database session used successfully
2025-06-29 23:33:39,952 - database - DEBUG - Closing database session
2025-06-29 23:34:50,885 - database - DEBUG - Creating new database session
2025-06-29 23:35:06,711 - database - DEBUG - Creating new database session
2025-06-29 23:35:06,721 - database - DEBUG - Database session used successfully
2025-06-29 23:35:06,721 - database - DEBUG - Closing database session
2025-06-29 23:36:22,692 - database - DEBUG - Creating new database session
2025-06-29 23:36:22,702 - database - DEBUG - Database session used successfully
2025-06-29 23:36:22,702 - database - DEBUG - Closing database session
2025-06-29 23:36:32,603 - database - DEBUG - Database session used successfully
2025-06-29 23:36:32,603 - database - DEBUG - Closing database session
2025-06-29 23:36:37,257 - database - DEBUG - Creating new database session
2025-06-29 23:36:37,409 - database - DEBUG - Database session used successfully
2025-06-29 23:36:37,410 - database - DEBUG - Closing database session
2025-06-29 23:36:38,369 - database - DEBUG - Creating new database session
2025-06-29 23:37:10,005 - database - DEBUG - Database session used successfully
2025-06-29 23:37:10,005 - database - DEBUG - Closing database session
2025-06-29 23:37:15,384 - database - DEBUG - Creating new database session
2025-06-29 23:37:17,723 - database - DEBUG - Creating new database session
2025-06-29 23:37:17,731 - database - ERROR - Error in database session: 500: An error occurred while refreshing token.
Traceback (most recent call last):
  File "C:\Users\Dhanush\FASTAPI\app\api\v1\endpoints\users.py", line 310, in refresh_access_token
     raise HTTPException(
    ...<3 lines>...
    )
fastapi.exceptions.HTTPException: 401: Invalid or expired refresh token

During handling of the above exception, another exception occurred:

Traceback (most recent call last):
  File "C:\Users\Dhanush\FASTAPI\app\database\session.py", line 65, in get_db
    yield session
  File "C:\Users\Dhanush\FASTAPI\venv\Lib\site-packages\fastapi\routing.py", line 301, in app
    raw_response = await run_endpoint_function(
                   ^^^^^^^^^^^^^^^^^^^^^^^^^^^^
    ...<3 lines>...
    )
    ^
  File "C:\Users\Dhanush\FASTAPI\venv\Lib\site-packages\fastapi\routing.py", line 212, in run_endpoint_function
    return await dependant.call(**values)
           ^^^^^^^^^^^^^^^^^^^^^^^^^^^^^^
  File "C:\Users\Dhanush\FASTAPI\app\api\v1\endpoints\users.py", line 360, in refresh_access_token
    raise HTTPException(
    ...<2 lines>...
    )
fastapi.exceptions.HTTPException: 500: An error occurred while refreshing token.
2025-06-29 23:37:17,737 - database - INFO - Session rolled back due to error
2025-06-29 23:37:17,738 - database - DEBUG - Closing database session
2025-06-29 23:37:38,253 - database - DEBUG - Creating new database session
2025-06-29 23:37:38,288 - database - DEBUG - Database session used successfully
2025-06-29 23:37:38,292 - database - DEBUG - Closing database session
2025-06-29 23:37:40,119 - database - DEBUG - Creating new database session
2025-06-29 23:37:40,382 - database - DEBUG - Database session used successfully
2025-06-29 23:37:40,382 - database - DEBUG - Closing database session
2025-06-29 23:37:50,489 - database - DEBUG - Database session used successfully
2025-06-29 23:37:50,491 - database - DEBUG - Closing database session
2025-06-30 03:09:21,612 - database - DEBUG - Creating new database session
2025-06-30 03:09:23,486 - database - DEBUG - Database session used successfully
2025-06-30 03:09:23,487 - database - DEBUG - Closing database session
2025-06-30 03:12:09,629 - database - DEBUG - Creating new database session
2025-06-30 03:12:11,196 - database - DEBUG - Database session used successfully
2025-06-30 03:12:11,197 - database - DEBUG - Closing database session
2025-06-30 03:15:05,127 - database - DEBUG - Creating new database session
2025-06-30 03:15:06,825 - database - DEBUG - Creating new database session
2025-06-30 03:15:06,887 - database - DEBUG - Database session used successfully
2025-06-30 03:15:06,888 - database - DEBUG - Closing database session
2025-06-30 03:15:18,368 - database - DEBUG - Database session used successfully
2025-06-30 03:15:18,369 - database - DEBUG - Closing database session
2025-06-30 03:21:33,715 - database - DEBUG - Creating new database session
2025-06-30 03:21:33,731 - database - DEBUG - Database session used successfully
2025-06-30 03:21:33,732 - database - DEBUG - Closing database session
2025-06-30 03:21:33,743 - database - DEBUG - Creating new database session
2025-06-30 03:21:33,749 - database - ERROR - Error in database session: 500: An error occurred while refreshing token.
Traceback (most recent call last):
  File "C:\Users\Dhanush\FASTAPI\app\api\v1\endpoints\users.py", line 310, in refresh_access_token
     raise HTTPException(
    ...<3 lines>...
    )
fastapi.exceptions.HTTPException: 401: Invalid or expired refresh token

During handling of the above exception, another exception occurred:

Traceback (most recent call last):
  File "C:\Users\Dhanush\FASTAPI\app\database\session.py", line 65, in get_db
    yield session
  File "C:\Users\Dhanush\FASTAPI\venv\Lib\site-packages\fastapi\routing.py", line 301, in app
    raw_response = await run_endpoint_function(
                   ^^^^^^^^^^^^^^^^^^^^^^^^^^^^
    ...<3 lines>...
    )
    ^
  File "C:\Users\Dhanush\FASTAPI\venv\Lib\site-packages\fastapi\routing.py", line 212, in run_endpoint_function
    return await dependant.call(**values)
           ^^^^^^^^^^^^^^^^^^^^^^^^^^^^^^
  File "C:\Users\Dhanush\FASTAPI\app\api\v1\endpoints\users.py", line 360, in refresh_access_token
    raise HTTPException(
    ...<2 lines>...
    )
fastapi.exceptions.HTTPException: 500: An error occurred while refreshing token.
2025-06-30 03:21:33,755 - database - INFO - Session rolled back due to error
2025-06-30 03:21:33,756 - database - DEBUG - Closing database session
2025-06-30 03:21:33,760 - database - DEBUG - Creating new database session
2025-06-30 03:21:33,798 - database - DEBUG - Database session used successfully
2025-06-30 03:21:33,799 - database - DEBUG - Closing database session
2025-06-30 03:21:33,821 - database - DEBUG - Creating new database session
2025-06-30 03:21:33,832 - database - DEBUG - Creating new database session
2025-06-30 03:21:33,903 - database - DEBUG - Database session used successfully
2025-06-30 03:21:33,904 - database - DEBUG - Closing database session
2025-06-30 03:21:33,912 - database - DEBUG - Creating new database session
2025-06-30 03:21:33,931 - database - DEBUG - Database session used successfully
2025-06-30 03:21:33,932 - database - DEBUG - Closing database session
2025-06-30 03:21:33,944 - database - DEBUG - Creating new database session
2025-06-30 03:21:33,975 - database - DEBUG - Database session used successfully
2025-06-30 03:21:33,975 - database - DEBUG - Closing database session
2025-06-30 03:21:33,990 - database - DEBUG - Creating new database session
2025-06-30 03:21:34,016 - database - DEBUG - Database session used successfully
2025-06-30 03:21:34,017 - database - DEBUG - Closing database session
2025-06-30 03:21:34,032 - database - DEBUG - Creating new database session
2025-06-30 03:21:34,048 - database - DEBUG - Database session used successfully
2025-06-30 03:21:34,050 - database - DEBUG - Closing database session
2025-06-30 03:21:36,852 - database - DEBUG - Creating new database session
2025-06-30 03:21:36,866 - database - DEBUG - Database session used successfully
2025-06-30 03:21:36,867 - database - DEBUG - Closing database session
2025-06-30 03:22:18,305 - database - DEBUG - Creating new database session
2025-06-30 03:22:18,318 - database - ERROR - Error in database session: 401: Could not validate credentials
Traceback (most recent call last):
  File "C:\Users\Dhanush\FASTAPI\app\core\security.py", line 93, in decode_token
    payload = jwt.decode(token, settings.SECRET_KEY, algorithms=[settings.ALGORITHM])
  File "C:\Users\Dhanush\FASTAPI\venv\Lib\site-packages\jose\jwt.py", line 174, in decode
    _validate_claims(
    ~~~~~~~~~~~~~~~~^
        claims,
        ^^^^^^^
    ...<5 lines>...
        options=defaults,
        ^^^^^^^^^^^^^^^^^
    )
    ^
  File "C:\Users\Dhanush\FASTAPI\venv\Lib\site-packages\jose\jwt.py", line 497, in _validate_claims
    _validate_exp(claims, leeway=leeway)
    ~~~~~~~~~~~~~^^^^^^^^^^^^^^^^^^^^^^^
  File "C:\Users\Dhanush\FASTAPI\venv\Lib\site-packages\jose\jwt.py", line 331, in _validate_exp
    raise ExpiredSignatureError("Signature has expired.")
jose.exceptions.ExpiredSignatureError: Signature has expired.

During handling of the above exception, another exception occurred:

Traceback (most recent call last):
  File "C:\Users\Dhanush\FASTAPI\app\api\v1\endpoints\users.py", line 289, in refresh_access_token
    payload = decode_token(refresh_token)
  File "C:\Users\Dhanush\FASTAPI\app\core\security.py", line 98, in decode_token
    raise JWTError("Could not validate credentials")
jose.exceptions.JWTError: Could not validate credentials

During handling of the above exception, another exception occurred:

Traceback (most recent call last):
  File "C:\Users\Dhanush\FASTAPI\app\database\session.py", line 65, in get_db
    yield session
  File "C:\Users\Dhanush\FASTAPI\venv\Lib\site-packages\fastapi\routing.py", line 301, in app
    raw_response = await run_endpoint_function(
                   ^^^^^^^^^^^^^^^^^^^^^^^^^^^^
    ...<3 lines>...
    )
    ^
  File "C:\Users\Dhanush\FASTAPI\venv\Lib\site-packages\fastapi\routing.py", line 212, in run_endpoint_function
    return await dependant.call(**values)
           ^^^^^^^^^^^^^^^^^^^^^^^^^^^^^^
  File "C:\Users\Dhanush\FASTAPI\app\api\v1\endpoints\users.py", line 352, in refresh_access_token
    raise HTTPException(
    ...<3 lines>...
    )
fastapi.exceptions.HTTPException: 401: Could not validate credentials
2025-06-30 03:22:18,327 - database - INFO - Session rolled back due to error
2025-06-30 03:22:18,328 - database - DEBUG - Closing database session
2025-06-30 03:22:18,490 - database - DEBUG - Creating new database session
2025-06-30 03:22:18,501 - database - ERROR - Error in database session: 401: Could not validate credentials
Traceback (most recent call last):
  File "C:\Users\Dhanush\FASTAPI\app\core\security.py", line 93, in decode_token
    payload = jwt.decode(token, settings.SECRET_KEY, algorithms=[settings.ALGORITHM])
  File "C:\Users\Dhanush\FASTAPI\venv\Lib\site-packages\jose\jwt.py", line 174, in decode
    _validate_claims(
    ~~~~~~~~~~~~~~~~^
        claims,
        ^^^^^^^
    ...<5 lines>...
        options=defaults,
        ^^^^^^^^^^^^^^^^^
    )
    ^
  File "C:\Users\Dhanush\FASTAPI\venv\Lib\site-packages\jose\jwt.py", line 497, in _validate_claims
    _validate_exp(claims, leeway=leeway)
    ~~~~~~~~~~~~~^^^^^^^^^^^^^^^^^^^^^^^
  File "C:\Users\Dhanush\FASTAPI\venv\Lib\site-packages\jose\jwt.py", line 331, in _validate_exp
    raise ExpiredSignatureError("Signature has expired.")
jose.exceptions.ExpiredSignatureError: Signature has expired.

During handling of the above exception, another exception occurred:

Traceback (most recent call last):
  File "C:\Users\Dhanush\FASTAPI\app\core\security.py", line 281, in get_current_user
    payload = decode_token(token)
  File "C:\Users\Dhanush\FASTAPI\app\core\security.py", line 98, in decode_token
    raise JWTError("Could not validate credentials")
jose.exceptions.JWTError: Could not validate credentials

During handling of the above exception, another exception occurred:

Traceback (most recent call last):
  File "C:\Users\Dhanush\FASTAPI\app\database\session.py", line 65, in get_db
    yield session
  File "C:\Users\Dhanush\FASTAPI\venv\Lib\site-packages\fastapi\routing.py", line 291, in app
    solved_result = await solve_dependencies(
                    ^^^^^^^^^^^^^^^^^^^^^^^^^
    ...<6 lines>...
    )
    ^
  File "C:\Users\Dhanush\FASTAPI\venv\Lib\site-packages\fastapi\dependencies\utils.py", line 638, in solve_dependencies
    solved = await call(**solved_result.values)
             ^^^^^^^^^^^^^^^^^^^^^^^^^^^^^^^^^^
  File "C:\Users\Dhanush\FASTAPI\app\core\security.py", line 326, in get_current_user
    raise credentials_exception
fastapi.exceptions.HTTPException: 401: Could not validate credentials
2025-06-30 03:22:18,507 - database - INFO - Session rolled back due to error
2025-06-30 03:22:18,508 - database - DEBUG - Closing database session
2025-06-30 03:22:27,980 - database - DEBUG - Database session used successfully
2025-06-30 03:22:27,981 - database - DEBUG - Closing database session
2025-06-30 03:22:30,646 - database - DEBUG - Creating new database session
2025-06-30 03:22:31,205 - database - DEBUG - Database session used successfully
2025-06-30 03:22:31,206 - database - DEBUG - Closing database session
2025-06-30 03:22:32,432 - database - DEBUG - Creating new database session
2025-06-30 03:22:32,446 - database - DEBUG - Database session used successfully
2025-06-30 03:22:32,447 - database - DEBUG - Closing database session
2025-06-30 03:22:32,463 - database - DEBUG - Creating new database session
2025-06-30 03:22:32,478 - database - DEBUG - Database session used successfully
2025-06-30 03:22:32,478 - database - DEBUG - Closing database session
2025-06-30 03:22:32,481 - database - DEBUG - Creating new database session
2025-06-30 03:22:32,662 - database - DEBUG - Creating new database session
2025-06-30 03:22:32,716 - database - DEBUG - Database session used successfully
2025-06-30 03:22:32,718 - database - DEBUG - Closing database session
2025-06-30 03:22:33,069 - database - DEBUG - Database session used successfully
2025-06-30 03:22:33,070 - database - DEBUG - Closing database session
2025-06-30 03:22:33,083 - database - DEBUG - Creating new database session
2025-06-30 03:22:33,719 - database - DEBUG - Database session used successfully
2025-06-30 03:22:33,720 - database - DEBUG - Closing database session
2025-06-30 03:22:33,758 - database - DEBUG - Creating new database session
2025-06-30 03:22:33,776 - database - DEBUG - Database session used successfully
2025-06-30 03:22:33,777 - database - DEBUG - Closing database session
2025-06-30 03:22:33,789 - database - DEBUG - Creating new database session
2025-06-30 03:23:48,862 - database - DEBUG - Creating new database session
2025-06-30 03:23:48,877 - database - DEBUG - Database session used successfully
2025-06-30 03:23:48,878 - database - DEBUG - Closing database session
2025-06-30 03:25:07,001 - database - DEBUG - Creating new database session
2025-06-30 03:25:07,013 - database - DEBUG - Database session used successfully
2025-06-30 03:25:07,014 - database - DEBUG - Closing database session
2025-06-30 03:25:12,888 - database - DEBUG - Database session used successfully
2025-06-30 03:25:12,889 - database - DEBUG - Closing database session
2025-06-30 03:27:55,837 - ERROR - database - Error in database session: 500: An error occurred while refreshing token.
Traceback (most recent call last):
  File "C:\Users\Dhanush\FASTAPI\app\api\v1\endpoints\users.py", line 310, in refresh_access_token
     raise HTTPException(
    ...<3 lines>...
    )
fastapi.exceptions.HTTPException: 401: Invalid or expired refresh token

During handling of the above exception, another exception occurred:

Traceback (most recent call last):
  File "C:\Users\Dhanush\FASTAPI\app\database\session.py", line 60, in get_db
    yield session
  File "C:\Users\Dhanush\FASTAPI\venv\Lib\site-packages\fastapi\routing.py", line 301, in app
    raw_response = await run_endpoint_function(
                   ^^^^^^^^^^^^^^^^^^^^^^^^^^^^
    ...<3 lines>...
    )
    ^
  File "C:\Users\Dhanush\FASTAPI\venv\Lib\site-packages\fastapi\routing.py", line 212, in run_endpoint_function
    return await dependant.call(**values)
           ^^^^^^^^^^^^^^^^^^^^^^^^^^^^^^
  File "C:\Users\Dhanush\FASTAPI\app\api\v1\endpoints\users.py", line 360, in refresh_access_token
    raise HTTPException(
    ...<2 lines>...
    )
fastapi.exceptions.HTTPException: 500: An error occurred while refreshing token.
2025-06-30 03:27:55,840 - INFO - database - Session rolled back due to error
2025-06-30 03:28:05,334 - ERROR - database - Error in database session: 500: An error occurred while refreshing token.
Traceback (most recent call last):
  File "C:\Users\Dhanush\FASTAPI\app\api\v1\endpoints\users.py", line 310, in refresh_access_token
     raise HTTPException(
    ...<3 lines>...
    )
fastapi.exceptions.HTTPException: 401: Invalid or expired refresh token

During handling of the above exception, another exception occurred:

Traceback (most recent call last):
  File "C:\Users\Dhanush\FASTAPI\app\database\session.py", line 60, in get_db
    yield session
  File "C:\Users\Dhanush\FASTAPI\venv\Lib\site-packages\fastapi\routing.py", line 301, in app
    raw_response = await run_endpoint_function(
                   ^^^^^^^^^^^^^^^^^^^^^^^^^^^^
    ...<3 lines>...
    )
    ^
  File "C:\Users\Dhanush\FASTAPI\venv\Lib\site-packages\fastapi\routing.py", line 212, in run_endpoint_function
    return await dependant.call(**values)
           ^^^^^^^^^^^^^^^^^^^^^^^^^^^^^^
  File "C:\Users\Dhanush\FASTAPI\app\api\v1\endpoints\users.py", line 360, in refresh_access_token
    raise HTTPException(
    ...<2 lines>...
    )
fastapi.exceptions.HTTPException: 500: An error occurred while refreshing token.
2025-06-30 03:28:05,336 - INFO - database - Session rolled back due to error
2025-06-30 03:41:52,519 - ERROR - database - Error in database session: 500: An error occurred while refreshing token.
Traceback (most recent call last):
  File "C:\Users\Dhanush\FASTAPI\app\api\v1\endpoints\users.py", line 310, in refresh_access_token
     raise HTTPException(
    ...<3 lines>...
    )
fastapi.exceptions.HTTPException: 401: Invalid or expired refresh token

During handling of the above exception, another exception occurred:

Traceback (most recent call last):
  File "C:\Users\Dhanush\FASTAPI\app\database\session.py", line 67, in get_db
    yield session
  File "C:\Users\Dhanush\FASTAPI\venv\Lib\site-packages\fastapi\routing.py", line 301, in app
    raw_response = await run_endpoint_function(
                   ^^^^^^^^^^^^^^^^^^^^^^^^^^^^
    ...<3 lines>...
    )
    ^
  File "C:\Users\Dhanush\FASTAPI\venv\Lib\site-packages\fastapi\routing.py", line 212, in run_endpoint_function
    return await dependant.call(**values)
           ^^^^^^^^^^^^^^^^^^^^^^^^^^^^^^
  File "C:\Users\Dhanush\FASTAPI\app\api\v1\endpoints\users.py", line 360, in refresh_access_token
    raise HTTPException(
    ...<2 lines>...
    )
fastapi.exceptions.HTTPException: 500: An error occurred while refreshing token.
2025-06-30 03:41:52,521 - INFO - database - Session rolled back due to error
2025-06-30 03:43:23,762 - ERROR - database - Error in database session: 500: An error occurred while refreshing token.
Traceback (most recent call last):
  File "C:\Users\Dhanush\FASTAPI\app\api\v1\endpoints\users.py", line 310, in refresh_access_token
     raise HTTPException(
    ...<3 lines>...
    )
fastapi.exceptions.HTTPException: 401: Invalid or expired refresh token

During handling of the above exception, another exception occurred:

Traceback (most recent call last):
  File "C:\Users\Dhanush\FASTAPI\app\database\session.py", line 67, in get_db
    yield session
  File "C:\Users\Dhanush\FASTAPI\venv\Lib\site-packages\fastapi\routing.py", line 301, in app
    raw_response = await run_endpoint_function(
                   ^^^^^^^^^^^^^^^^^^^^^^^^^^^^
    ...<3 lines>...
    )
    ^
  File "C:\Users\Dhanush\FASTAPI\venv\Lib\site-packages\fastapi\routing.py", line 212, in run_endpoint_function
    return await dependant.call(**values)
           ^^^^^^^^^^^^^^^^^^^^^^^^^^^^^^
  File "C:\Users\Dhanush\FASTAPI\app\api\v1\endpoints\users.py", line 360, in refresh_access_token
    raise HTTPException(
    ...<2 lines>...
    )
fastapi.exceptions.HTTPException: 500: An error occurred while refreshing token.
2025-06-30 03:43:23,763 - INFO - database - Session rolled back due to error
2025-06-30 03:43:27,581 - ERROR - database - Error in database session: 500: An error occurred while refreshing token.
Traceback (most recent call last):
  File "C:\Users\Dhanush\FASTAPI\app\api\v1\endpoints\users.py", line 310, in refresh_access_token
     raise HTTPException(
    ...<3 lines>...
    )
fastapi.exceptions.HTTPException: 401: Invalid or expired refresh token

During handling of the above exception, another exception occurred:

Traceback (most recent call last):
  File "C:\Users\Dhanush\FASTAPI\app\database\session.py", line 67, in get_db
    yield session
  File "C:\Users\Dhanush\FASTAPI\venv\Lib\site-packages\fastapi\routing.py", line 301, in app
    raw_response = await run_endpoint_function(
                   ^^^^^^^^^^^^^^^^^^^^^^^^^^^^
    ...<3 lines>...
    )
    ^
  File "C:\Users\Dhanush\FASTAPI\venv\Lib\site-packages\fastapi\routing.py", line 212, in run_endpoint_function
    return await dependant.call(**values)
           ^^^^^^^^^^^^^^^^^^^^^^^^^^^^^^
  File "C:\Users\Dhanush\FASTAPI\app\api\v1\endpoints\users.py", line 360, in refresh_access_token
    raise HTTPException(
    ...<2 lines>...
    )
fastapi.exceptions.HTTPException: 500: An error occurred while refreshing token.
2025-06-30 03:43:27,582 - INFO - database - Session rolled back due to error
2025-06-30 03:43:31,073 - ERROR - database - Error in database session: 500: An error occurred while refreshing token.
Traceback (most recent call last):
  File "C:\Users\Dhanush\FASTAPI\app\api\v1\endpoints\users.py", line 310, in refresh_access_token
     raise HTTPException(
    ...<3 lines>...
    )
fastapi.exceptions.HTTPException: 401: Invalid or expired refresh token

During handling of the above exception, another exception occurred:

Traceback (most recent call last):
  File "C:\Users\Dhanush\FASTAPI\app\database\session.py", line 67, in get_db
    yield session
  File "C:\Users\Dhanush\FASTAPI\venv\Lib\site-packages\fastapi\routing.py", line 301, in app
    raw_response = await run_endpoint_function(
                   ^^^^^^^^^^^^^^^^^^^^^^^^^^^^
    ...<3 lines>...
    )
    ^
  File "C:\Users\Dhanush\FASTAPI\venv\Lib\site-packages\fastapi\routing.py", line 212, in run_endpoint_function
    return await dependant.call(**values)
           ^^^^^^^^^^^^^^^^^^^^^^^^^^^^^^
  File "C:\Users\Dhanush\FASTAPI\app\api\v1\endpoints\users.py", line 360, in refresh_access_token
    raise HTTPException(
    ...<2 lines>...
    )
fastapi.exceptions.HTTPException: 500: An error occurred while refreshing token.
2025-06-30 03:43:31,075 - INFO - database - Session rolled back due to error
