2025-06-27 04:47:44,237 - database - DEBUG - Creating new database session
2025-06-27 04:47:44,241 - database - DEBUG - Creating new database session
2025-06-27 04:47:44,250 - database - ERROR - Error in database session: 500: An error occurred while refreshing token.
Traceback (most recent call last):
  File "C:\Users\Dhanush\FASTAPI\app\api\v1\endpoints\users.py", line 310, in refresh_access_token
     raise HTTPException(
    ...<3 lines>...
    )
fastapi.exceptions.HTTPException: 401: Invalid or expired refresh token

During handling of the above exception, another exception occurred:

Traceback (most recent call last):
  File "C:\Users\Dhanush\FASTAPI\app\database\session.py", line 65, in get_db
    yield session
  File "C:\Users\Dhanush\FASTAPI\venv\Lib\site-packages\fastapi\routing.py", line 301, in app
    raw_response = await run_endpoint_function(
                   ^^^^^^^^^^^^^^^^^^^^^^^^^^^^
    ...<3 lines>...
    )
    ^
  File "C:\Users\Dhanush\FASTAPI\venv\Lib\site-packages\fastapi\routing.py", line 212, in run_endpoint_function
    return await dependant.call(**values)
           ^^^^^^^^^^^^^^^^^^^^^^^^^^^^^^
  File "C:\Users\Dhanush\FASTAPI\app\api\v1\endpoints\users.py", line 360, in refresh_access_token
    raise HTTPException(
    ...<2 lines>...
    )
fastapi.exceptions.HTTPException: 500: An error occurred while refreshing token.
2025-06-27 04:47:44,256 - database - INFO - Session rolled back due to error
2025-06-27 04:47:44,257 - database - DEBUG - Closing database session
2025-06-27 04:47:46,092 - database - DEBUG - Database session used successfully
2025-06-27 04:47:46,092 - database - DEBUG - Closing database session
2025-06-27 04:47:48,367 - database - DEBUG - Creating new database session
2025-06-27 04:47:48,664 - database - DEBUG - Database session used successfully
2025-06-27 04:47:48,676 - database - DEBUG - Closing database session
2025-06-27 04:47:49,916 - database - DEBUG - Creating new database session
2025-06-27 04:47:50,085 - database - DEBUG - Database session used successfully
2025-06-27 04:47:50,086 - database - DEBUG - Closing database session
2025-06-27 04:47:50,151 - database - DEBUG - Creating new database session
2025-06-27 04:47:50,439 - database - DEBUG - Database session used successfully
2025-06-27 04:47:50,446 - database - DEBUG - Closing database session
2025-06-27 04:47:50,526 - database - DEBUG - Creating new database session
2025-06-27 04:47:50,583 - database - DEBUG - Database session used successfully
2025-06-27 04:47:50,584 - database - DEBUG - Closing database session
2025-06-27 04:47:50,588 - database - DEBUG - Creating new database session
2025-06-27 04:47:52,565 - database - DEBUG - Database session used successfully
2025-06-27 04:47:52,569 - database - DEBUG - Closing database session
2025-06-27 04:47:52,615 - database - DEBUG - Creating new database session
2025-06-27 04:47:52,983 - database - DEBUG - Creating new database session
2025-06-27 04:47:55,316 - database - DEBUG - Database session used successfully
2025-06-27 04:47:55,319 - database - DEBUG - Closing database session
2025-06-27 04:47:55,411 - database - DEBUG - Creating new database session
2025-06-27 04:47:55,477 - database - DEBUG - Database session used successfully
2025-06-27 04:47:55,482 - database - DEBUG - Closing database session
2025-06-27 04:49:04,606 - database - DEBUG - Creating new database session
2025-06-27 04:49:04,619 - database - DEBUG - Database session used successfully
2025-06-27 04:49:04,619 - database - DEBUG - Closing database session
2025-06-27 04:49:20,061 - database - DEBUG - Creating new database session
2025-06-27 04:49:20,074 - database - ERROR - Error in database session: 500: An error occurred while refreshing token.
Traceback (most recent call last):
  File "C:\Users\Dhanush\FASTAPI\app\api\v1\endpoints\users.py", line 310, in refresh_access_token
     raise HTTPException(
    ...<3 lines>...
    )
fastapi.exceptions.HTTPException: 401: Invalid or expired refresh token

During handling of the above exception, another exception occurred:

Traceback (most recent call last):
  File "C:\Users\Dhanush\FASTAPI\app\database\session.py", line 65, in get_db
    yield session
  File "C:\Users\Dhanush\FASTAPI\venv\Lib\site-packages\fastapi\routing.py", line 301, in app
    raw_response = await run_endpoint_function(
                   ^^^^^^^^^^^^^^^^^^^^^^^^^^^^
    ...<3 lines>...
    )
    ^
  File "C:\Users\Dhanush\FASTAPI\venv\Lib\site-packages\fastapi\routing.py", line 212, in run_endpoint_function
    return await dependant.call(**values)
           ^^^^^^^^^^^^^^^^^^^^^^^^^^^^^^
  File "C:\Users\Dhanush\FASTAPI\app\api\v1\endpoints\users.py", line 360, in refresh_access_token
    raise HTTPException(
    ...<2 lines>...
    )
fastapi.exceptions.HTTPException: 500: An error occurred while refreshing token.
2025-06-27 04:49:20,079 - database - INFO - Session rolled back due to error
2025-06-27 04:49:20,080 - database - DEBUG - Closing database session
2025-06-27 04:49:43,381 - database - DEBUG - Database session used successfully
2025-06-27 04:49:43,396 - database - DEBUG - Closing database session
2025-06-27 05:03:35,745 - database - DEBUG - Creating new database session
2025-06-27 05:03:38,881 - database - DEBUG - Creating new database session
2025-06-27 05:03:38,898 - database - ERROR - Error in database session: 500: An error occurred while refreshing token.
Traceback (most recent call last):
  File "C:\Users\Dhanush\FASTAPI\app\api\v1\endpoints\users.py", line 310, in refresh_access_token
     raise HTTPException(
    ...<3 lines>...
    )
fastapi.exceptions.HTTPException: 401: Invalid or expired refresh token

During handling of the above exception, another exception occurred:

Traceback (most recent call last):
  File "C:\Users\Dhanush\FASTAPI\app\database\session.py", line 65, in get_db
    yield session
  File "C:\Users\Dhanush\AppData\Local\Programs\Python\Python313\Lib\site-packages\fastapi\routing.py", line 301, in app
    raw_response = await run_endpoint_function(
                   ^^^^^^^^^^^^^^^^^^^^^^^^^^^^
    ...<3 lines>...
    )
    ^
  File "C:\Users\Dhanush\AppData\Local\Programs\Python\Python313\Lib\site-packages\fastapi\routing.py", line 212, in run_endpoint_function
    return await dependant.call(**values)
           ^^^^^^^^^^^^^^^^^^^^^^^^^^^^^^
  File "C:\Users\Dhanush\FASTAPI\app\api\v1\endpoints\users.py", line 360, in refresh_access_token
    raise HTTPException(
    ...<2 lines>...
    )
fastapi.exceptions.HTTPException: 500: An error occurred while refreshing token.
2025-06-27 05:03:38,907 - database - INFO - Session rolled back due to error
2025-06-27 05:03:38,908 - database - DEBUG - Closing database session
2025-06-27 05:03:40,428 - database - DEBUG - Database session used successfully
2025-06-27 05:03:40,429 - database - DEBUG - Closing database session
2025-06-27 05:04:09,851 - database - DEBUG - Creating new database session
2025-06-27 05:04:10,152 - database - DEBUG - Database session used successfully
2025-06-27 05:04:10,153 - database - DEBUG - Closing database session
2025-06-27 05:04:11,343 - database - DEBUG - Creating new database session
2025-06-27 05:04:11,367 - database - DEBUG - Database session used successfully
2025-06-27 05:04:11,368 - database - DEBUG - Closing database session
2025-06-27 05:04:11,407 - database - DEBUG - Creating new database session
2025-06-27 05:04:11,430 - database - DEBUG - Database session used successfully
2025-06-27 05:04:11,430 - database - DEBUG - Closing database session
2025-06-27 05:04:11,436 - database - DEBUG - Creating new database session
2025-06-27 05:04:11,498 - database - DEBUG - Creating new database session
2025-06-27 05:04:11,578 - database - DEBUG - Database session used successfully
2025-06-27 05:04:11,579 - database - DEBUG - Closing database session
2025-06-27 05:04:12,778 - database - DEBUG - Database session used successfully
2025-06-27 05:04:12,782 - database - DEBUG - Closing database session
2025-06-27 05:04:12,820 - database - DEBUG - Creating new database session
2025-06-27 05:04:13,291 - database - DEBUG - Creating new database session
2025-06-27 05:04:15,929 - database - DEBUG - Database session used successfully
2025-06-27 05:04:15,930 - database - DEBUG - Closing database session
2025-06-27 05:04:17,001 - database - DEBUG - Creating new database session
2025-06-27 05:04:17,111 - database - DEBUG - Database session used successfully
2025-06-27 05:04:17,115 - database - DEBUG - Closing database session
2025-06-27 05:05:26,348 - database - DEBUG - Database session used successfully
2025-06-27 05:05:26,349 - database - DEBUG - Closing database session
2025-06-27 05:05:48,744 - database - DEBUG - Creating new database session
2025-06-27 05:06:02,532 - database - DEBUG - Database session used successfully
2025-06-27 05:06:02,532 - database - DEBUG - Closing database session
2025-06-27 05:06:03,236 - database - DEBUG - Creating new database session
2025-06-27 05:06:03,258 - database - DEBUG - Database session used successfully
2025-06-27 05:06:03,258 - database - DEBUG - Closing database session
2025-06-27 05:06:03,270 - database - DEBUG - Creating new database session
2025-06-27 05:06:03,292 - database - DEBUG - Database session used successfully
2025-06-27 05:06:03,292 - database - DEBUG - Closing database session
2025-06-27 05:06:03,303 - database - DEBUG - Creating new database session
2025-06-27 05:06:03,314 - database - DEBUG - Database session used successfully
2025-06-27 05:06:03,315 - database - DEBUG - Closing database session
2025-06-27 05:06:03,735 - database - DEBUG - Creating new database session
2025-06-27 05:06:03,997 - database - DEBUG - Creating new database session
2025-06-27 05:06:04,024 - database - DEBUG - Creating new database session
2025-06-27 05:06:04,135 - database - DEBUG - Database session used successfully
2025-06-27 05:06:04,136 - database - DEBUG - Closing database session
2025-06-27 05:06:04,860 - database - DEBUG - Creating new database session
2025-06-27 05:06:04,894 - database - DEBUG - Database session used successfully
2025-06-27 05:06:04,895 - database - DEBUG - Closing database session
2025-06-27 05:06:04,975 - database - DEBUG - Database session used successfully
2025-06-27 05:06:04,976 - database - DEBUG - Closing database session
2025-06-27 05:06:05,002 - database - DEBUG - Creating new database session
2025-06-27 05:06:05,039 - database - DEBUG - Database session used successfully
2025-06-27 05:06:05,040 - database - DEBUG - Closing database session
2025-06-27 05:06:05,075 - database - DEBUG - Creating new database session
2025-06-27 05:06:05,094 - database - DEBUG - Database session used successfully
2025-06-27 05:06:05,094 - database - DEBUG - Closing database session
2025-06-27 05:06:05,200 - database - DEBUG - Creating new database session
2025-06-27 05:06:05,209 - database - DEBUG - Database session used successfully
2025-06-27 05:06:05,209 - database - DEBUG - Closing database session
2025-06-27 05:06:05,672 - database - DEBUG - Database session used successfully
2025-06-27 05:06:05,672 - database - DEBUG - Closing database session
2025-06-27 05:06:05,680 - database - DEBUG - Creating new database session
2025-06-27 05:06:06,038 - database - DEBUG - Creating new database session
2025-06-27 05:06:06,350 - database - DEBUG - Database session used successfully
2025-06-27 05:06:06,358 - database - DEBUG - Closing database session
2025-06-27 05:06:06,401 - database - DEBUG - Creating new database session
2025-06-27 05:06:06,474 - database - DEBUG - Database session used successfully
2025-06-27 05:06:06,475 - database - DEBUG - Closing database session
2025-06-27 05:06:42,523 - database - DEBUG - Database session used successfully
2025-06-27 05:06:42,523 - database - DEBUG - Closing database session
2025-06-27 05:06:43,028 - database - DEBUG - Creating new database session
2025-06-27 05:06:43,037 - database - DEBUG - Database session used successfully
2025-06-27 05:06:43,038 - database - DEBUG - Closing database session
2025-06-27 05:06:43,046 - database - DEBUG - Creating new database session
2025-06-27 05:06:43,058 - database - DEBUG - Database session used successfully
2025-06-27 05:06:43,059 - database - DEBUG - Closing database session
2025-06-27 05:06:43,068 - database - DEBUG - Creating new database session
2025-06-27 05:06:43,393 - database - DEBUG - Creating new database session
2025-06-27 05:06:43,436 - database - DEBUG - Database session used successfully
2025-06-27 05:06:43,437 - database - DEBUG - Closing database session
2025-06-27 05:06:43,510 - database - DEBUG - Database session used successfully
2025-06-27 05:06:43,510 - database - DEBUG - Closing database session
2025-06-27 05:06:43,527 - database - DEBUG - Creating new database session
2025-06-27 05:06:44,109 - database - DEBUG - Database session used successfully
2025-06-27 05:06:44,110 - database - DEBUG - Closing database session
2025-06-27 05:06:44,200 - database - DEBUG - Creating new database session
2025-06-27 05:06:44,220 - database - DEBUG - Database session used successfully
2025-06-27 05:06:44,220 - database - DEBUG - Closing database session
2025-06-27 05:06:44,269 - database - DEBUG - Creating new database session
2025-06-27 05:07:12,574 - database - DEBUG - Creating new database session
2025-06-27 05:07:12,731 - database - DEBUG - Database session used successfully
2025-06-27 05:07:12,731 - database - DEBUG - Closing database session
2025-06-27 05:07:23,333 - database - DEBUG - Creating new database session
2025-06-27 05:07:23,440 - database - DEBUG - Database session used successfully
2025-06-27 05:07:23,441 - database - DEBUG - Closing database session
2025-06-27 05:07:48,804 - database - DEBUG - Creating new database session
2025-06-27 05:07:48,811 - database - ERROR - Error in database session: 500: An error occurred while refreshing token.
Traceback (most recent call last):
  File "C:\Users\Dhanush\FASTAPI\app\api\v1\endpoints\users.py", line 310, in refresh_access_token
     raise HTTPException(
    ...<3 lines>...
    )
fastapi.exceptions.HTTPException: 401: Invalid or expired refresh token

During handling of the above exception, another exception occurred:

Traceback (most recent call last):
  File "C:\Users\Dhanush\FASTAPI\app\database\session.py", line 65, in get_db
    yield session
  File "C:\Users\Dhanush\AppData\Local\Programs\Python\Python313\Lib\site-packages\fastapi\routing.py", line 301, in app
    raw_response = await run_endpoint_function(
                   ^^^^^^^^^^^^^^^^^^^^^^^^^^^^
    ...<3 lines>...
    )
    ^
  File "C:\Users\Dhanush\AppData\Local\Programs\Python\Python313\Lib\site-packages\fastapi\routing.py", line 212, in run_endpoint_function
    return await dependant.call(**values)
           ^^^^^^^^^^^^^^^^^^^^^^^^^^^^^^
  File "C:\Users\Dhanush\FASTAPI\app\api\v1\endpoints\users.py", line 360, in refresh_access_token
    raise HTTPException(
    ...<2 lines>...
    )
fastapi.exceptions.HTTPException: 500: An error occurred while refreshing token.
2025-06-27 05:07:48,818 - database - INFO - Session rolled back due to error
2025-06-27 05:07:48,819 - database - DEBUG - Closing database session
2025-06-27 05:07:59,918 - database - DEBUG - Creating new database session
2025-06-27 05:07:59,927 - database - DEBUG - Database session used successfully
2025-06-27 05:07:59,927 - database - DEBUG - Closing database session
2025-06-27 05:08:03,396 - database - DEBUG - Creating new database session
2025-06-27 05:08:03,403 - database - ERROR - Error in database session: 500: An error occurred while refreshing token.
Traceback (most recent call last):
  File "C:\Users\Dhanush\FASTAPI\app\api\v1\endpoints\users.py", line 310, in refresh_access_token
     raise HTTPException(
    ...<3 lines>...
    )
fastapi.exceptions.HTTPException: 401: Invalid or expired refresh token

During handling of the above exception, another exception occurred:

Traceback (most recent call last):
  File "C:\Users\Dhanush\FASTAPI\app\database\session.py", line 65, in get_db
    yield session
  File "C:\Users\Dhanush\AppData\Local\Programs\Python\Python313\Lib\site-packages\fastapi\routing.py", line 301, in app
    raw_response = await run_endpoint_function(
                   ^^^^^^^^^^^^^^^^^^^^^^^^^^^^
    ...<3 lines>...
    )
    ^
  File "C:\Users\Dhanush\AppData\Local\Programs\Python\Python313\Lib\site-packages\fastapi\routing.py", line 212, in run_endpoint_function
    return await dependant.call(**values)
           ^^^^^^^^^^^^^^^^^^^^^^^^^^^^^^
  File "C:\Users\Dhanush\FASTAPI\app\api\v1\endpoints\users.py", line 360, in refresh_access_token
    raise HTTPException(
    ...<2 lines>...
    )
fastapi.exceptions.HTTPException: 500: An error occurred while refreshing token.
2025-06-27 05:08:03,407 - database - INFO - Session rolled back due to error
2025-06-27 05:08:03,407 - database - DEBUG - Closing database session
2025-06-27 05:08:11,867 - database - DEBUG - Creating new database session
2025-06-27 05:08:11,887 - database - DEBUG - Database session used successfully
2025-06-27 05:08:11,889 - database - DEBUG - Closing database session
2025-06-27 05:09:00,606 - database - DEBUG - Creating new database session
2025-06-27 05:09:00,610 - database - ERROR - Error in database session: 500: An error occurred while refreshing token.
Traceback (most recent call last):
  File "C:\Users\Dhanush\FASTAPI\app\api\v1\endpoints\users.py", line 310, in refresh_access_token
     raise HTTPException(
    ...<3 lines>...
    )
fastapi.exceptions.HTTPException: 401: Invalid or expired refresh token

During handling of the above exception, another exception occurred:

Traceback (most recent call last):
  File "C:\Users\Dhanush\FASTAPI\app\database\session.py", line 65, in get_db
    yield session
  File "C:\Users\Dhanush\AppData\Local\Programs\Python\Python313\Lib\site-packages\fastapi\routing.py", line 301, in app
    raw_response = await run_endpoint_function(
                   ^^^^^^^^^^^^^^^^^^^^^^^^^^^^
    ...<3 lines>...
    )
    ^
  File "C:\Users\Dhanush\AppData\Local\Programs\Python\Python313\Lib\site-packages\fastapi\routing.py", line 212, in run_endpoint_function
    return await dependant.call(**values)
           ^^^^^^^^^^^^^^^^^^^^^^^^^^^^^^
  File "C:\Users\Dhanush\FASTAPI\app\api\v1\endpoints\users.py", line 360, in refresh_access_token
    raise HTTPException(
    ...<2 lines>...
    )
fastapi.exceptions.HTTPException: 500: An error occurred while refreshing token.
2025-06-27 05:09:00,611 - database - INFO - Session rolled back due to error
2025-06-27 05:09:00,612 - database - DEBUG - Closing database session
2025-06-27 05:09:15,041 - database - DEBUG - Creating new database session
2025-06-27 05:09:15,065 - database - DEBUG - Database session used successfully
2025-06-27 05:09:15,066 - database - DEBUG - Closing database session
2025-06-27 05:09:35,826 - database - DEBUG - Database session used successfully
2025-06-27 05:09:35,826 - database - DEBUG - Closing database session
2025-06-27 05:10:53,929 - database - DEBUG - Creating new database session
2025-06-27 05:10:54,751 - database - DEBUG - Database session used successfully
2025-06-27 05:10:54,752 - database - DEBUG - Closing database session
2025-06-27 05:10:55,888 - database - DEBUG - Creating new database session
2025-06-27 05:10:55,922 - database - DEBUG - Database session used successfully
2025-06-27 05:10:55,924 - database - DEBUG - Closing database session
2025-06-27 05:10:55,973 - database - DEBUG - Creating new database session
2025-06-27 05:10:55,987 - database - DEBUG - Creating new database session
2025-06-27 05:10:56,003 - database - DEBUG - Database session used successfully
2025-06-27 05:10:56,003 - database - DEBUG - Closing database session
2025-06-27 05:10:56,215 - database - DEBUG - Creating new database session
2025-06-27 05:10:56,272 - database - DEBUG - Database session used successfully
2025-06-27 05:10:56,273 - database - DEBUG - Closing database session
2025-06-27 05:10:57,105 - database - DEBUG - Database session used successfully
2025-06-27 05:10:57,107 - database - DEBUG - Closing database session
2025-06-27 05:10:57,134 - database - DEBUG - Creating new database session
2025-06-27 05:10:57,628 - database - DEBUG - Creating new database session
2025-06-27 05:10:58,778 - database - DEBUG - Database session used successfully
2025-06-27 05:10:58,780 - database - DEBUG - Closing database session
2025-06-27 05:10:58,823 - database - DEBUG - Creating new database session
2025-06-27 05:10:58,878 - database - DEBUG - Database session used successfully
2025-06-27 05:10:58,879 - database - DEBUG - Closing database session
2025-06-27 05:11:10,980 - database - DEBUG - Creating new database session
2025-06-27 05:11:11,012 - database - ERROR - Error in database session: 404: No wallet records found for this user.
Traceback (most recent call last):
  File "C:\Users\Dhanush\FASTAPI\app\database\session.py", line 65, in get_db
    yield session
  File "C:\Users\Dhanush\AppData\Local\Programs\Python\Python313\Lib\site-packages\fastapi\routing.py", line 301, in app
    raw_response = await run_endpoint_function(
                   ^^^^^^^^^^^^^^^^^^^^^^^^^^^^
    ...<3 lines>...
    )
    ^
  File "C:\Users\Dhanush\AppData\Local\Programs\Python\Python313\Lib\site-packages\fastapi\routing.py", line 212, in run_endpoint_function
    return await dependant.call(**values)
           ^^^^^^^^^^^^^^^^^^^^^^^^^^^^^^
  File "C:\Users\Dhanush\FASTAPI\app\api\v1\endpoints\wallets.py", line 39, in get_my_wallets
    raise HTTPException(
    ...<2 lines>...
    )
fastapi.exceptions.HTTPException: 404: No wallet records found for this user.
2025-06-27 05:11:11,028 - database - INFO - Session rolled back due to error
2025-06-27 05:11:11,028 - database - DEBUG - Closing database session
2025-06-27 05:11:21,687 - database - DEBUG - Creating new database session
2025-06-27 05:11:21,876 - database - DEBUG - Database session used successfully
2025-06-27 05:11:21,883 - database - DEBUG - Closing database session
2025-06-27 05:11:22,027 - database - DEBUG - Creating new database session
2025-06-27 05:11:24,666 - database - DEBUG - Database session used successfully
2025-06-27 05:11:24,667 - database - DEBUG - Closing database session
2025-06-27 05:11:50,379 - database - DEBUG - Creating new database session
2025-06-27 05:11:50,439 - database - DEBUG - Database session used successfully
2025-06-27 05:11:50,439 - database - DEBUG - Closing database session
2025-06-27 05:11:53,808 - database - DEBUG - Creating new database session
2025-06-27 05:11:53,900 - database - DEBUG - Database session used successfully
2025-06-27 05:11:53,901 - database - DEBUG - Closing database session
2025-06-27 05:11:55,876 - database - DEBUG - Creating new database session
2025-06-27 05:11:55,948 - database - ERROR - Error in database session: 500: An error occurred while refreshing token.
Traceback (most recent call last):
  File "C:\Users\Dhanush\FASTAPI\app\api\v1\endpoints\users.py", line 310, in refresh_access_token
     raise HTTPException(
    ...<3 lines>...
    )
fastapi.exceptions.HTTPException: 401: Invalid or expired refresh token

During handling of the above exception, another exception occurred:

Traceback (most recent call last):
  File "C:\Users\Dhanush\FASTAPI\app\database\session.py", line 65, in get_db
    yield session
  File "C:\Users\Dhanush\AppData\Local\Programs\Python\Python313\Lib\site-packages\fastapi\routing.py", line 301, in app
    raw_response = await run_endpoint_function(
                   ^^^^^^^^^^^^^^^^^^^^^^^^^^^^
    ...<3 lines>...
    )
    ^
  File "C:\Users\Dhanush\AppData\Local\Programs\Python\Python313\Lib\site-packages\fastapi\routing.py", line 212, in run_endpoint_function
    return await dependant.call(**values)
           ^^^^^^^^^^^^^^^^^^^^^^^^^^^^^^
  File "C:\Users\Dhanush\FASTAPI\app\api\v1\endpoints\users.py", line 360, in refresh_access_token
    raise HTTPException(
    ...<2 lines>...
    )
fastapi.exceptions.HTTPException: 500: An error occurred while refreshing token.
2025-06-27 05:11:55,977 - database - INFO - Session rolled back due to error
2025-06-27 05:11:55,984 - database - DEBUG - Closing database session
2025-06-27 05:12:12,720 - database - DEBUG - Creating new database session
2025-06-27 05:12:12,754 - database - DEBUG - Database session used successfully
2025-06-27 05:12:12,754 - database - DEBUG - Closing database session
2025-06-27 05:13:16,801 - database - DEBUG - Creating new database session
2025-06-27 05:13:17,197 - database - DEBUG - Database session used successfully
2025-06-27 05:13:17,198 - database - DEBUG - Closing database session
2025-06-27 05:13:38,329 - database - DEBUG - Creating new database session
2025-06-27 05:13:38,717 - database - DEBUG - Database session used successfully
2025-06-27 05:13:38,718 - database - DEBUG - Closing database session
2025-06-27 05:13:39,944 - database - DEBUG - Creating new database session
2025-06-27 05:13:39,972 - database - ERROR - Error in database session: 500: An error occurred while refreshing token.
Traceback (most recent call last):
  File "C:\Users\Dhanush\FASTAPI\app\api\v1\endpoints\users.py", line 310, in refresh_access_token
     raise HTTPException(
    ...<3 lines>...
    )
fastapi.exceptions.HTTPException: 401: Invalid or expired refresh token

During handling of the above exception, another exception occurred:

Traceback (most recent call last):
  File "C:\Users\Dhanush\FASTAPI\app\database\session.py", line 65, in get_db
    yield session
  File "C:\Users\Dhanush\AppData\Local\Programs\Python\Python313\Lib\site-packages\fastapi\routing.py", line 301, in app
    raw_response = await run_endpoint_function(
                   ^^^^^^^^^^^^^^^^^^^^^^^^^^^^
    ...<3 lines>...
    )
    ^
  File "C:\Users\Dhanush\AppData\Local\Programs\Python\Python313\Lib\site-packages\fastapi\routing.py", line 212, in run_endpoint_function
    return await dependant.call(**values)
           ^^^^^^^^^^^^^^^^^^^^^^^^^^^^^^
  File "C:\Users\Dhanush\FASTAPI\app\api\v1\endpoints\users.py", line 360, in refresh_access_token
    raise HTTPException(
    ...<2 lines>...
    )
fastapi.exceptions.HTTPException: 500: An error occurred while refreshing token.
2025-06-27 05:13:39,986 - database - INFO - Session rolled back due to error
2025-06-27 05:13:39,988 - database - DEBUG - Closing database session
2025-06-27 05:13:54,312 - database - DEBUG - Creating new database session
2025-06-27 05:13:54,456 - database - DEBUG - Database session used successfully
2025-06-27 05:13:54,457 - database - DEBUG - Closing database session
2025-06-27 05:13:57,692 - database - DEBUG - Creating new database session
2025-06-27 05:13:57,696 - database - ERROR - Error in database session: 500: An error occurred while refreshing token.
Traceback (most recent call last):
  File "C:\Users\Dhanush\FASTAPI\app\api\v1\endpoints\users.py", line 310, in refresh_access_token
     raise HTTPException(
    ...<3 lines>...
    )
fastapi.exceptions.HTTPException: 401: Invalid or expired refresh token

During handling of the above exception, another exception occurred:

Traceback (most recent call last):
  File "C:\Users\Dhanush\FASTAPI\app\database\session.py", line 65, in get_db
    yield session
  File "C:\Users\Dhanush\AppData\Local\Programs\Python\Python313\Lib\site-packages\fastapi\routing.py", line 301, in app
    raw_response = await run_endpoint_function(
                   ^^^^^^^^^^^^^^^^^^^^^^^^^^^^
    ...<3 lines>...
    )
    ^
  File "C:\Users\Dhanush\AppData\Local\Programs\Python\Python313\Lib\site-packages\fastapi\routing.py", line 212, in run_endpoint_function
    return await dependant.call(**values)
           ^^^^^^^^^^^^^^^^^^^^^^^^^^^^^^
  File "C:\Users\Dhanush\FASTAPI\app\api\v1\endpoints\users.py", line 360, in refresh_access_token
    raise HTTPException(
    ...<2 lines>...
    )
fastapi.exceptions.HTTPException: 500: An error occurred while refreshing token.
2025-06-27 05:13:57,698 - database - INFO - Session rolled back due to error
2025-06-27 05:13:57,699 - database - DEBUG - Closing database session
2025-06-27 05:14:23,834 - database - DEBUG - Creating new database session
2025-06-27 05:14:23,841 - database - ERROR - Error in database session: 500: An error occurred while refreshing token.
Traceback (most recent call last):
  File "C:\Users\Dhanush\FASTAPI\app\api\v1\endpoints\users.py", line 310, in refresh_access_token
     raise HTTPException(
    ...<3 lines>...
    )
fastapi.exceptions.HTTPException: 401: Invalid or expired refresh token

During handling of the above exception, another exception occurred:

Traceback (most recent call last):
  File "C:\Users\Dhanush\FASTAPI\app\database\session.py", line 65, in get_db
    yield session
  File "C:\Users\Dhanush\AppData\Local\Programs\Python\Python313\Lib\site-packages\fastapi\routing.py", line 301, in app
    raw_response = await run_endpoint_function(
                   ^^^^^^^^^^^^^^^^^^^^^^^^^^^^
    ...<3 lines>...
    )
    ^
  File "C:\Users\Dhanush\AppData\Local\Programs\Python\Python313\Lib\site-packages\fastapi\routing.py", line 212, in run_endpoint_function
    return await dependant.call(**values)
           ^^^^^^^^^^^^^^^^^^^^^^^^^^^^^^
  File "C:\Users\Dhanush\FASTAPI\app\api\v1\endpoints\users.py", line 360, in refresh_access_token
    raise HTTPException(
    ...<2 lines>...
    )
fastapi.exceptions.HTTPException: 500: An error occurred while refreshing token.
2025-06-27 05:14:23,845 - database - INFO - Session rolled back due to error
2025-06-27 05:14:23,845 - database - DEBUG - Closing database session
2025-06-27 05:14:40,257 - database - DEBUG - Database session used successfully
2025-06-27 05:14:40,258 - database - DEBUG - Closing database session
2025-06-27 05:14:40,774 - database - DEBUG - Creating new database session
2025-06-27 05:14:40,791 - database - DEBUG - Database session used successfully
2025-06-27 05:14:40,794 - database - DEBUG - Closing database session
2025-06-27 05:14:40,822 - database - DEBUG - Creating new database session
2025-06-27 05:14:40,849 - database - DEBUG - Database session used successfully
2025-06-27 05:14:40,851 - database - DEBUG - Closing database session
2025-06-27 05:14:40,856 - database - DEBUG - Creating new database session
2025-06-27 05:14:41,225 - database - DEBUG - Database session used successfully
2025-06-27 05:14:41,226 - database - DEBUG - Closing database session
2025-06-27 05:14:41,235 - database - DEBUG - Creating new database session
2025-06-27 05:14:41,586 - database - DEBUG - Creating new database session
2025-06-27 05:14:41,778 - database - DEBUG - Database session used successfully
2025-06-27 05:14:41,778 - database - DEBUG - Closing database session
2025-06-27 05:14:41,814 - database - DEBUG - Creating new database session
2025-06-27 05:14:41,836 - database - DEBUG - Database session used successfully
2025-06-27 05:14:41,837 - database - DEBUG - Closing database session
2025-06-27 05:14:42,613 - database - DEBUG - Creating new database session
2025-06-27 05:14:42,693 - database - DEBUG - Database session used successfully
2025-06-27 05:14:42,695 - database - DEBUG - Closing database session
2025-06-27 05:14:48,136 - database - DEBUG - Creating new database session
2025-06-27 05:14:48,148 - database - DEBUG - Database session used successfully
2025-06-27 05:14:48,148 - database - DEBUG - Closing database session
2025-06-27 05:14:58,194 - database - DEBUG - Creating new database session
2025-06-27 05:14:58,213 - database - DEBUG - Database session used successfully
2025-06-27 05:14:58,214 - database - DEBUG - Closing database session
2025-06-27 05:14:58,237 - database - DEBUG - Creating new database session
2025-06-27 05:15:00,412 - database - DEBUG - Database session used successfully
2025-06-27 05:15:00,412 - database - DEBUG - Closing database session
2025-06-27 05:15:32,384 - database - DEBUG - Creating new database session
2025-06-27 05:15:32,397 - database - DEBUG - Database session used successfully
2025-06-27 05:15:32,398 - database - DEBUG - Closing database session
2025-06-27 05:15:33,376 - database - DEBUG - Creating new database session
2025-06-27 05:15:33,403 - database - DEBUG - Database session used successfully
2025-06-27 05:15:33,404 - database - DEBUG - Closing database session
2025-06-27 05:15:45,506 - database - DEBUG - Creating new database session
2025-06-27 05:15:45,587 - database - DEBUG - Database session used successfully
2025-06-27 05:15:45,587 - database - DEBUG - Closing database session
2025-06-27 05:15:49,047 - database - DEBUG - Creating new database session
2025-06-27 05:15:49,054 - database - ERROR - Error in database session: 500: An error occurred while refreshing token.
Traceback (most recent call last):
  File "C:\Users\Dhanush\FASTAPI\app\api\v1\endpoints\users.py", line 310, in refresh_access_token
     raise HTTPException(
    ...<3 lines>...
    )
fastapi.exceptions.HTTPException: 401: Invalid or expired refresh token

During handling of the above exception, another exception occurred:

Traceback (most recent call last):
  File "C:\Users\Dhanush\FASTAPI\app\database\session.py", line 65, in get_db
    yield session
  File "C:\Users\Dhanush\AppData\Local\Programs\Python\Python313\Lib\site-packages\fastapi\routing.py", line 301, in app
    raw_response = await run_endpoint_function(
                   ^^^^^^^^^^^^^^^^^^^^^^^^^^^^
    ...<3 lines>...
    )
    ^
  File "C:\Users\Dhanush\AppData\Local\Programs\Python\Python313\Lib\site-packages\fastapi\routing.py", line 212, in run_endpoint_function
    return await dependant.call(**values)
           ^^^^^^^^^^^^^^^^^^^^^^^^^^^^^^
  File "C:\Users\Dhanush\FASTAPI\app\api\v1\endpoints\users.py", line 360, in refresh_access_token
    raise HTTPException(
    ...<2 lines>...
    )
fastapi.exceptions.HTTPException: 500: An error occurred while refreshing token.
2025-06-27 05:15:49,058 - database - INFO - Session rolled back due to error
2025-06-27 05:15:49,059 - database - DEBUG - Closing database session
2025-06-27 05:15:53,220 - database - DEBUG - Creating new database session
2025-06-27 05:15:54,002 - database - DEBUG - Creating new database session
2025-06-27 05:15:54,029 - database - DEBUG - Database session used successfully
2025-06-27 05:15:54,029 - database - DEBUG - Closing database session
2025-06-27 05:15:54,676 - database - DEBUG - Database session used successfully
2025-06-27 05:15:54,676 - database - DEBUG - Closing database session
2025-06-27 05:15:56,560 - database - DEBUG - Creating new database session
2025-06-27 05:15:56,576 - database - DEBUG - Database session used successfully
2025-06-27 05:15:56,576 - database - DEBUG - Closing database session
2025-06-27 05:17:07,750 - database - DEBUG - Database session used successfully
2025-06-27 05:17:07,777 - database - DEBUG - Closing database session
2025-06-27 05:17:34,778 - database - DEBUG - Creating new database session
2025-06-27 05:18:05,668 - database - DEBUG - Database session used successfully
2025-06-27 05:18:05,669 - database - DEBUG - Closing database session
2025-06-27 05:18:11,323 - database - DEBUG - Creating new database session
2025-06-27 05:18:11,326 - database - DEBUG - Creating new database session
2025-06-27 05:18:11,340 - database - ERROR - Error in database session: 500: An error occurred while refreshing token.
Traceback (most recent call last):
  File "C:\Users\Dhanush\FASTAPI\app\api\v1\endpoints\users.py", line 310, in refresh_access_token
     raise HTTPException(
    ...<3 lines>...
    )
fastapi.exceptions.HTTPException: 401: Invalid or expired refresh token

During handling of the above exception, another exception occurred:

Traceback (most recent call last):
  File "C:\Users\Dhanush\FASTAPI\app\database\session.py", line 65, in get_db
    yield session
  File "C:\Users\Dhanush\AppData\Local\Programs\Python\Python313\Lib\site-packages\fastapi\routing.py", line 301, in app
    raw_response = await run_endpoint_function(
                   ^^^^^^^^^^^^^^^^^^^^^^^^^^^^
    ...<3 lines>...
    )
    ^
  File "C:\Users\Dhanush\AppData\Local\Programs\Python\Python313\Lib\site-packages\fastapi\routing.py", line 212, in run_endpoint_function
    return await dependant.call(**values)
           ^^^^^^^^^^^^^^^^^^^^^^^^^^^^^^
  File "C:\Users\Dhanush\FASTAPI\app\api\v1\endpoints\users.py", line 360, in refresh_access_token
    raise HTTPException(
    ...<2 lines>...
    )
fastapi.exceptions.HTTPException: 500: An error occurred while refreshing token.
2025-06-27 05:18:11,349 - database - INFO - Session rolled back due to error
2025-06-27 05:18:11,349 - database - DEBUG - Closing database session
2025-06-27 05:18:17,561 - database - DEBUG - Creating new database session
2025-06-27 05:18:18,570 - database - DEBUG - Database session used successfully
2025-06-27 05:18:18,579 - database - DEBUG - Closing database session
2025-06-27 05:18:32,436 - database - DEBUG - Creating new database session
2025-06-27 05:18:32,493 - database - ERROR - Error in database session: 500: An error occurred while refreshing token.
Traceback (most recent call last):
  File "C:\Users\Dhanush\FASTAPI\app\api\v1\endpoints\users.py", line 310, in refresh_access_token
     raise HTTPException(
    ...<3 lines>...
    )
fastapi.exceptions.HTTPException: 401: Invalid or expired refresh token

During handling of the above exception, another exception occurred:

Traceback (most recent call last):
  File "C:\Users\Dhanush\FASTAPI\app\database\session.py", line 65, in get_db
    yield session
  File "C:\Users\Dhanush\AppData\Local\Programs\Python\Python313\Lib\site-packages\fastapi\routing.py", line 301, in app
    raw_response = await run_endpoint_function(
                   ^^^^^^^^^^^^^^^^^^^^^^^^^^^^
    ...<3 lines>...
    )
    ^
  File "C:\Users\Dhanush\AppData\Local\Programs\Python\Python313\Lib\site-packages\fastapi\routing.py", line 212, in run_endpoint_function
    return await dependant.call(**values)
           ^^^^^^^^^^^^^^^^^^^^^^^^^^^^^^
  File "C:\Users\Dhanush\FASTAPI\app\api\v1\endpoints\users.py", line 360, in refresh_access_token
    raise HTTPException(
    ...<2 lines>...
    )
fastapi.exceptions.HTTPException: 500: An error occurred while refreshing token.
2025-06-27 05:18:32,511 - database - INFO - Session rolled back due to error
2025-06-27 05:18:32,515 - database - DEBUG - Closing database session
2025-06-27 05:18:48,076 - database - DEBUG - Creating new database session
2025-06-27 05:18:48,128 - database - DEBUG - Database session used successfully
2025-06-27 05:18:48,130 - database - DEBUG - Closing database session
2025-06-27 05:18:52,489 - database - DEBUG - Creating new database session
2025-06-27 05:18:52,568 - database - ERROR - Error in database session: 500: An error occurred while refreshing token.
Traceback (most recent call last):
  File "C:\Users\Dhanush\FASTAPI\app\api\v1\endpoints\users.py", line 310, in refresh_access_token
     raise HTTPException(
    ...<3 lines>...
    )
fastapi.exceptions.HTTPException: 401: Invalid or expired refresh token

During handling of the above exception, another exception occurred:

Traceback (most recent call last):
  File "C:\Users\Dhanush\FASTAPI\app\database\session.py", line 65, in get_db
    yield session
  File "C:\Users\Dhanush\AppData\Local\Programs\Python\Python313\Lib\site-packages\fastapi\routing.py", line 301, in app
    raw_response = await run_endpoint_function(
                   ^^^^^^^^^^^^^^^^^^^^^^^^^^^^
    ...<3 lines>...
    )
    ^
  File "C:\Users\Dhanush\AppData\Local\Programs\Python\Python313\Lib\site-packages\fastapi\routing.py", line 212, in run_endpoint_function
    return await dependant.call(**values)
           ^^^^^^^^^^^^^^^^^^^^^^^^^^^^^^
  File "C:\Users\Dhanush\FASTAPI\app\api\v1\endpoints\users.py", line 360, in refresh_access_token
    raise HTTPException(
    ...<2 lines>...
    )
fastapi.exceptions.HTTPException: 500: An error occurred while refreshing token.
2025-06-27 05:18:52,593 - database - INFO - Session rolled back due to error
2025-06-27 05:18:52,597 - database - DEBUG - Closing database session
2025-06-27 05:19:09,307 - database - DEBUG - Database session used successfully
2025-06-27 05:19:09,313 - database - DEBUG - Closing database session
2025-06-27 05:19:11,905 - database - DEBUG - Creating new database session
2025-06-27 05:19:12,220 - database - DEBUG - Database session used successfully
2025-06-27 05:19:12,221 - database - DEBUG - Closing database session
2025-06-27 05:19:13,485 - database - DEBUG - Creating new database session
2025-06-27 05:19:13,509 - database - DEBUG - Database session used successfully
2025-06-27 05:19:13,510 - database - DEBUG - Closing database session
2025-06-27 05:19:13,564 - database - DEBUG - Creating new database session
2025-06-27 05:19:13,596 - database - DEBUG - Creating new database session
2025-06-27 05:19:13,625 - database - DEBUG - Database session used successfully
2025-06-27 05:19:13,625 - database - DEBUG - Closing database session
2025-06-27 05:19:13,736 - database - DEBUG - Creating new database session
2025-06-27 05:19:13,849 - database - DEBUG - Database session used successfully
2025-06-27 05:19:13,851 - database - DEBUG - Closing database session
2025-06-27 05:19:14,967 - database - DEBUG - Database session used successfully
2025-06-27 05:19:14,968 - database - DEBUG - Closing database session
2025-06-27 05:19:14,982 - database - DEBUG - Creating new database session
2025-06-27 05:19:15,339 - database - DEBUG - Creating new database session
2025-06-27 05:19:16,113 - database - DEBUG - Database session used successfully
2025-06-27 05:19:16,113 - database - DEBUG - Closing database session
2025-06-27 05:19:16,201 - database - DEBUG - Creating new database session
2025-06-27 05:19:16,255 - database - DEBUG - Database session used successfully
2025-06-27 05:19:16,256 - database - DEBUG - Closing database session
2025-06-27 05:19:31,125 - database - DEBUG - Creating new database session
2025-06-27 05:19:31,237 - database - DEBUG - Database session used successfully
2025-06-27 05:19:31,238 - database - DEBUG - Closing database session
2025-06-27 05:19:43,150 - database - DEBUG - Database session used successfully
2025-06-27 05:19:43,150 - database - DEBUG - Closing database session
2025-06-27 05:25:33,752 - database - DEBUG - Creating new database session
2025-06-27 05:25:38,069 - database - DEBUG - Creating new database session
2025-06-27 05:25:38,097 - database - DEBUG - Database session used successfully
2025-06-27 05:25:38,097 - database - DEBUG - Closing database session
2025-06-27 05:25:56,449 - database - DEBUG - Creating new database session
2025-06-27 05:25:56,457 - database - ERROR - Error in database session: 500: An error occurred while refreshing token.
Traceback (most recent call last):
  File "C:\Users\Dhanush\FASTAPI\app\api\v1\endpoints\users.py", line 310, in refresh_access_token
     raise HTTPException(
    ...<3 lines>...
    )
fastapi.exceptions.HTTPException: 401: Invalid or expired refresh token

During handling of the above exception, another exception occurred:

Traceback (most recent call last):
  File "C:\Users\Dhanush\FASTAPI\app\database\session.py", line 65, in get_db
    yield session
  File "C:\Users\Dhanush\AppData\Local\Programs\Python\Python313\Lib\site-packages\fastapi\routing.py", line 301, in app
    raw_response = await run_endpoint_function(
                   ^^^^^^^^^^^^^^^^^^^^^^^^^^^^
    ...<3 lines>...
    )
    ^
  File "C:\Users\Dhanush\AppData\Local\Programs\Python\Python313\Lib\site-packages\fastapi\routing.py", line 212, in run_endpoint_function
    return await dependant.call(**values)
           ^^^^^^^^^^^^^^^^^^^^^^^^^^^^^^
  File "C:\Users\Dhanush\FASTAPI\app\api\v1\endpoints\users.py", line 360, in refresh_access_token
    raise HTTPException(
    ...<2 lines>...
    )
fastapi.exceptions.HTTPException: 500: An error occurred while refreshing token.
2025-06-27 05:25:56,460 - database - INFO - Session rolled back due to error
2025-06-27 05:25:56,462 - database - DEBUG - Closing database session
2025-06-27 05:26:24,273 - database - DEBUG - Creating new database session
2025-06-27 05:26:26,542 - database - DEBUG - Database session used successfully
2025-06-27 05:26:26,543 - database - DEBUG - Closing database session
2025-06-27 05:26:52,223 - database - DEBUG - Creating new database session
2025-06-27 05:26:52,555 - database - DEBUG - Database session used successfully
2025-06-27 05:26:52,556 - database - DEBUG - Closing database session
2025-06-27 05:26:56,444 - database - DEBUG - Creating new database session
2025-06-27 05:26:56,454 - database - ERROR - Error in database session: 500: An error occurred while refreshing token.
Traceback (most recent call last):
  File "C:\Users\Dhanush\FASTAPI\app\api\v1\endpoints\users.py", line 310, in refresh_access_token
     raise HTTPException(
    ...<3 lines>...
    )
fastapi.exceptions.HTTPException: 401: Invalid or expired refresh token

During handling of the above exception, another exception occurred:

Traceback (most recent call last):
  File "C:\Users\Dhanush\FASTAPI\app\database\session.py", line 65, in get_db
    yield session
  File "C:\Users\Dhanush\AppData\Local\Programs\Python\Python313\Lib\site-packages\fastapi\routing.py", line 301, in app
    raw_response = await run_endpoint_function(
                   ^^^^^^^^^^^^^^^^^^^^^^^^^^^^
    ...<3 lines>...
    )
    ^
  File "C:\Users\Dhanush\AppData\Local\Programs\Python\Python313\Lib\site-packages\fastapi\routing.py", line 212, in run_endpoint_function
    return await dependant.call(**values)
           ^^^^^^^^^^^^^^^^^^^^^^^^^^^^^^
  File "C:\Users\Dhanush\FASTAPI\app\api\v1\endpoints\users.py", line 360, in refresh_access_token
    raise HTTPException(
    ...<2 lines>...
    )
fastapi.exceptions.HTTPException: 500: An error occurred while refreshing token.
2025-06-27 05:26:56,459 - database - INFO - Session rolled back due to error
2025-06-27 05:26:56,459 - database - DEBUG - Closing database session
2025-06-27 05:27:22,513 - database - DEBUG - Creating new database session
2025-06-27 05:27:22,535 - database - ERROR - Error in database session: 500: An error occurred while refreshing token.
Traceback (most recent call last):
  File "C:\Users\Dhanush\FASTAPI\app\api\v1\endpoints\users.py", line 310, in refresh_access_token
     raise HTTPException(
    ...<3 lines>...
    )
fastapi.exceptions.HTTPException: 401: Invalid or expired refresh token

During handling of the above exception, another exception occurred:

Traceback (most recent call last):
  File "C:\Users\Dhanush\FASTAPI\app\database\session.py", line 65, in get_db
    yield session
  File "C:\Users\Dhanush\AppData\Local\Programs\Python\Python313\Lib\site-packages\fastapi\routing.py", line 301, in app
    raw_response = await run_endpoint_function(
                   ^^^^^^^^^^^^^^^^^^^^^^^^^^^^
    ...<3 lines>...
    )
    ^
  File "C:\Users\Dhanush\AppData\Local\Programs\Python\Python313\Lib\site-packages\fastapi\routing.py", line 212, in run_endpoint_function
    return await dependant.call(**values)
           ^^^^^^^^^^^^^^^^^^^^^^^^^^^^^^
  File "C:\Users\Dhanush\FASTAPI\app\api\v1\endpoints\users.py", line 360, in refresh_access_token
    raise HTTPException(
    ...<2 lines>...
    )
fastapi.exceptions.HTTPException: 500: An error occurred while refreshing token.
2025-06-27 05:27:22,556 - database - INFO - Session rolled back due to error
2025-06-27 05:27:22,559 - database - DEBUG - Closing database session
2025-06-27 05:27:24,379 - database - DEBUG - Creating new database session
2025-06-27 05:27:24,448 - database - ERROR - Error in database session: 500: An error occurred while refreshing token.
Traceback (most recent call last):
  File "C:\Users\Dhanush\FASTAPI\app\api\v1\endpoints\users.py", line 310, in refresh_access_token
     raise HTTPException(
    ...<3 lines>...
    )
fastapi.exceptions.HTTPException: 401: Invalid or expired refresh token

During handling of the above exception, another exception occurred:

Traceback (most recent call last):
  File "C:\Users\Dhanush\FASTAPI\app\database\session.py", line 65, in get_db
    yield session
  File "C:\Users\Dhanush\AppData\Local\Programs\Python\Python313\Lib\site-packages\fastapi\routing.py", line 301, in app
    raw_response = await run_endpoint_function(
                   ^^^^^^^^^^^^^^^^^^^^^^^^^^^^
    ...<3 lines>...
    )
    ^
  File "C:\Users\Dhanush\AppData\Local\Programs\Python\Python313\Lib\site-packages\fastapi\routing.py", line 212, in run_endpoint_function
    return await dependant.call(**values)
           ^^^^^^^^^^^^^^^^^^^^^^^^^^^^^^
  File "C:\Users\Dhanush\FASTAPI\app\api\v1\endpoints\users.py", line 360, in refresh_access_token
    raise HTTPException(
    ...<2 lines>...
    )
fastapi.exceptions.HTTPException: 500: An error occurred while refreshing token.
2025-06-27 05:27:24,454 - database - INFO - Session rolled back due to error
2025-06-27 05:27:24,458 - database - DEBUG - Closing database session
2025-06-27 05:27:34,149 - database - DEBUG - Creating new database session
2025-06-27 05:27:34,155 - database - ERROR - Error in database session: 500: An error occurred while refreshing token.
Traceback (most recent call last):
  File "C:\Users\Dhanush\FASTAPI\app\api\v1\endpoints\users.py", line 310, in refresh_access_token
     raise HTTPException(
    ...<3 lines>...
    )
fastapi.exceptions.HTTPException: 401: Invalid or expired refresh token

During handling of the above exception, another exception occurred:

Traceback (most recent call last):
  File "C:\Users\Dhanush\FASTAPI\app\database\session.py", line 65, in get_db
    yield session
  File "C:\Users\Dhanush\AppData\Local\Programs\Python\Python313\Lib\site-packages\fastapi\routing.py", line 301, in app
    raw_response = await run_endpoint_function(
                   ^^^^^^^^^^^^^^^^^^^^^^^^^^^^
    ...<3 lines>...
    )
    ^
  File "C:\Users\Dhanush\AppData\Local\Programs\Python\Python313\Lib\site-packages\fastapi\routing.py", line 212, in run_endpoint_function
    return await dependant.call(**values)
           ^^^^^^^^^^^^^^^^^^^^^^^^^^^^^^
  File "C:\Users\Dhanush\FASTAPI\app\api\v1\endpoints\users.py", line 360, in refresh_access_token
    raise HTTPException(
    ...<2 lines>...
    )
fastapi.exceptions.HTTPException: 500: An error occurred while refreshing token.
2025-06-27 05:27:34,157 - database - INFO - Session rolled back due to error
2025-06-27 05:27:34,158 - database - DEBUG - Closing database session
2025-06-27 05:27:59,424 - database - DEBUG - Creating new database session
2025-06-27 05:27:59,441 - database - ERROR - Error in database session: 500: An error occurred while refreshing token.
Traceback (most recent call last):
  File "C:\Users\Dhanush\FASTAPI\app\api\v1\endpoints\users.py", line 310, in refresh_access_token
     raise HTTPException(
    ...<3 lines>...
    )
fastapi.exceptions.HTTPException: 401: Invalid or expired refresh token

During handling of the above exception, another exception occurred:

Traceback (most recent call last):
  File "C:\Users\Dhanush\FASTAPI\app\database\session.py", line 65, in get_db
    yield session
  File "C:\Users\Dhanush\AppData\Local\Programs\Python\Python313\Lib\site-packages\fastapi\routing.py", line 301, in app
    raw_response = await run_endpoint_function(
                   ^^^^^^^^^^^^^^^^^^^^^^^^^^^^
    ...<3 lines>...
    )
    ^
  File "C:\Users\Dhanush\AppData\Local\Programs\Python\Python313\Lib\site-packages\fastapi\routing.py", line 212, in run_endpoint_function
    return await dependant.call(**values)
           ^^^^^^^^^^^^^^^^^^^^^^^^^^^^^^
  File "C:\Users\Dhanush\FASTAPI\app\api\v1\endpoints\users.py", line 360, in refresh_access_token
    raise HTTPException(
    ...<2 lines>...
    )
fastapi.exceptions.HTTPException: 500: An error occurred while refreshing token.
2025-06-27 05:27:59,451 - database - INFO - Session rolled back due to error
2025-06-27 05:27:59,452 - database - DEBUG - Closing database session
2025-06-27 05:28:06,424 - database - DEBUG - Creating new database session
2025-06-27 05:28:06,575 - database - DEBUG - Database session used successfully
2025-06-27 05:28:06,575 - database - DEBUG - Closing database session
2025-06-27 05:29:14,959 - database - DEBUG - Creating new database session
2025-06-27 05:29:15,056 - database - DEBUG - Database session used successfully
2025-06-27 05:29:15,057 - database - DEBUG - Closing database session
2025-06-27 05:29:18,195 - database - DEBUG - Creating new database session
2025-06-27 05:29:18,201 - database - ERROR - Error in database session: 500: An error occurred while refreshing token.
Traceback (most recent call last):
  File "C:\Users\Dhanush\FASTAPI\app\api\v1\endpoints\users.py", line 310, in refresh_access_token
     raise HTTPException(
    ...<3 lines>...
    )
fastapi.exceptions.HTTPException: 401: Invalid or expired refresh token

During handling of the above exception, another exception occurred:

Traceback (most recent call last):
  File "C:\Users\Dhanush\FASTAPI\app\database\session.py", line 65, in get_db
    yield session
  File "C:\Users\Dhanush\AppData\Local\Programs\Python\Python313\Lib\site-packages\fastapi\routing.py", line 301, in app
    raw_response = await run_endpoint_function(
                   ^^^^^^^^^^^^^^^^^^^^^^^^^^^^
    ...<3 lines>...
    )
    ^
  File "C:\Users\Dhanush\AppData\Local\Programs\Python\Python313\Lib\site-packages\fastapi\routing.py", line 212, in run_endpoint_function
    return await dependant.call(**values)
           ^^^^^^^^^^^^^^^^^^^^^^^^^^^^^^
  File "C:\Users\Dhanush\FASTAPI\app\api\v1\endpoints\users.py", line 360, in refresh_access_token
    raise HTTPException(
    ...<2 lines>...
    )
fastapi.exceptions.HTTPException: 500: An error occurred while refreshing token.
2025-06-27 05:29:18,205 - database - INFO - Session rolled back due to error
2025-06-27 05:29:18,206 - database - DEBUG - Closing database session
2025-06-27 05:29:24,872 - database - DEBUG - Creating new database session
2025-06-27 05:29:24,909 - database - DEBUG - Database session used successfully
2025-06-27 05:29:24,913 - database - DEBUG - Closing database session
2025-06-27 05:29:34,522 - database - DEBUG - Creating new database session
2025-06-27 05:29:34,535 - database - ERROR - Error in database session: 500: An error occurred while refreshing token.
Traceback (most recent call last):
  File "C:\Users\Dhanush\FASTAPI\app\api\v1\endpoints\users.py", line 310, in refresh_access_token
     raise HTTPException(
    ...<3 lines>...
    )
fastapi.exceptions.HTTPException: 401: Invalid or expired refresh token

During handling of the above exception, another exception occurred:

Traceback (most recent call last):
  File "C:\Users\Dhanush\FASTAPI\app\database\session.py", line 65, in get_db
    yield session
  File "C:\Users\Dhanush\AppData\Local\Programs\Python\Python313\Lib\site-packages\fastapi\routing.py", line 301, in app
    raw_response = await run_endpoint_function(
                   ^^^^^^^^^^^^^^^^^^^^^^^^^^^^
    ...<3 lines>...
    )
    ^
  File "C:\Users\Dhanush\AppData\Local\Programs\Python\Python313\Lib\site-packages\fastapi\routing.py", line 212, in run_endpoint_function
    return await dependant.call(**values)
           ^^^^^^^^^^^^^^^^^^^^^^^^^^^^^^
  File "C:\Users\Dhanush\FASTAPI\app\api\v1\endpoints\users.py", line 360, in refresh_access_token
    raise HTTPException(
    ...<2 lines>...
    )
fastapi.exceptions.HTTPException: 500: An error occurred while refreshing token.
2025-06-27 05:29:34,540 - database - INFO - Session rolled back due to error
2025-06-27 05:29:34,543 - database - DEBUG - Closing database session
2025-06-27 05:29:47,815 - database - DEBUG - Creating new database session
2025-06-27 05:29:47,864 - database - ERROR - Error in database session: 500: An error occurred while refreshing token.
Traceback (most recent call last):
  File "C:\Users\Dhanush\FASTAPI\app\api\v1\endpoints\users.py", line 310, in refresh_access_token
     raise HTTPException(
    ...<3 lines>...
    )
fastapi.exceptions.HTTPException: 401: Invalid or expired refresh token

During handling of the above exception, another exception occurred:

Traceback (most recent call last):
  File "C:\Users\Dhanush\FASTAPI\app\database\session.py", line 65, in get_db
    yield session
  File "C:\Users\Dhanush\AppData\Local\Programs\Python\Python313\Lib\site-packages\fastapi\routing.py", line 301, in app
    raw_response = await run_endpoint_function(
                   ^^^^^^^^^^^^^^^^^^^^^^^^^^^^
    ...<3 lines>...
    )
    ^
  File "C:\Users\Dhanush\AppData\Local\Programs\Python\Python313\Lib\site-packages\fastapi\routing.py", line 212, in run_endpoint_function
    return await dependant.call(**values)
           ^^^^^^^^^^^^^^^^^^^^^^^^^^^^^^
  File "C:\Users\Dhanush\FASTAPI\app\api\v1\endpoints\users.py", line 360, in refresh_access_token
    raise HTTPException(
    ...<2 lines>...
    )
fastapi.exceptions.HTTPException: 500: An error occurred while refreshing token.
2025-06-27 05:29:47,885 - database - INFO - Session rolled back due to error
2025-06-27 05:29:47,901 - database - DEBUG - Closing database session
2025-06-27 05:30:17,835 - database - DEBUG - Creating new database session
2025-06-27 05:30:17,839 - database - ERROR - Error in database session: 500: An error occurred while refreshing token.
Traceback (most recent call last):
  File "C:\Users\Dhanush\FASTAPI\app\api\v1\endpoints\users.py", line 310, in refresh_access_token
     raise HTTPException(
    ...<3 lines>...
    )
fastapi.exceptions.HTTPException: 401: Invalid or expired refresh token

During handling of the above exception, another exception occurred:

Traceback (most recent call last):
  File "C:\Users\Dhanush\FASTAPI\app\database\session.py", line 65, in get_db
    yield session
  File "C:\Users\Dhanush\AppData\Local\Programs\Python\Python313\Lib\site-packages\fastapi\routing.py", line 301, in app
    raw_response = await run_endpoint_function(
                   ^^^^^^^^^^^^^^^^^^^^^^^^^^^^
    ...<3 lines>...
    )
    ^
  File "C:\Users\Dhanush\AppData\Local\Programs\Python\Python313\Lib\site-packages\fastapi\routing.py", line 212, in run_endpoint_function
    return await dependant.call(**values)
           ^^^^^^^^^^^^^^^^^^^^^^^^^^^^^^
  File "C:\Users\Dhanush\FASTAPI\app\api\v1\endpoints\users.py", line 360, in refresh_access_token
    raise HTTPException(
    ...<2 lines>...
    )
fastapi.exceptions.HTTPException: 500: An error occurred while refreshing token.
2025-06-27 05:30:17,842 - database - INFO - Session rolled back due to error
2025-06-27 05:30:17,842 - database - DEBUG - Closing database session
2025-06-27 05:30:30,794 - database - DEBUG - Creating new database session
2025-06-27 05:30:30,876 - database - DEBUG - Database session used successfully
2025-06-27 05:30:30,877 - database - DEBUG - Closing database session
2025-06-27 05:30:39,046 - database - DEBUG - Creating new database session
2025-06-27 05:30:39,069 - database - DEBUG - Database session used successfully
2025-06-27 05:30:39,069 - database - DEBUG - Closing database session
2025-06-27 05:30:50,153 - database - DEBUG - Database session used successfully
2025-06-27 05:30:50,153 - database - DEBUG - Closing database session
2025-06-27 05:34:18,778 - database - DEBUG - Creating new database session
2025-06-27 05:34:20,757 - database - DEBUG - Creating new database session
2025-06-27 05:34:20,787 - database - DEBUG - Database session used successfully
2025-06-27 05:34:20,788 - database - DEBUG - Closing database session
2025-06-27 05:34:25,886 - database - DEBUG - Creating new database session
2025-06-27 05:34:25,891 - database - ERROR - Error in database session: 500: An error occurred while refreshing token.
Traceback (most recent call last):
  File "C:\Users\Dhanush\FASTAPI\app\api\v1\endpoints\users.py", line 310, in refresh_access_token
     raise HTTPException(
    ...<3 lines>...
    )
fastapi.exceptions.HTTPException: 401: Invalid or expired refresh token

During handling of the above exception, another exception occurred:

Traceback (most recent call last):
  File "C:\Users\Dhanush\FASTAPI\app\database\session.py", line 65, in get_db
    yield session
  File "C:\Users\Dhanush\AppData\Local\Programs\Python\Python313\Lib\site-packages\fastapi\routing.py", line 301, in app
    raw_response = await run_endpoint_function(
                   ^^^^^^^^^^^^^^^^^^^^^^^^^^^^
    ...<3 lines>...
    )
    ^
  File "C:\Users\Dhanush\AppData\Local\Programs\Python\Python313\Lib\site-packages\fastapi\routing.py", line 212, in run_endpoint_function
    return await dependant.call(**values)
           ^^^^^^^^^^^^^^^^^^^^^^^^^^^^^^
  File "C:\Users\Dhanush\FASTAPI\app\api\v1\endpoints\users.py", line 360, in refresh_access_token
    raise HTTPException(
    ...<2 lines>...
    )
fastapi.exceptions.HTTPException: 500: An error occurred while refreshing token.
2025-06-27 05:34:25,897 - database - INFO - Session rolled back due to error
2025-06-27 05:34:25,898 - database - DEBUG - Closing database session
2025-06-27 05:34:27,055 - database - DEBUG - Creating new database session
2025-06-27 05:34:27,077 - database - DEBUG - Database session used successfully
2025-06-27 05:34:27,078 - database - DEBUG - Closing database session
2025-06-27 05:35:39,081 - database - DEBUG - Creating new database session
2025-06-27 05:35:39,145 - database - DEBUG - Database session used successfully
2025-06-27 05:35:39,146 - database - DEBUG - Closing database session
2025-06-27 05:35:43,651 - database - DEBUG - Creating new database session
2025-06-27 05:35:43,691 - database - DEBUG - Database session used successfully
2025-06-27 05:35:43,693 - database - DEBUG - Closing database session
2025-06-27 05:35:44,912 - database - DEBUG - Creating new database session
2025-06-27 05:35:44,945 - database - ERROR - Error in database session: 500: An error occurred while refreshing token.
Traceback (most recent call last):
  File "C:\Users\Dhanush\FASTAPI\app\api\v1\endpoints\users.py", line 310, in refresh_access_token
     raise HTTPException(
    ...<3 lines>...
    )
fastapi.exceptions.HTTPException: 401: Invalid or expired refresh token

During handling of the above exception, another exception occurred:

Traceback (most recent call last):
  File "C:\Users\Dhanush\FASTAPI\app\database\session.py", line 65, in get_db
    yield session
  File "C:\Users\Dhanush\AppData\Local\Programs\Python\Python313\Lib\site-packages\fastapi\routing.py", line 301, in app
    raw_response = await run_endpoint_function(
                   ^^^^^^^^^^^^^^^^^^^^^^^^^^^^
    ...<3 lines>...
    )
    ^
  File "C:\Users\Dhanush\AppData\Local\Programs\Python\Python313\Lib\site-packages\fastapi\routing.py", line 212, in run_endpoint_function
    return await dependant.call(**values)
           ^^^^^^^^^^^^^^^^^^^^^^^^^^^^^^
  File "C:\Users\Dhanush\FASTAPI\app\api\v1\endpoints\users.py", line 360, in refresh_access_token
    raise HTTPException(
    ...<2 lines>...
    )
fastapi.exceptions.HTTPException: 500: An error occurred while refreshing token.
2025-06-27 05:35:44,950 - database - INFO - Session rolled back due to error
2025-06-27 05:35:44,962 - database - DEBUG - Closing database session
2025-06-27 05:36:35,327 - database - DEBUG - Database session used successfully
2025-06-27 05:36:35,328 - database - DEBUG - Closing database session
2025-06-27 05:36:52,756 - database - DEBUG - Creating new database session
2025-06-27 05:36:52,893 - database - DEBUG - Database session used successfully
2025-06-27 05:36:52,893 - database - DEBUG - Closing database session
2025-06-27 05:36:56,760 - database - DEBUG - Creating new database session
2025-06-27 05:36:59,574 - database - DEBUG - Creating new database session
2025-06-27 05:36:59,578 - database - ERROR - Error in database session: 500: An error occurred while refreshing token.
Traceback (most recent call last):
  File "C:\Users\Dhanush\FASTAPI\app\api\v1\endpoints\users.py", line 310, in refresh_access_token
     raise HTTPException(
    ...<3 lines>...
    )
fastapi.exceptions.HTTPException: 401: Invalid or expired refresh token

During handling of the above exception, another exception occurred:

Traceback (most recent call last):
  File "C:\Users\Dhanush\FASTAPI\app\database\session.py", line 65, in get_db
    yield session
  File "C:\Users\Dhanush\AppData\Local\Programs\Python\Python313\Lib\site-packages\fastapi\routing.py", line 301, in app
    raw_response = await run_endpoint_function(
                   ^^^^^^^^^^^^^^^^^^^^^^^^^^^^
    ...<3 lines>...
    )
    ^
  File "C:\Users\Dhanush\AppData\Local\Programs\Python\Python313\Lib\site-packages\fastapi\routing.py", line 212, in run_endpoint_function
    return await dependant.call(**values)
           ^^^^^^^^^^^^^^^^^^^^^^^^^^^^^^
  File "C:\Users\Dhanush\FASTAPI\app\api\v1\endpoints\users.py", line 360, in refresh_access_token
    raise HTTPException(
    ...<2 lines>...
    )
fastapi.exceptions.HTTPException: 500: An error occurred while refreshing token.
2025-06-27 05:36:59,581 - database - INFO - Session rolled back due to error
2025-06-27 05:36:59,582 - database - DEBUG - Closing database session
2025-06-27 05:37:01,597 - database - DEBUG - Creating new database session
2025-06-27 05:37:01,611 - database - DEBUG - Database session used successfully
2025-06-27 05:37:01,612 - database - DEBUG - Closing database session
2025-06-27 05:37:07,443 - database - DEBUG - Creating new database session
2025-06-27 05:37:10,050 - database - DEBUG - Database session used successfully
2025-06-27 05:37:10,052 - database - DEBUG - Closing database session
2025-06-27 05:37:29,126 - database - DEBUG - Creating new database session
2025-06-27 05:37:30,703 - database - DEBUG - Database session used successfully
2025-06-27 05:37:30,704 - database - DEBUG - Closing database session
2025-06-27 05:38:06,447 - database - DEBUG - Creating new database session
2025-06-27 05:38:06,484 - database - DEBUG - Database session used successfully
2025-06-27 05:38:06,485 - database - DEBUG - Closing database session
2025-06-27 05:38:17,897 - database - DEBUG - Creating new database session
2025-06-27 05:38:17,905 - database - DEBUG - Creating new database session
2025-06-27 05:38:17,945 - database - ERROR - Error in database session: 500: An error occurred while refreshing token.
Traceback (most recent call last):
  File "C:\Users\Dhanush\FASTAPI\app\api\v1\endpoints\users.py", line 310, in refresh_access_token
     raise HTTPException(
    ...<3 lines>...
    )
fastapi.exceptions.HTTPException: 401: Invalid or expired refresh token

During handling of the above exception, another exception occurred:

Traceback (most recent call last):
  File "C:\Users\Dhanush\FASTAPI\app\database\session.py", line 65, in get_db
    yield session
  File "C:\Users\Dhanush\AppData\Local\Programs\Python\Python313\Lib\site-packages\fastapi\routing.py", line 301, in app
    raw_response = await run_endpoint_function(
                   ^^^^^^^^^^^^^^^^^^^^^^^^^^^^
    ...<3 lines>...
    )
    ^
  File "C:\Users\Dhanush\AppData\Local\Programs\Python\Python313\Lib\site-packages\fastapi\routing.py", line 212, in run_endpoint_function
    return await dependant.call(**values)
           ^^^^^^^^^^^^^^^^^^^^^^^^^^^^^^
  File "C:\Users\Dhanush\FASTAPI\app\api\v1\endpoints\users.py", line 360, in refresh_access_token
    raise HTTPException(
    ...<2 lines>...
    )
fastapi.exceptions.HTTPException: 500: An error occurred while refreshing token.
2025-06-27 05:38:17,951 - database - INFO - Session rolled back due to error
2025-06-27 05:38:17,954 - database - DEBUG - Closing database session
2025-06-27 05:38:17,976 - database - DEBUG - Database session used successfully
2025-06-27 05:38:17,977 - database - DEBUG - Closing database session
2025-06-27 05:38:30,644 - database - DEBUG - Creating new database session
2025-06-27 05:38:30,664 - database - ERROR - Error in database session: 500: An error occurred while refreshing token.
Traceback (most recent call last):
  File "C:\Users\Dhanush\FASTAPI\app\api\v1\endpoints\users.py", line 310, in refresh_access_token
     raise HTTPException(
    ...<3 lines>...
    )
fastapi.exceptions.HTTPException: 401: Invalid or expired refresh token

During handling of the above exception, another exception occurred:

Traceback (most recent call last):
  File "C:\Users\Dhanush\FASTAPI\app\database\session.py", line 65, in get_db
    yield session
  File "C:\Users\Dhanush\AppData\Local\Programs\Python\Python313\Lib\site-packages\fastapi\routing.py", line 301, in app
    raw_response = await run_endpoint_function(
                   ^^^^^^^^^^^^^^^^^^^^^^^^^^^^
    ...<3 lines>...
    )
    ^
  File "C:\Users\Dhanush\AppData\Local\Programs\Python\Python313\Lib\site-packages\fastapi\routing.py", line 212, in run_endpoint_function
    return await dependant.call(**values)
           ^^^^^^^^^^^^^^^^^^^^^^^^^^^^^^
  File "C:\Users\Dhanush\FASTAPI\app\api\v1\endpoints\users.py", line 360, in refresh_access_token
    raise HTTPException(
    ...<2 lines>...
    )
fastapi.exceptions.HTTPException: 500: An error occurred while refreshing token.
2025-06-27 05:38:30,681 - database - INFO - Session rolled back due to error
2025-06-27 05:38:30,686 - database - DEBUG - Closing database session
2025-06-27 05:38:40,922 - database - DEBUG - Creating new database session
2025-06-27 05:38:40,947 - database - ERROR - Error in database session: 500: An error occurred while refreshing token.
Traceback (most recent call last):
  File "C:\Users\Dhanush\FASTAPI\app\api\v1\endpoints\users.py", line 310, in refresh_access_token
     raise HTTPException(
    ...<3 lines>...
    )
fastapi.exceptions.HTTPException: 401: Invalid or expired refresh token

During handling of the above exception, another exception occurred:

Traceback (most recent call last):
  File "C:\Users\Dhanush\FASTAPI\app\database\session.py", line 65, in get_db
    yield session
  File "C:\Users\Dhanush\AppData\Local\Programs\Python\Python313\Lib\site-packages\fastapi\routing.py", line 301, in app
    raw_response = await run_endpoint_function(
                   ^^^^^^^^^^^^^^^^^^^^^^^^^^^^
    ...<3 lines>...
    )
    ^
  File "C:\Users\Dhanush\AppData\Local\Programs\Python\Python313\Lib\site-packages\fastapi\routing.py", line 212, in run_endpoint_function
    return await dependant.call(**values)
           ^^^^^^^^^^^^^^^^^^^^^^^^^^^^^^
  File "C:\Users\Dhanush\FASTAPI\app\api\v1\endpoints\users.py", line 360, in refresh_access_token
    raise HTTPException(
    ...<2 lines>...
    )
fastapi.exceptions.HTTPException: 500: An error occurred while refreshing token.
2025-06-27 05:38:40,974 - database - INFO - Session rolled back due to error
2025-06-27 05:38:40,983 - database - DEBUG - Closing database session
2025-06-27 05:38:52,393 - database - DEBUG - Creating new database session
2025-06-27 05:38:52,417 - database - ERROR - Error in database session: 500: An error occurred while refreshing token.
Traceback (most recent call last):
  File "C:\Users\Dhanush\FASTAPI\app\api\v1\endpoints\users.py", line 310, in refresh_access_token
     raise HTTPException(
    ...<3 lines>...
    )
fastapi.exceptions.HTTPException: 401: Invalid or expired refresh token

During handling of the above exception, another exception occurred:

Traceback (most recent call last):
  File "C:\Users\Dhanush\FASTAPI\app\database\session.py", line 65, in get_db
    yield session
  File "C:\Users\Dhanush\AppData\Local\Programs\Python\Python313\Lib\site-packages\fastapi\routing.py", line 301, in app
    raw_response = await run_endpoint_function(
                   ^^^^^^^^^^^^^^^^^^^^^^^^^^^^
    ...<3 lines>...
    )
    ^
  File "C:\Users\Dhanush\AppData\Local\Programs\Python\Python313\Lib\site-packages\fastapi\routing.py", line 212, in run_endpoint_function
    return await dependant.call(**values)
           ^^^^^^^^^^^^^^^^^^^^^^^^^^^^^^
  File "C:\Users\Dhanush\FASTAPI\app\api\v1\endpoints\users.py", line 360, in refresh_access_token
    raise HTTPException(
    ...<2 lines>...
    )
fastapi.exceptions.HTTPException: 500: An error occurred while refreshing token.
2025-06-27 05:38:52,428 - database - INFO - Session rolled back due to error
2025-06-27 05:38:52,430 - database - DEBUG - Closing database session
2025-06-27 05:38:59,746 - database - DEBUG - Creating new database session
2025-06-27 05:38:59,757 - database - ERROR - Error in database session: 500: An error occurred while refreshing token.
Traceback (most recent call last):
  File "C:\Users\Dhanush\FASTAPI\app\api\v1\endpoints\users.py", line 310, in refresh_access_token
     raise HTTPException(
    ...<3 lines>...
    )
fastapi.exceptions.HTTPException: 401: Invalid or expired refresh token

During handling of the above exception, another exception occurred:

Traceback (most recent call last):
  File "C:\Users\Dhanush\FASTAPI\app\database\session.py", line 65, in get_db
    yield session
  File "C:\Users\Dhanush\AppData\Local\Programs\Python\Python313\Lib\site-packages\fastapi\routing.py", line 301, in app
    raw_response = await run_endpoint_function(
                   ^^^^^^^^^^^^^^^^^^^^^^^^^^^^
    ...<3 lines>...
    )
    ^
  File "C:\Users\Dhanush\AppData\Local\Programs\Python\Python313\Lib\site-packages\fastapi\routing.py", line 212, in run_endpoint_function
    return await dependant.call(**values)
           ^^^^^^^^^^^^^^^^^^^^^^^^^^^^^^
  File "C:\Users\Dhanush\FASTAPI\app\api\v1\endpoints\users.py", line 360, in refresh_access_token
    raise HTTPException(
    ...<2 lines>...
    )
fastapi.exceptions.HTTPException: 500: An error occurred while refreshing token.
2025-06-27 05:38:59,760 - database - INFO - Session rolled back due to error
2025-06-27 05:38:59,762 - database - DEBUG - Closing database session
2025-06-27 05:39:07,937 - database - DEBUG - Creating new database session
2025-06-27 05:39:07,946 - database - ERROR - Error in database session: 500: An error occurred while refreshing token.
Traceback (most recent call last):
  File "C:\Users\Dhanush\FASTAPI\app\api\v1\endpoints\users.py", line 310, in refresh_access_token
     raise HTTPException(
    ...<3 lines>...
    )
fastapi.exceptions.HTTPException: 401: Invalid or expired refresh token

During handling of the above exception, another exception occurred:

Traceback (most recent call last):
  File "C:\Users\Dhanush\FASTAPI\app\database\session.py", line 65, in get_db
    yield session
  File "C:\Users\Dhanush\AppData\Local\Programs\Python\Python313\Lib\site-packages\fastapi\routing.py", line 301, in app
    raw_response = await run_endpoint_function(
                   ^^^^^^^^^^^^^^^^^^^^^^^^^^^^
    ...<3 lines>...
    )
    ^
  File "C:\Users\Dhanush\AppData\Local\Programs\Python\Python313\Lib\site-packages\fastapi\routing.py", line 212, in run_endpoint_function
    return await dependant.call(**values)
           ^^^^^^^^^^^^^^^^^^^^^^^^^^^^^^
  File "C:\Users\Dhanush\FASTAPI\app\api\v1\endpoints\users.py", line 360, in refresh_access_token
    raise HTTPException(
    ...<2 lines>...
    )
fastapi.exceptions.HTTPException: 500: An error occurred while refreshing token.
2025-06-27 05:39:07,957 - database - INFO - Session rolled back due to error
2025-06-27 05:39:07,960 - database - DEBUG - Closing database session
2025-06-27 05:39:14,790 - database - DEBUG - Creating new database session
2025-06-27 05:39:14,800 - database - DEBUG - Database session used successfully
2025-06-27 05:39:14,804 - database - DEBUG - Closing database session
2025-06-27 05:39:15,610 - database - DEBUG - Creating new database session
2025-06-27 05:39:15,627 - database - ERROR - Error in database session: 500: An error occurred while refreshing token.
Traceback (most recent call last):
  File "C:\Users\Dhanush\FASTAPI\app\api\v1\endpoints\users.py", line 310, in refresh_access_token
     raise HTTPException(
    ...<3 lines>...
    )
fastapi.exceptions.HTTPException: 401: Invalid or expired refresh token

During handling of the above exception, another exception occurred:

Traceback (most recent call last):
  File "C:\Users\Dhanush\FASTAPI\app\database\session.py", line 65, in get_db
    yield session
  File "C:\Users\Dhanush\AppData\Local\Programs\Python\Python313\Lib\site-packages\fastapi\routing.py", line 301, in app
    raw_response = await run_endpoint_function(
                   ^^^^^^^^^^^^^^^^^^^^^^^^^^^^
    ...<3 lines>...
    )
    ^
  File "C:\Users\Dhanush\AppData\Local\Programs\Python\Python313\Lib\site-packages\fastapi\routing.py", line 212, in run_endpoint_function
    return await dependant.call(**values)
           ^^^^^^^^^^^^^^^^^^^^^^^^^^^^^^
  File "C:\Users\Dhanush\FASTAPI\app\api\v1\endpoints\users.py", line 360, in refresh_access_token
    raise HTTPException(
    ...<2 lines>...
    )
fastapi.exceptions.HTTPException: 500: An error occurred while refreshing token.
2025-06-27 05:39:15,642 - database - INFO - Session rolled back due to error
2025-06-27 05:39:15,646 - database - DEBUG - Closing database session
2025-06-27 05:39:22,901 - database - DEBUG - Database session used successfully
2025-06-27 05:39:22,902 - database - DEBUG - Closing database session
2025-06-27 05:39:23,059 - database - DEBUG - Creating new database session
2025-06-27 05:39:23,114 - database - DEBUG - Database session used successfully
2025-06-27 05:39:23,115 - database - DEBUG - Closing database session
2025-06-27 05:39:23,125 - database - DEBUG - Creating new database session
2025-06-27 05:39:23,194 - database - DEBUG - Database session used successfully
2025-06-27 05:39:23,194 - database - DEBUG - Closing database session
2025-06-27 05:39:23,256 - database - DEBUG - Creating new database session
2025-06-27 05:39:24,862 - database - DEBUG - Database session used successfully
2025-06-27 05:39:24,863 - database - DEBUG - Closing database session
2025-06-27 05:39:24,884 - database - DEBUG - Creating new database session
2025-06-27 05:39:25,232 - database - DEBUG - Creating new database session
2025-06-27 05:39:25,694 - database - DEBUG - Creating new database session
2025-06-27 05:39:25,762 - database - DEBUG - Database session used successfully
2025-06-27 05:39:25,763 - database - DEBUG - Closing database session
2025-06-27 05:39:26,478 - database - DEBUG - Database session used successfully
2025-06-27 05:39:26,480 - database - DEBUG - Closing database session
2025-06-27 05:39:26,526 - database - DEBUG - Creating new database session
2025-06-27 05:39:26,566 - database - DEBUG - Database session used successfully
2025-06-27 05:39:26,567 - database - DEBUG - Closing database session
2025-06-27 05:40:33,979 - database - DEBUG - Creating new database session
2025-06-27 05:40:33,993 - database - ERROR - Error in database session: 500: An error occurred while refreshing token.
Traceback (most recent call last):
  File "C:\Users\Dhanush\FASTAPI\app\api\v1\endpoints\users.py", line 310, in refresh_access_token
     raise HTTPException(
    ...<3 lines>...
    )
fastapi.exceptions.HTTPException: 401: Invalid or expired refresh token

During handling of the above exception, another exception occurred:

Traceback (most recent call last):
  File "C:\Users\Dhanush\FASTAPI\app\database\session.py", line 65, in get_db
    yield session
  File "C:\Users\Dhanush\AppData\Local\Programs\Python\Python313\Lib\site-packages\fastapi\routing.py", line 301, in app
    raw_response = await run_endpoint_function(
                   ^^^^^^^^^^^^^^^^^^^^^^^^^^^^
    ...<3 lines>...
    )
    ^
  File "C:\Users\Dhanush\AppData\Local\Programs\Python\Python313\Lib\site-packages\fastapi\routing.py", line 212, in run_endpoint_function
    return await dependant.call(**values)
           ^^^^^^^^^^^^^^^^^^^^^^^^^^^^^^
  File "C:\Users\Dhanush\FASTAPI\app\api\v1\endpoints\users.py", line 360, in refresh_access_token
    raise HTTPException(
    ...<2 lines>...
    )
fastapi.exceptions.HTTPException: 500: An error occurred while refreshing token.
2025-06-27 05:40:34,000 - database - INFO - Session rolled back due to error
2025-06-27 05:40:34,002 - database - DEBUG - Closing database session
2025-06-27 05:40:40,699 - database - DEBUG - Creating new database session
2025-06-27 05:40:40,739 - database - DEBUG - Database session used successfully
2025-06-27 05:40:40,740 - database - DEBUG - Closing database session
2025-06-27 05:40:44,647 - database - DEBUG - Creating new database session
2025-06-27 05:40:44,667 - database - ERROR - Error in database session: 500: An error occurred while refreshing token.
Traceback (most recent call last):
  File "C:\Users\Dhanush\FASTAPI\app\api\v1\endpoints\users.py", line 310, in refresh_access_token
     raise HTTPException(
    ...<3 lines>...
    )
fastapi.exceptions.HTTPException: 401: Invalid or expired refresh token

During handling of the above exception, another exception occurred:

Traceback (most recent call last):
  File "C:\Users\Dhanush\FASTAPI\app\database\session.py", line 65, in get_db
    yield session
  File "C:\Users\Dhanush\AppData\Local\Programs\Python\Python313\Lib\site-packages\fastapi\routing.py", line 301, in app
    raw_response = await run_endpoint_function(
                   ^^^^^^^^^^^^^^^^^^^^^^^^^^^^
    ...<3 lines>...
    )
    ^
  File "C:\Users\Dhanush\AppData\Local\Programs\Python\Python313\Lib\site-packages\fastapi\routing.py", line 212, in run_endpoint_function
    return await dependant.call(**values)
           ^^^^^^^^^^^^^^^^^^^^^^^^^^^^^^
  File "C:\Users\Dhanush\FASTAPI\app\api\v1\endpoints\users.py", line 360, in refresh_access_token
    raise HTTPException(
    ...<2 lines>...
    )
fastapi.exceptions.HTTPException: 500: An error occurred while refreshing token.
2025-06-27 05:40:44,682 - database - INFO - Session rolled back due to error
2025-06-27 05:40:44,688 - database - DEBUG - Closing database session
2025-06-27 05:40:59,810 - database - DEBUG - Creating new database session
2025-06-27 05:40:59,826 - database - ERROR - Error in database session: 500: An error occurred while refreshing token.
Traceback (most recent call last):
  File "C:\Users\Dhanush\FASTAPI\app\api\v1\endpoints\users.py", line 310, in refresh_access_token
     raise HTTPException(
    ...<3 lines>...
    )
fastapi.exceptions.HTTPException: 401: Invalid or expired refresh token

During handling of the above exception, another exception occurred:

Traceback (most recent call last):
  File "C:\Users\Dhanush\FASTAPI\app\database\session.py", line 65, in get_db
    yield session
  File "C:\Users\Dhanush\AppData\Local\Programs\Python\Python313\Lib\site-packages\fastapi\routing.py", line 301, in app
    raw_response = await run_endpoint_function(
                   ^^^^^^^^^^^^^^^^^^^^^^^^^^^^
    ...<3 lines>...
    )
    ^
  File "C:\Users\Dhanush\AppData\Local\Programs\Python\Python313\Lib\site-packages\fastapi\routing.py", line 212, in run_endpoint_function
    return await dependant.call(**values)
           ^^^^^^^^^^^^^^^^^^^^^^^^^^^^^^
  File "C:\Users\Dhanush\FASTAPI\app\api\v1\endpoints\users.py", line 360, in refresh_access_token
    raise HTTPException(
    ...<2 lines>...
    )
fastapi.exceptions.HTTPException: 500: An error occurred while refreshing token.
2025-06-27 05:40:59,830 - database - INFO - Session rolled back due to error
2025-06-27 05:40:59,830 - database - DEBUG - Closing database session
2025-06-27 05:41:01,661 - database - DEBUG - Creating new database session
2025-06-27 05:41:01,680 - database - ERROR - Error in database session: 500: An error occurred while refreshing token.
Traceback (most recent call last):
  File "C:\Users\Dhanush\FASTAPI\app\api\v1\endpoints\users.py", line 310, in refresh_access_token
     raise HTTPException(
    ...<3 lines>...
    )
fastapi.exceptions.HTTPException: 401: Invalid or expired refresh token

During handling of the above exception, another exception occurred:

Traceback (most recent call last):
  File "C:\Users\Dhanush\FASTAPI\app\database\session.py", line 65, in get_db
    yield session
  File "C:\Users\Dhanush\AppData\Local\Programs\Python\Python313\Lib\site-packages\fastapi\routing.py", line 301, in app
    raw_response = await run_endpoint_function(
                   ^^^^^^^^^^^^^^^^^^^^^^^^^^^^
    ...<3 lines>...
    )
    ^
  File "C:\Users\Dhanush\AppData\Local\Programs\Python\Python313\Lib\site-packages\fastapi\routing.py", line 212, in run_endpoint_function
    return await dependant.call(**values)
           ^^^^^^^^^^^^^^^^^^^^^^^^^^^^^^
  File "C:\Users\Dhanush\FASTAPI\app\api\v1\endpoints\users.py", line 360, in refresh_access_token
    raise HTTPException(
    ...<2 lines>...
    )
fastapi.exceptions.HTTPException: 500: An error occurred while refreshing token.
2025-06-27 05:41:01,694 - database - INFO - Session rolled back due to error
2025-06-27 05:41:01,696 - database - DEBUG - Closing database session
2025-06-27 05:41:04,133 - database - DEBUG - Creating new database session
2025-06-27 05:41:04,140 - database - ERROR - Error in database session: 500: An error occurred while refreshing token.
Traceback (most recent call last):
  File "C:\Users\Dhanush\FASTAPI\app\api\v1\endpoints\users.py", line 310, in refresh_access_token
     raise HTTPException(
    ...<3 lines>...
    )
fastapi.exceptions.HTTPException: 401: Invalid or expired refresh token

During handling of the above exception, another exception occurred:

Traceback (most recent call last):
  File "C:\Users\Dhanush\FASTAPI\app\database\session.py", line 65, in get_db
    yield session
  File "C:\Users\Dhanush\AppData\Local\Programs\Python\Python313\Lib\site-packages\fastapi\routing.py", line 301, in app
    raw_response = await run_endpoint_function(
                   ^^^^^^^^^^^^^^^^^^^^^^^^^^^^
    ...<3 lines>...
    )
    ^
  File "C:\Users\Dhanush\AppData\Local\Programs\Python\Python313\Lib\site-packages\fastapi\routing.py", line 212, in run_endpoint_function
    return await dependant.call(**values)
           ^^^^^^^^^^^^^^^^^^^^^^^^^^^^^^
  File "C:\Users\Dhanush\FASTAPI\app\api\v1\endpoints\users.py", line 360, in refresh_access_token
    raise HTTPException(
    ...<2 lines>...
    )
fastapi.exceptions.HTTPException: 500: An error occurred while refreshing token.
2025-06-27 05:41:04,143 - database - INFO - Session rolled back due to error
2025-06-27 05:41:04,143 - database - DEBUG - Closing database session
2025-06-27 05:41:55,613 - database - DEBUG - Creating new database session
2025-06-27 05:41:55,628 - database - DEBUG - Database session used successfully
2025-06-27 05:41:55,629 - database - DEBUG - Closing database session
2025-06-27 05:42:04,460 - database - DEBUG - Creating new database session
2025-06-27 05:42:04,465 - database - ERROR - Error in database session: 500: An error occurred while refreshing token.
Traceback (most recent call last):
  File "C:\Users\Dhanush\FASTAPI\app\api\v1\endpoints\users.py", line 310, in refresh_access_token
     raise HTTPException(
    ...<3 lines>...
    )
fastapi.exceptions.HTTPException: 401: Invalid or expired refresh token

During handling of the above exception, another exception occurred:

Traceback (most recent call last):
  File "C:\Users\Dhanush\FASTAPI\app\database\session.py", line 65, in get_db
    yield session
  File "C:\Users\Dhanush\AppData\Local\Programs\Python\Python313\Lib\site-packages\fastapi\routing.py", line 301, in app
    raw_response = await run_endpoint_function(
                   ^^^^^^^^^^^^^^^^^^^^^^^^^^^^
    ...<3 lines>...
    )
    ^
  File "C:\Users\Dhanush\AppData\Local\Programs\Python\Python313\Lib\site-packages\fastapi\routing.py", line 212, in run_endpoint_function
    return await dependant.call(**values)
           ^^^^^^^^^^^^^^^^^^^^^^^^^^^^^^
  File "C:\Users\Dhanush\FASTAPI\app\api\v1\endpoints\users.py", line 360, in refresh_access_token
    raise HTTPException(
    ...<2 lines>...
    )
fastapi.exceptions.HTTPException: 500: An error occurred while refreshing token.
2025-06-27 05:42:04,469 - database - INFO - Session rolled back due to error
2025-06-27 05:42:04,469 - database - DEBUG - Closing database session
2025-06-27 05:42:54,962 - database - DEBUG - Creating new database session
2025-06-27 05:42:54,980 - database - ERROR - Error in database session: 500: An error occurred while refreshing token.
Traceback (most recent call last):
  File "C:\Users\Dhanush\FASTAPI\app\api\v1\endpoints\users.py", line 310, in refresh_access_token
     raise HTTPException(
    ...<3 lines>...
    )
fastapi.exceptions.HTTPException: 401: Invalid or expired refresh token

During handling of the above exception, another exception occurred:

Traceback (most recent call last):
  File "C:\Users\Dhanush\FASTAPI\app\database\session.py", line 65, in get_db
    yield session
  File "C:\Users\Dhanush\AppData\Local\Programs\Python\Python313\Lib\site-packages\fastapi\routing.py", line 301, in app
    raw_response = await run_endpoint_function(
                   ^^^^^^^^^^^^^^^^^^^^^^^^^^^^
    ...<3 lines>...
    )
    ^
  File "C:\Users\Dhanush\AppData\Local\Programs\Python\Python313\Lib\site-packages\fastapi\routing.py", line 212, in run_endpoint_function
    return await dependant.call(**values)
           ^^^^^^^^^^^^^^^^^^^^^^^^^^^^^^
  File "C:\Users\Dhanush\FASTAPI\app\api\v1\endpoints\users.py", line 360, in refresh_access_token
    raise HTTPException(
    ...<2 lines>...
    )
fastapi.exceptions.HTTPException: 500: An error occurred while refreshing token.
2025-06-27 05:42:54,984 - database - INFO - Session rolled back due to error
2025-06-27 05:42:54,985 - database - DEBUG - Closing database session
2025-06-27 05:43:11,728 - database - DEBUG - Creating new database session
2025-06-27 05:43:11,748 - database - DEBUG - Database session used successfully
2025-06-27 05:43:11,748 - database - DEBUG - Closing database session
2025-06-27 05:43:54,972 - database - DEBUG - Creating new database session
2025-06-27 05:43:54,986 - database - ERROR - Error in database session: 500: An error occurred while refreshing token.
Traceback (most recent call last):
  File "C:\Users\Dhanush\FASTAPI\app\api\v1\endpoints\users.py", line 310, in refresh_access_token
     raise HTTPException(
    ...<3 lines>...
    )
fastapi.exceptions.HTTPException: 401: Invalid or expired refresh token

During handling of the above exception, another exception occurred:

Traceback (most recent call last):
  File "C:\Users\Dhanush\FASTAPI\app\database\session.py", line 65, in get_db
    yield session
  File "C:\Users\Dhanush\AppData\Local\Programs\Python\Python313\Lib\site-packages\fastapi\routing.py", line 301, in app
    raw_response = await run_endpoint_function(
                   ^^^^^^^^^^^^^^^^^^^^^^^^^^^^
    ...<3 lines>...
    )
    ^
  File "C:\Users\Dhanush\AppData\Local\Programs\Python\Python313\Lib\site-packages\fastapi\routing.py", line 212, in run_endpoint_function
    return await dependant.call(**values)
           ^^^^^^^^^^^^^^^^^^^^^^^^^^^^^^
  File "C:\Users\Dhanush\FASTAPI\app\api\v1\endpoints\users.py", line 360, in refresh_access_token
    raise HTTPException(
    ...<2 lines>...
    )
fastapi.exceptions.HTTPException: 500: An error occurred while refreshing token.
2025-06-27 05:43:54,988 - database - INFO - Session rolled back due to error
2025-06-27 05:43:54,990 - database - DEBUG - Closing database session
2025-06-27 05:44:25,285 - database - DEBUG - Creating new database session
2025-06-27 05:44:25,309 - database - DEBUG - Database session used successfully
2025-06-27 05:44:25,309 - database - DEBUG - Closing database session
2025-06-27 05:45:15,976 - database - DEBUG - Creating new database session
2025-06-27 05:45:16,021 - database - DEBUG - Creating new database session
2025-06-27 05:45:16,064 - database - DEBUG - Database session used successfully
2025-06-27 05:45:16,065 - database - DEBUG - Closing database session
2025-06-27 05:45:16,071 - database - ERROR - Error in database session: 500: An error occurred while refreshing token.
Traceback (most recent call last):
  File "C:\Users\Dhanush\FASTAPI\app\api\v1\endpoints\users.py", line 310, in refresh_access_token
     raise HTTPException(
    ...<3 lines>...
    )
fastapi.exceptions.HTTPException: 401: Invalid or expired refresh token

During handling of the above exception, another exception occurred:

Traceback (most recent call last):
  File "C:\Users\Dhanush\FASTAPI\app\database\session.py", line 65, in get_db
    yield session
  File "C:\Users\Dhanush\AppData\Local\Programs\Python\Python313\Lib\site-packages\fastapi\routing.py", line 301, in app
    raw_response = await run_endpoint_function(
                   ^^^^^^^^^^^^^^^^^^^^^^^^^^^^
    ...<3 lines>...
    )
    ^
  File "C:\Users\Dhanush\AppData\Local\Programs\Python\Python313\Lib\site-packages\fastapi\routing.py", line 212, in run_endpoint_function
    return await dependant.call(**values)
           ^^^^^^^^^^^^^^^^^^^^^^^^^^^^^^
  File "C:\Users\Dhanush\FASTAPI\app\api\v1\endpoints\users.py", line 360, in refresh_access_token
    raise HTTPException(
    ...<2 lines>...
    )
fastapi.exceptions.HTTPException: 500: An error occurred while refreshing token.
2025-06-27 05:45:16,076 - database - INFO - Session rolled back due to error
2025-06-27 05:45:16,077 - database - DEBUG - Closing database session
2025-06-27 05:45:16,083 - database - DEBUG - Creating new database session
2025-06-27 05:45:16,113 - database - DEBUG - Database session used successfully
2025-06-27 05:45:16,115 - database - DEBUG - Closing database session
2025-06-27 05:45:16,264 - database - DEBUG - Database session used successfully
2025-06-27 05:45:16,267 - database - DEBUG - Closing database session
2025-06-27 05:45:16,315 - database - DEBUG - Creating new database session
2025-06-27 05:45:16,384 - database - DEBUG - Database session used successfully
2025-06-27 05:45:16,386 - database - DEBUG - Closing database session
2025-06-27 05:45:16,652 - database - DEBUG - Creating new database session
2025-06-27 05:45:18,336 - database - DEBUG - Database session used successfully
2025-06-27 05:45:18,337 - database - DEBUG - Closing database session
2025-06-27 05:45:18,376 - database - DEBUG - Creating new database session
2025-06-27 05:45:18,758 - database - DEBUG - Creating new database session
2025-06-27 05:45:20,290 - database - DEBUG - Database session used successfully
2025-06-27 05:45:20,291 - database - DEBUG - Closing database session
2025-06-27 05:45:20,378 - database - DEBUG - Creating new database session
2025-06-27 05:45:20,432 - database - DEBUG - Database session used successfully
2025-06-27 05:45:20,433 - database - DEBUG - Closing database session
2025-06-27 05:46:16,481 - database - DEBUG - Creating new database session
2025-06-27 05:46:16,513 - database - DEBUG - Database session used successfully
2025-06-27 05:46:16,514 - database - DEBUG - Closing database session
2025-06-27 05:50:01,308 - database - DEBUG - Creating new database session
2025-06-27 05:50:01,329 - database - ERROR - Error in database session: 401: Could not validate credentials
Traceback (most recent call last):
  File "C:\Users\Dhanush\FASTAPI\app\core\security.py", line 93, in decode_token
    payload = jwt.decode(token, settings.SECRET_KEY, algorithms=[settings.ALGORITHM])
  File "C:\Users\Dhanush\AppData\Local\Programs\Python\Python313\Lib\site-packages\jose\jwt.py", line 174, in decode
    _validate_claims(
    ~~~~~~~~~~~~~~~~^
        claims,
        ^^^^^^^
    ...<5 lines>...
        options=defaults,
        ^^^^^^^^^^^^^^^^^
    )
    ^
  File "C:\Users\Dhanush\AppData\Local\Programs\Python\Python313\Lib\site-packages\jose\jwt.py", line 497, in _validate_claims
    _validate_exp(claims, leeway=leeway)
    ~~~~~~~~~~~~~^^^^^^^^^^^^^^^^^^^^^^^
  File "C:\Users\Dhanush\AppData\Local\Programs\Python\Python313\Lib\site-packages\jose\jwt.py", line 331, in _validate_exp
    raise ExpiredSignatureError("Signature has expired.")
jose.exceptions.ExpiredSignatureError: Signature has expired.

During handling of the above exception, another exception occurred:

Traceback (most recent call last):
  File "C:\Users\Dhanush\FASTAPI\app\core\security.py", line 281, in get_current_user
    payload = decode_token(token)
  File "C:\Users\Dhanush\FASTAPI\app\core\security.py", line 98, in decode_token
    raise JWTError("Could not validate credentials")
jose.exceptions.JWTError: Could not validate credentials

During handling of the above exception, another exception occurred:

Traceback (most recent call last):
  File "C:\Users\Dhanush\FASTAPI\app\database\session.py", line 65, in get_db
    yield session
  File "C:\Users\Dhanush\AppData\Local\Programs\Python\Python313\Lib\site-packages\fastapi\routing.py", line 291, in app
    solved_result = await solve_dependencies(
                    ^^^^^^^^^^^^^^^^^^^^^^^^^
    ...<6 lines>...
    )
    ^
  File "C:\Users\Dhanush\AppData\Local\Programs\Python\Python313\Lib\site-packages\fastapi\dependencies\utils.py", line 638, in solve_dependencies
    solved = await call(**solved_result.values)
             ^^^^^^^^^^^^^^^^^^^^^^^^^^^^^^^^^^
  File "C:\Users\Dhanush\FASTAPI\app\core\security.py", line 326, in get_current_user
    raise credentials_exception
fastapi.exceptions.HTTPException: 401: Could not validate credentials
2025-06-27 05:50:01,342 - database - INFO - Session rolled back due to error
2025-06-27 05:50:01,347 - database - DEBUG - Closing database session
2025-06-27 05:50:01,350 - database - DEBUG - Creating new database session
2025-06-27 05:50:01,369 - database - ERROR - Error in database session: 401: Could not validate credentials
Traceback (most recent call last):
  File "C:\Users\Dhanush\FASTAPI\app\core\security.py", line 93, in decode_token
    payload = jwt.decode(token, settings.SECRET_KEY, algorithms=[settings.ALGORITHM])
  File "C:\Users\Dhanush\AppData\Local\Programs\Python\Python313\Lib\site-packages\jose\jwt.py", line 174, in decode
    _validate_claims(
    ~~~~~~~~~~~~~~~~^
        claims,
        ^^^^^^^
    ...<5 lines>...
        options=defaults,
        ^^^^^^^^^^^^^^^^^
    )
    ^
  File "C:\Users\Dhanush\AppData\Local\Programs\Python\Python313\Lib\site-packages\jose\jwt.py", line 497, in _validate_claims
    _validate_exp(claims, leeway=leeway)
    ~~~~~~~~~~~~~^^^^^^^^^^^^^^^^^^^^^^^
  File "C:\Users\Dhanush\AppData\Local\Programs\Python\Python313\Lib\site-packages\jose\jwt.py", line 331, in _validate_exp
    raise ExpiredSignatureError("Signature has expired.")
jose.exceptions.ExpiredSignatureError: Signature has expired.

During handling of the above exception, another exception occurred:

Traceback (most recent call last):
  File "C:\Users\Dhanush\FASTAPI\app\core\security.py", line 281, in get_current_user
    payload = decode_token(token)
  File "C:\Users\Dhanush\FASTAPI\app\core\security.py", line 98, in decode_token
    raise JWTError("Could not validate credentials")
jose.exceptions.JWTError: Could not validate credentials

During handling of the above exception, another exception occurred:

Traceback (most recent call last):
  File "C:\Users\Dhanush\FASTAPI\app\database\session.py", line 65, in get_db
    yield session
  File "C:\Users\Dhanush\AppData\Local\Programs\Python\Python313\Lib\site-packages\fastapi\routing.py", line 291, in app
    solved_result = await solve_dependencies(
                    ^^^^^^^^^^^^^^^^^^^^^^^^^
    ...<6 lines>...
    )
    ^
  File "C:\Users\Dhanush\AppData\Local\Programs\Python\Python313\Lib\site-packages\fastapi\dependencies\utils.py", line 638, in solve_dependencies
    solved = await call(**solved_result.values)
             ^^^^^^^^^^^^^^^^^^^^^^^^^^^^^^^^^^
  File "C:\Users\Dhanush\FASTAPI\app\core\security.py", line 326, in get_current_user
    raise credentials_exception
fastapi.exceptions.HTTPException: 401: Could not validate credentials
2025-06-27 05:50:01,378 - database - INFO - Session rolled back due to error
2025-06-27 05:50:01,379 - database - DEBUG - Closing database session
2025-06-27 05:50:01,390 - database - DEBUG - Creating new database session
2025-06-27 05:50:01,395 - database - ERROR - Error in database session: 401: Could not validate credentials
Traceback (most recent call last):
  File "C:\Users\Dhanush\FASTAPI\app\core\security.py", line 93, in decode_token
    payload = jwt.decode(token, settings.SECRET_KEY, algorithms=[settings.ALGORITHM])
  File "C:\Users\Dhanush\AppData\Local\Programs\Python\Python313\Lib\site-packages\jose\jwt.py", line 174, in decode
    _validate_claims(
    ~~~~~~~~~~~~~~~~^
        claims,
        ^^^^^^^
    ...<5 lines>...
        options=defaults,
        ^^^^^^^^^^^^^^^^^
    )
    ^
  File "C:\Users\Dhanush\AppData\Local\Programs\Python\Python313\Lib\site-packages\jose\jwt.py", line 497, in _validate_claims
    _validate_exp(claims, leeway=leeway)
    ~~~~~~~~~~~~~^^^^^^^^^^^^^^^^^^^^^^^
  File "C:\Users\Dhanush\AppData\Local\Programs\Python\Python313\Lib\site-packages\jose\jwt.py", line 331, in _validate_exp
    raise ExpiredSignatureError("Signature has expired.")
jose.exceptions.ExpiredSignatureError: Signature has expired.

During handling of the above exception, another exception occurred:

Traceback (most recent call last):
  File "C:\Users\Dhanush\FASTAPI\app\api\v1\endpoints\users.py", line 289, in refresh_access_token
    payload = decode_token(refresh_token)
  File "C:\Users\Dhanush\FASTAPI\app\core\security.py", line 98, in decode_token
    raise JWTError("Could not validate credentials")
jose.exceptions.JWTError: Could not validate credentials

During handling of the above exception, another exception occurred:

Traceback (most recent call last):
  File "C:\Users\Dhanush\FASTAPI\app\database\session.py", line 65, in get_db
    yield session
  File "C:\Users\Dhanush\AppData\Local\Programs\Python\Python313\Lib\site-packages\fastapi\routing.py", line 301, in app
    raw_response = await run_endpoint_function(
                   ^^^^^^^^^^^^^^^^^^^^^^^^^^^^
    ...<3 lines>...
    )
    ^
  File "C:\Users\Dhanush\AppData\Local\Programs\Python\Python313\Lib\site-packages\fastapi\routing.py", line 212, in run_endpoint_function
    return await dependant.call(**values)
           ^^^^^^^^^^^^^^^^^^^^^^^^^^^^^^
  File "C:\Users\Dhanush\FASTAPI\app\api\v1\endpoints\users.py", line 352, in refresh_access_token
    raise HTTPException(
    ...<3 lines>...
    )
fastapi.exceptions.HTTPException: 401: Could not validate credentials
2025-06-27 05:50:01,399 - database - INFO - Session rolled back due to error
2025-06-27 05:50:01,399 - database - DEBUG - Closing database session
2025-06-27 05:50:01,852 - database - DEBUG - Creating new database session
2025-06-27 05:50:01,863 - database - ERROR - Error in database session: 401: Could not validate credentials
Traceback (most recent call last):
  File "C:\Users\Dhanush\FASTAPI\app\core\security.py", line 93, in decode_token
    payload = jwt.decode(token, settings.SECRET_KEY, algorithms=[settings.ALGORITHM])
  File "C:\Users\Dhanush\AppData\Local\Programs\Python\Python313\Lib\site-packages\jose\jwt.py", line 174, in decode
    _validate_claims(
    ~~~~~~~~~~~~~~~~^
        claims,
        ^^^^^^^
    ...<5 lines>...
        options=defaults,
        ^^^^^^^^^^^^^^^^^
    )
    ^
  File "C:\Users\Dhanush\AppData\Local\Programs\Python\Python313\Lib\site-packages\jose\jwt.py", line 497, in _validate_claims
    _validate_exp(claims, leeway=leeway)
    ~~~~~~~~~~~~~^^^^^^^^^^^^^^^^^^^^^^^
  File "C:\Users\Dhanush\AppData\Local\Programs\Python\Python313\Lib\site-packages\jose\jwt.py", line 331, in _validate_exp
    raise ExpiredSignatureError("Signature has expired.")
jose.exceptions.ExpiredSignatureError: Signature has expired.

During handling of the above exception, another exception occurred:

Traceback (most recent call last):
  File "C:\Users\Dhanush\FASTAPI\app\core\security.py", line 281, in get_current_user
    payload = decode_token(token)
  File "C:\Users\Dhanush\FASTAPI\app\core\security.py", line 98, in decode_token
    raise JWTError("Could not validate credentials")
jose.exceptions.JWTError: Could not validate credentials

During handling of the above exception, another exception occurred:

Traceback (most recent call last):
  File "C:\Users\Dhanush\FASTAPI\app\database\session.py", line 65, in get_db
    yield session
  File "C:\Users\Dhanush\AppData\Local\Programs\Python\Python313\Lib\site-packages\fastapi\routing.py", line 291, in app
    solved_result = await solve_dependencies(
                    ^^^^^^^^^^^^^^^^^^^^^^^^^
    ...<6 lines>...
    )
    ^
  File "C:\Users\Dhanush\AppData\Local\Programs\Python\Python313\Lib\site-packages\fastapi\dependencies\utils.py", line 638, in solve_dependencies
    solved = await call(**solved_result.values)
             ^^^^^^^^^^^^^^^^^^^^^^^^^^^^^^^^^^
  File "C:\Users\Dhanush\FASTAPI\app\core\security.py", line 326, in get_current_user
    raise credentials_exception
fastapi.exceptions.HTTPException: 401: Could not validate credentials
2025-06-27 05:50:01,871 - database - INFO - Session rolled back due to error
2025-06-27 05:50:01,872 - database - DEBUG - Closing database session
2025-06-27 05:50:23,415 - database - DEBUG - Database session used successfully
2025-06-27 05:50:23,415 - database - DEBUG - Closing database session
2025-06-27 06:02:50,281 - database - DEBUG - Creating new database session
2025-06-27 06:02:50,301 - database - DEBUG - Database session used successfully
2025-06-27 06:02:50,301 - database - DEBUG - Closing database session
2025-06-27 06:02:50,308 - database - DEBUG - Creating new database session
2025-06-27 06:02:50,318 - database - ERROR - Error in database session: 401: Could not validate credentials
Traceback (most recent call last):
  File "C:\Users\Dhanush\FASTAPI\app\core\security.py", line 93, in decode_token
    payload = jwt.decode(token, settings.SECRET_KEY, algorithms=[settings.ALGORITHM])
  File "C:\Users\Dhanush\AppData\Local\Programs\Python\Python313\Lib\site-packages\jose\jwt.py", line 174, in decode
    _validate_claims(
    ~~~~~~~~~~~~~~~~^
        claims,
        ^^^^^^^
    ...<5 lines>...
        options=defaults,
        ^^^^^^^^^^^^^^^^^
    )
    ^
  File "C:\Users\Dhanush\AppData\Local\Programs\Python\Python313\Lib\site-packages\jose\jwt.py", line 497, in _validate_claims
    _validate_exp(claims, leeway=leeway)
    ~~~~~~~~~~~~~^^^^^^^^^^^^^^^^^^^^^^^
  File "C:\Users\Dhanush\AppData\Local\Programs\Python\Python313\Lib\site-packages\jose\jwt.py", line 331, in _validate_exp
    raise ExpiredSignatureError("Signature has expired.")
jose.exceptions.ExpiredSignatureError: Signature has expired.

During handling of the above exception, another exception occurred:

Traceback (most recent call last):
  File "C:\Users\Dhanush\FASTAPI\app\core\security.py", line 281, in get_current_user
    payload = decode_token(token)
  File "C:\Users\Dhanush\FASTAPI\app\core\security.py", line 98, in decode_token
    raise JWTError("Could not validate credentials")
jose.exceptions.JWTError: Could not validate credentials

During handling of the above exception, another exception occurred:

Traceback (most recent call last):
  File "C:\Users\Dhanush\FASTAPI\app\database\session.py", line 65, in get_db
    yield session
  File "C:\Users\Dhanush\AppData\Local\Programs\Python\Python313\Lib\site-packages\fastapi\routing.py", line 291, in app
    solved_result = await solve_dependencies(
                    ^^^^^^^^^^^^^^^^^^^^^^^^^
    ...<6 lines>...
    )
    ^
  File "C:\Users\Dhanush\AppData\Local\Programs\Python\Python313\Lib\site-packages\fastapi\dependencies\utils.py", line 638, in solve_dependencies
    solved = await call(**solved_result.values)
             ^^^^^^^^^^^^^^^^^^^^^^^^^^^^^^^^^^
  File "C:\Users\Dhanush\FASTAPI\app\core\security.py", line 326, in get_current_user
    raise credentials_exception
fastapi.exceptions.HTTPException: 401: Could not validate credentials
2025-06-27 06:02:50,330 - database - INFO - Session rolled back due to error
2025-06-27 06:02:50,331 - database - DEBUG - Closing database session
2025-06-27 06:02:50,346 - database - DEBUG - Creating new database session
2025-06-27 06:02:50,353 - database - ERROR - Error in database session: 401: Could not validate credentials
Traceback (most recent call last):
  File "C:\Users\Dhanush\FASTAPI\app\core\security.py", line 93, in decode_token
    payload = jwt.decode(token, settings.SECRET_KEY, algorithms=[settings.ALGORITHM])
  File "C:\Users\Dhanush\AppData\Local\Programs\Python\Python313\Lib\site-packages\jose\jwt.py", line 174, in decode
    _validate_claims(
    ~~~~~~~~~~~~~~~~^
        claims,
        ^^^^^^^
    ...<5 lines>...
        options=defaults,
        ^^^^^^^^^^^^^^^^^
    )
    ^
  File "C:\Users\Dhanush\AppData\Local\Programs\Python\Python313\Lib\site-packages\jose\jwt.py", line 497, in _validate_claims
    _validate_exp(claims, leeway=leeway)
    ~~~~~~~~~~~~~^^^^^^^^^^^^^^^^^^^^^^^
  File "C:\Users\Dhanush\AppData\Local\Programs\Python\Python313\Lib\site-packages\jose\jwt.py", line 331, in _validate_exp
    raise ExpiredSignatureError("Signature has expired.")
jose.exceptions.ExpiredSignatureError: Signature has expired.

During handling of the above exception, another exception occurred:

Traceback (most recent call last):
  File "C:\Users\Dhanush\FASTAPI\app\core\security.py", line 281, in get_current_user
    payload = decode_token(token)
  File "C:\Users\Dhanush\FASTAPI\app\core\security.py", line 98, in decode_token
    raise JWTError("Could not validate credentials")
jose.exceptions.JWTError: Could not validate credentials

During handling of the above exception, another exception occurred:

Traceback (most recent call last):
  File "C:\Users\Dhanush\FASTAPI\app\database\session.py", line 65, in get_db
    yield session
  File "C:\Users\Dhanush\AppData\Local\Programs\Python\Python313\Lib\site-packages\fastapi\routing.py", line 291, in app
    solved_result = await solve_dependencies(
                    ^^^^^^^^^^^^^^^^^^^^^^^^^
    ...<6 lines>...
    )
    ^
  File "C:\Users\Dhanush\AppData\Local\Programs\Python\Python313\Lib\site-packages\fastapi\dependencies\utils.py", line 638, in solve_dependencies
    solved = await call(**solved_result.values)
             ^^^^^^^^^^^^^^^^^^^^^^^^^^^^^^^^^^
  File "C:\Users\Dhanush\FASTAPI\app\core\security.py", line 326, in get_current_user
    raise credentials_exception
fastapi.exceptions.HTTPException: 401: Could not validate credentials
2025-06-27 06:02:50,359 - database - INFO - Session rolled back due to error
2025-06-27 06:02:50,360 - database - DEBUG - Closing database session
2025-06-27 06:02:52,520 - database - DEBUG - Creating new database session
2025-06-27 06:02:52,527 - database - ERROR - Error in database session: 401: Could not validate credentials
Traceback (most recent call last):
  File "C:\Users\Dhanush\FASTAPI\app\core\security.py", line 93, in decode_token
    payload = jwt.decode(token, settings.SECRET_KEY, algorithms=[settings.ALGORITHM])
  File "C:\Users\Dhanush\AppData\Local\Programs\Python\Python313\Lib\site-packages\jose\jwt.py", line 174, in decode
    _validate_claims(
    ~~~~~~~~~~~~~~~~^
        claims,
        ^^^^^^^
    ...<5 lines>...
        options=defaults,
        ^^^^^^^^^^^^^^^^^
    )
    ^
  File "C:\Users\Dhanush\AppData\Local\Programs\Python\Python313\Lib\site-packages\jose\jwt.py", line 497, in _validate_claims
    _validate_exp(claims, leeway=leeway)
    ~~~~~~~~~~~~~^^^^^^^^^^^^^^^^^^^^^^^
  File "C:\Users\Dhanush\AppData\Local\Programs\Python\Python313\Lib\site-packages\jose\jwt.py", line 331, in _validate_exp
    raise ExpiredSignatureError("Signature has expired.")
jose.exceptions.ExpiredSignatureError: Signature has expired.

During handling of the above exception, another exception occurred:

Traceback (most recent call last):
  File "C:\Users\Dhanush\FASTAPI\app\core\security.py", line 281, in get_current_user
    payload = decode_token(token)
  File "C:\Users\Dhanush\FASTAPI\app\core\security.py", line 98, in decode_token
    raise JWTError("Could not validate credentials")
jose.exceptions.JWTError: Could not validate credentials

During handling of the above exception, another exception occurred:

Traceback (most recent call last):
  File "C:\Users\Dhanush\FASTAPI\app\database\session.py", line 65, in get_db
    yield session
  File "C:\Users\Dhanush\AppData\Local\Programs\Python\Python313\Lib\site-packages\fastapi\routing.py", line 291, in app
    solved_result = await solve_dependencies(
                    ^^^^^^^^^^^^^^^^^^^^^^^^^
    ...<6 lines>...
    )
    ^
  File "C:\Users\Dhanush\AppData\Local\Programs\Python\Python313\Lib\site-packages\fastapi\dependencies\utils.py", line 638, in solve_dependencies
    solved = await call(**solved_result.values)
             ^^^^^^^^^^^^^^^^^^^^^^^^^^^^^^^^^^
  File "C:\Users\Dhanush\FASTAPI\app\core\security.py", line 326, in get_current_user
    raise credentials_exception
fastapi.exceptions.HTTPException: 401: Could not validate credentials
2025-06-27 06:02:52,532 - database - INFO - Session rolled back due to error
2025-06-27 06:02:52,533 - database - DEBUG - Closing database session
2025-06-27 06:02:56,383 - database - DEBUG - Creating new database session
2025-06-27 06:02:56,890 - database - DEBUG - Database session used successfully
2025-06-27 06:02:56,891 - database - DEBUG - Closing database session
2025-06-27 06:02:58,286 - database - DEBUG - Creating new database session
2025-06-27 06:02:58,407 - database - DEBUG - Database session used successfully
2025-06-27 06:02:58,410 - database - DEBUG - Closing database session
2025-06-27 06:02:58,447 - database - DEBUG - Creating new database session
2025-06-27 06:02:58,598 - database - DEBUG - Database session used successfully
2025-06-27 06:02:58,598 - database - DEBUG - Closing database session
2025-06-27 06:02:58,610 - database - DEBUG - Creating new database session
2025-06-27 06:02:58,682 - database - DEBUG - Database session used successfully
2025-06-27 06:02:58,690 - database - DEBUG - Closing database session
2025-06-27 06:02:58,730 - database - DEBUG - Creating new database session
2025-06-27 06:03:00,671 - database - DEBUG - Database session used successfully
2025-06-27 06:03:00,672 - database - DEBUG - Closing database session
2025-06-27 06:03:00,733 - database - DEBUG - Creating new database session
2025-06-27 06:03:00,785 - database - DEBUG - Creating new database session
2025-06-27 06:03:00,952 - database - DEBUG - Database session used successfully
2025-06-27 06:03:00,956 - database - DEBUG - Closing database session
2025-06-27 06:03:03,472 - database - DEBUG - Database session used successfully
2025-06-27 06:03:03,476 - database - DEBUG - Closing database session
2025-06-27 06:03:03,862 - database - DEBUG - Creating new database session
2025-06-27 06:04:14,439 - database - DEBUG - Creating new database session
2025-06-27 06:04:14,535 - database - DEBUG - Database session used successfully
2025-06-27 06:04:14,536 - database - DEBUG - Closing database session
2025-06-27 06:04:18,636 - database - DEBUG - Creating new database session
2025-06-27 06:04:18,656 - database - ERROR - Error in database session: 500: An error occurred while refreshing token.
Traceback (most recent call last):
  File "C:\Users\Dhanush\FASTAPI\app\api\v1\endpoints\users.py", line 310, in refresh_access_token
     raise HTTPException(
    ...<3 lines>...
    )
fastapi.exceptions.HTTPException: 401: Invalid or expired refresh token

During handling of the above exception, another exception occurred:

Traceback (most recent call last):
  File "C:\Users\Dhanush\FASTAPI\app\database\session.py", line 65, in get_db
    yield session
  File "C:\Users\Dhanush\AppData\Local\Programs\Python\Python313\Lib\site-packages\fastapi\routing.py", line 301, in app
    raw_response = await run_endpoint_function(
                   ^^^^^^^^^^^^^^^^^^^^^^^^^^^^
    ...<3 lines>...
    )
    ^
  File "C:\Users\Dhanush\AppData\Local\Programs\Python\Python313\Lib\site-packages\fastapi\routing.py", line 212, in run_endpoint_function
    return await dependant.call(**values)
           ^^^^^^^^^^^^^^^^^^^^^^^^^^^^^^
  File "C:\Users\Dhanush\FASTAPI\app\api\v1\endpoints\users.py", line 360, in refresh_access_token
    raise HTTPException(
    ...<2 lines>...
    )
fastapi.exceptions.HTTPException: 500: An error occurred while refreshing token.
2025-06-27 06:04:18,664 - database - INFO - Session rolled back due to error
2025-06-27 06:04:18,665 - database - DEBUG - Closing database session
2025-06-27 06:04:19,793 - database - DEBUG - Creating new database session
2025-06-27 06:04:21,983 - database - DEBUG - Database session used successfully
2025-06-27 06:04:21,984 - database - DEBUG - Closing database session
2025-06-27 06:05:18,956 - database - DEBUG - Creating new database session
2025-06-27 06:05:18,966 - database - ERROR - Error in database session: 500: An error occurred while refreshing token.
Traceback (most recent call last):
  File "C:\Users\Dhanush\FASTAPI\app\api\v1\endpoints\users.py", line 310, in refresh_access_token
     raise HTTPException(
    ...<3 lines>...
    )
fastapi.exceptions.HTTPException: 401: Invalid or expired refresh token

During handling of the above exception, another exception occurred:

Traceback (most recent call last):
  File "C:\Users\Dhanush\FASTAPI\app\database\session.py", line 65, in get_db
    yield session
  File "C:\Users\Dhanush\AppData\Local\Programs\Python\Python313\Lib\site-packages\fastapi\routing.py", line 301, in app
    raw_response = await run_endpoint_function(
                   ^^^^^^^^^^^^^^^^^^^^^^^^^^^^
    ...<3 lines>...
    )
    ^
  File "C:\Users\Dhanush\AppData\Local\Programs\Python\Python313\Lib\site-packages\fastapi\routing.py", line 212, in run_endpoint_function
    return await dependant.call(**values)
           ^^^^^^^^^^^^^^^^^^^^^^^^^^^^^^
  File "C:\Users\Dhanush\FASTAPI\app\api\v1\endpoints\users.py", line 360, in refresh_access_token
    raise HTTPException(
    ...<2 lines>...
    )
fastapi.exceptions.HTTPException: 500: An error occurred while refreshing token.
2025-06-27 06:05:18,970 - database - INFO - Session rolled back due to error
2025-06-27 06:05:18,972 - database - DEBUG - Closing database session
2025-06-27 06:05:28,773 - database - DEBUG - Creating new database session
2025-06-27 06:05:28,807 - database - DEBUG - Database session used successfully
2025-06-27 06:05:28,809 - database - DEBUG - Closing database session
2025-06-27 06:05:41,533 - database - DEBUG - Creating new database session
2025-06-27 06:05:41,538 - database - ERROR - Error in database session: 500: An error occurred while refreshing token.
Traceback (most recent call last):
  File "C:\Users\Dhanush\FASTAPI\app\api\v1\endpoints\users.py", line 310, in refresh_access_token
     raise HTTPException(
    ...<3 lines>...
    )
fastapi.exceptions.HTTPException: 401: Invalid or expired refresh token

During handling of the above exception, another exception occurred:

Traceback (most recent call last):
  File "C:\Users\Dhanush\FASTAPI\app\database\session.py", line 65, in get_db
    yield session
  File "C:\Users\Dhanush\AppData\Local\Programs\Python\Python313\Lib\site-packages\fastapi\routing.py", line 301, in app
    raw_response = await run_endpoint_function(
                   ^^^^^^^^^^^^^^^^^^^^^^^^^^^^
    ...<3 lines>...
    )
    ^
  File "C:\Users\Dhanush\AppData\Local\Programs\Python\Python313\Lib\site-packages\fastapi\routing.py", line 212, in run_endpoint_function
    return await dependant.call(**values)
           ^^^^^^^^^^^^^^^^^^^^^^^^^^^^^^
  File "C:\Users\Dhanush\FASTAPI\app\api\v1\endpoints\users.py", line 360, in refresh_access_token
    raise HTTPException(
    ...<2 lines>...
    )
fastapi.exceptions.HTTPException: 500: An error occurred while refreshing token.
2025-06-27 06:05:41,539 - database - INFO - Session rolled back due to error
2025-06-27 06:05:41,540 - database - DEBUG - Closing database session
2025-06-27 06:06:02,251 - database - DEBUG - Database session used successfully
2025-06-27 06:06:02,254 - database - DEBUG - Closing database session
2025-06-27 06:06:02,399 - database - DEBUG - Creating new database session
2025-06-27 06:06:02,433 - database - DEBUG - Database session used successfully
2025-06-27 06:06:02,433 - database - DEBUG - Closing database session
2025-06-27 06:06:02,469 - database - DEBUG - Creating new database session
2025-06-27 06:06:02,522 - database - DEBUG - Database session used successfully
2025-06-27 06:06:02,525 - database - DEBUG - Closing database session
2025-06-27 06:06:02,579 - database - DEBUG - Creating new database session
2025-06-27 06:06:02,920 - database - DEBUG - Creating new database session
2025-06-27 06:06:03,159 - database - DEBUG - Database session used successfully
2025-06-27 06:06:03,180 - database - DEBUG - Closing database session
2025-06-27 06:06:04,414 - database - DEBUG - Database session used successfully
2025-06-27 06:06:04,415 - database - DEBUG - Closing database session
2025-06-27 06:06:04,448 - database - DEBUG - Creating new database session
2025-06-27 06:06:05,110 - database - DEBUG - Creating new database session
2025-06-27 06:06:07,561 - database - DEBUG - Database session used successfully
2025-06-27 06:06:07,563 - database - DEBUG - Closing database session
2025-06-27 06:06:07,672 - database - DEBUG - Creating new database session
2025-06-27 06:06:07,767 - database - DEBUG - Database session used successfully
2025-06-27 06:06:07,771 - database - DEBUG - Closing database session
2025-06-27 06:08:12,286 - database - DEBUG - Creating new database session
2025-06-27 06:08:13,882 - database - DEBUG - Database session used successfully
2025-06-27 06:08:13,883 - database - DEBUG - Closing database session
2025-06-27 06:08:15,773 - database - DEBUG - Creating new database session
2025-06-27 06:08:16,469 - database - DEBUG - Database session used successfully
2025-06-27 06:08:16,470 - database - DEBUG - Closing database session
2025-06-27 06:08:17,797 - database - DEBUG - Creating new database session
2025-06-27 06:08:17,834 - database - DEBUG - Database session used successfully
2025-06-27 06:08:17,835 - database - DEBUG - Closing database session
2025-06-27 06:08:17,863 - database - DEBUG - Creating new database session
2025-06-27 06:08:17,902 - database - DEBUG - Creating new database session
2025-06-27 06:08:17,927 - database - DEBUG - Database session used successfully
2025-06-27 06:08:17,931 - database - DEBUG - Closing database session
2025-06-27 06:08:18,003 - database - DEBUG - Creating new database session
2025-06-27 06:08:18,079 - database - DEBUG - Database session used successfully
2025-06-27 06:08:18,080 - database - DEBUG - Closing database session
2025-06-27 06:08:19,940 - database - DEBUG - Database session used successfully
2025-06-27 06:08:19,941 - database - DEBUG - Closing database session
2025-06-27 06:08:19,984 - database - DEBUG - Creating new database session
2025-06-27 06:08:20,333 - database - DEBUG - Creating new database session
2025-06-27 06:08:22,325 - database - DEBUG - Database session used successfully
2025-06-27 06:08:22,328 - database - DEBUG - Closing database session
2025-06-27 06:08:22,392 - database - DEBUG - Creating new database session
2025-06-27 06:08:22,452 - database - DEBUG - Database session used successfully
2025-06-27 06:08:22,454 - database - DEBUG - Closing database session
2025-06-27 06:08:41,778 - database - DEBUG - Creating new database session
2025-06-27 06:08:43,764 - database - DEBUG - Database session used successfully
2025-06-27 06:08:43,765 - database - DEBUG - Closing database session
2025-06-27 06:09:32,991 - database - DEBUG - Creating new database session
2025-06-27 06:09:33,020 - database - ERROR - Error in database session: 500: An error occurred while refreshing token.
Traceback (most recent call last):
  File "C:\Users\Dhanush\FASTAPI\app\api\v1\endpoints\users.py", line 310, in refresh_access_token
     raise HTTPException(
    ...<3 lines>...
    )
fastapi.exceptions.HTTPException: 401: Invalid or expired refresh token

During handling of the above exception, another exception occurred:

Traceback (most recent call last):
  File "C:\Users\Dhanush\FASTAPI\app\database\session.py", line 65, in get_db
    yield session
  File "C:\Users\Dhanush\AppData\Local\Programs\Python\Python313\Lib\site-packages\fastapi\routing.py", line 301, in app
    raw_response = await run_endpoint_function(
                   ^^^^^^^^^^^^^^^^^^^^^^^^^^^^
    ...<3 lines>...
    )
    ^
  File "C:\Users\Dhanush\AppData\Local\Programs\Python\Python313\Lib\site-packages\fastapi\routing.py", line 212, in run_endpoint_function
    return await dependant.call(**values)
           ^^^^^^^^^^^^^^^^^^^^^^^^^^^^^^
  File "C:\Users\Dhanush\FASTAPI\app\api\v1\endpoints\users.py", line 360, in refresh_access_token
    raise HTTPException(
    ...<2 lines>...
    )
fastapi.exceptions.HTTPException: 500: An error occurred while refreshing token.
2025-06-27 06:09:33,031 - database - INFO - Session rolled back due to error
2025-06-27 06:09:33,032 - database - DEBUG - Closing database session
2025-06-27 06:09:34,688 - database - DEBUG - Creating new database session
2025-06-27 06:09:34,783 - database - DEBUG - Database session used successfully
2025-06-27 06:09:34,784 - database - DEBUG - Closing database session
2025-06-27 06:10:07,197 - database - DEBUG - Creating new database session
2025-06-27 06:10:07,199 - database - ERROR - Error in database session: 500: An error occurred while refreshing token.
Traceback (most recent call last):
  File "C:\Users\Dhanush\FASTAPI\app\api\v1\endpoints\users.py", line 310, in refresh_access_token
     raise HTTPException(
    ...<3 lines>...
    )
fastapi.exceptions.HTTPException: 401: Invalid or expired refresh token

During handling of the above exception, another exception occurred:

Traceback (most recent call last):
  File "C:\Users\Dhanush\FASTAPI\app\database\session.py", line 65, in get_db
    yield session
  File "C:\Users\Dhanush\AppData\Local\Programs\Python\Python313\Lib\site-packages\fastapi\routing.py", line 301, in app
    raw_response = await run_endpoint_function(
                   ^^^^^^^^^^^^^^^^^^^^^^^^^^^^
    ...<3 lines>...
    )
    ^
  File "C:\Users\Dhanush\AppData\Local\Programs\Python\Python313\Lib\site-packages\fastapi\routing.py", line 212, in run_endpoint_function
    return await dependant.call(**values)
           ^^^^^^^^^^^^^^^^^^^^^^^^^^^^^^
  File "C:\Users\Dhanush\FASTAPI\app\api\v1\endpoints\users.py", line 360, in refresh_access_token
    raise HTTPException(
    ...<2 lines>...
    )
fastapi.exceptions.HTTPException: 500: An error occurred while refreshing token.
2025-06-27 06:10:07,201 - database - INFO - Session rolled back due to error
2025-06-27 06:10:07,202 - database - DEBUG - Closing database session
2025-06-27 06:10:49,619 - database - DEBUG - Creating new database session
2025-06-27 06:10:49,633 - database - DEBUG - Database session used successfully
2025-06-27 06:10:49,634 - database - DEBUG - Closing database session
2025-06-27 06:11:03,716 - database - DEBUG - Creating new database session
2025-06-27 06:11:03,724 - database - ERROR - Error in database session: 500: An error occurred while refreshing token.
Traceback (most recent call last):
  File "C:\Users\Dhanush\FASTAPI\app\api\v1\endpoints\users.py", line 310, in refresh_access_token
     raise HTTPException(
    ...<3 lines>...
    )
fastapi.exceptions.HTTPException: 401: Invalid or expired refresh token

During handling of the above exception, another exception occurred:

Traceback (most recent call last):
  File "C:\Users\Dhanush\FASTAPI\app\database\session.py", line 65, in get_db
    yield session
  File "C:\Users\Dhanush\AppData\Local\Programs\Python\Python313\Lib\site-packages\fastapi\routing.py", line 301, in app
    raw_response = await run_endpoint_function(
                   ^^^^^^^^^^^^^^^^^^^^^^^^^^^^
    ...<3 lines>...
    )
    ^
  File "C:\Users\Dhanush\AppData\Local\Programs\Python\Python313\Lib\site-packages\fastapi\routing.py", line 212, in run_endpoint_function
    return await dependant.call(**values)
           ^^^^^^^^^^^^^^^^^^^^^^^^^^^^^^
  File "C:\Users\Dhanush\FASTAPI\app\api\v1\endpoints\users.py", line 360, in refresh_access_token
    raise HTTPException(
    ...<2 lines>...
    )
fastapi.exceptions.HTTPException: 500: An error occurred while refreshing token.
2025-06-27 06:11:03,728 - database - INFO - Session rolled back due to error
2025-06-27 06:11:03,729 - database - DEBUG - Closing database session
2025-06-27 06:11:18,269 - database - DEBUG - Creating new database session
2025-06-27 06:11:18,283 - database - ERROR - Error in database session: 500: An error occurred while refreshing token.
Traceback (most recent call last):
  File "C:\Users\Dhanush\FASTAPI\app\api\v1\endpoints\users.py", line 310, in refresh_access_token
     raise HTTPException(
    ...<3 lines>...
    )
fastapi.exceptions.HTTPException: 401: Invalid or expired refresh token

During handling of the above exception, another exception occurred:

Traceback (most recent call last):
  File "C:\Users\Dhanush\FASTAPI\app\database\session.py", line 65, in get_db
    yield session
  File "C:\Users\Dhanush\AppData\Local\Programs\Python\Python313\Lib\site-packages\fastapi\routing.py", line 301, in app
    raw_response = await run_endpoint_function(
                   ^^^^^^^^^^^^^^^^^^^^^^^^^^^^
    ...<3 lines>...
    )
    ^
  File "C:\Users\Dhanush\AppData\Local\Programs\Python\Python313\Lib\site-packages\fastapi\routing.py", line 212, in run_endpoint_function
    return await dependant.call(**values)
           ^^^^^^^^^^^^^^^^^^^^^^^^^^^^^^
  File "C:\Users\Dhanush\FASTAPI\app\api\v1\endpoints\users.py", line 360, in refresh_access_token
    raise HTTPException(
    ...<2 lines>...
    )
fastapi.exceptions.HTTPException: 500: An error occurred while refreshing token.
2025-06-27 06:11:18,289 - database - INFO - Session rolled back due to error
2025-06-27 06:11:18,290 - database - DEBUG - Closing database session
2025-06-27 06:12:05,880 - database - DEBUG - Creating new database session
2025-06-27 06:12:05,903 - database - DEBUG - Database session used successfully
2025-06-27 06:12:05,904 - database - DEBUG - Closing database session
2025-06-27 06:12:06,689 - database - DEBUG - Creating new database session
2025-06-27 06:12:06,695 - database - ERROR - Error in database session: 500: An error occurred while refreshing token.
Traceback (most recent call last):
  File "C:\Users\Dhanush\FASTAPI\app\api\v1\endpoints\users.py", line 310, in refresh_access_token
     raise HTTPException(
    ...<3 lines>...
    )
fastapi.exceptions.HTTPException: 401: Invalid or expired refresh token

During handling of the above exception, another exception occurred:

Traceback (most recent call last):
  File "C:\Users\Dhanush\FASTAPI\app\database\session.py", line 65, in get_db
    yield session
  File "C:\Users\Dhanush\AppData\Local\Programs\Python\Python313\Lib\site-packages\fastapi\routing.py", line 301, in app
    raw_response = await run_endpoint_function(
                   ^^^^^^^^^^^^^^^^^^^^^^^^^^^^
    ...<3 lines>...
    )
    ^
  File "C:\Users\Dhanush\AppData\Local\Programs\Python\Python313\Lib\site-packages\fastapi\routing.py", line 212, in run_endpoint_function
    return await dependant.call(**values)
           ^^^^^^^^^^^^^^^^^^^^^^^^^^^^^^
  File "C:\Users\Dhanush\FASTAPI\app\api\v1\endpoints\users.py", line 360, in refresh_access_token
    raise HTTPException(
    ...<2 lines>...
    )
fastapi.exceptions.HTTPException: 500: An error occurred while refreshing token.
2025-06-27 06:12:06,697 - database - INFO - Session rolled back due to error
2025-06-27 06:12:06,698 - database - DEBUG - Closing database session
2025-06-27 06:12:21,718 - database - DEBUG - Database session used successfully
2025-06-27 06:12:21,719 - database - DEBUG - Closing database session
2025-06-28 04:37:11,713 - database - DEBUG - Creating new database session
2025-06-28 04:37:11,771 - database - ERROR - Error in database session: 401: Could not validate credentials
Traceback (most recent call last):
  File "C:\Users\Dhanush\FASTAPI\app\core\security.py", line 93, in decode_token
    payload = jwt.decode(token, settings.SECRET_KEY, algorithms=[settings.ALGORITHM])
  File "C:\Users\Dhanush\FASTAPI\venv\Lib\site-packages\jose\jwt.py", line 174, in decode
    _validate_claims(
    ~~~~~~~~~~~~~~~~^
        claims,
        ^^^^^^^
    ...<5 lines>...
        options=defaults,
        ^^^^^^^^^^^^^^^^^
    )
    ^
  File "C:\Users\Dhanush\FASTAPI\venv\Lib\site-packages\jose\jwt.py", line 497, in _validate_claims
    _validate_exp(claims, leeway=leeway)
    ~~~~~~~~~~~~~^^^^^^^^^^^^^^^^^^^^^^^
  File "C:\Users\Dhanush\FASTAPI\venv\Lib\site-packages\jose\jwt.py", line 331, in _validate_exp
    raise ExpiredSignatureError("Signature has expired.")
jose.exceptions.ExpiredSignatureError: Signature has expired.

During handling of the above exception, another exception occurred:

Traceback (most recent call last):
  File "C:\Users\Dhanush\FASTAPI\app\core\security.py", line 371, in get_user_from_service_or_user_token
    payload = decode_token(token)
  File "C:\Users\Dhanush\FASTAPI\app\core\security.py", line 98, in decode_token
    raise JWTError("Could not validate credentials")
jose.exceptions.JWTError: Could not validate credentials

During handling of the above exception, another exception occurred:

Traceback (most recent call last):
  File "C:\Users\Dhanush\FASTAPI\app\database\session.py", line 65, in get_db
    yield session
  File "C:\Users\Dhanush\FASTAPI\venv\Lib\site-packages\fastapi\routing.py", line 291, in app
    solved_result = await solve_dependencies(
                    ^^^^^^^^^^^^^^^^^^^^^^^^^
    ...<6 lines>...
    )
    ^
  File "C:\Users\Dhanush\FASTAPI\venv\Lib\site-packages\fastapi\dependencies\utils.py", line 638, in solve_dependencies
    solved = await call(**solved_result.values)
             ^^^^^^^^^^^^^^^^^^^^^^^^^^^^^^^^^^
  File "C:\Users\Dhanush\FASTAPI\app\core\security.py", line 424, in get_user_from_service_or_user_token
    raise HTTPException(
    ...<3 lines>...
    )
fastapi.exceptions.HTTPException: 401: Could not validate credentials
2025-06-28 04:37:11,785 - database - INFO - Session rolled back due to error
2025-06-28 04:37:11,787 - database - DEBUG - Closing database session
2025-06-28 04:37:11,826 - database - DEBUG - Creating new database session
2025-06-28 04:37:11,866 - database - ERROR - Error in database session: 401: Could not validate credentials
Traceback (most recent call last):
  File "C:\Users\Dhanush\FASTAPI\app\core\security.py", line 93, in decode_token
    payload = jwt.decode(token, settings.SECRET_KEY, algorithms=[settings.ALGORITHM])
  File "C:\Users\Dhanush\FASTAPI\venv\Lib\site-packages\jose\jwt.py", line 174, in decode
    _validate_claims(
    ~~~~~~~~~~~~~~~~^
        claims,
        ^^^^^^^
    ...<5 lines>...
        options=defaults,
        ^^^^^^^^^^^^^^^^^
    )
    ^
  File "C:\Users\Dhanush\FASTAPI\venv\Lib\site-packages\jose\jwt.py", line 497, in _validate_claims
    _validate_exp(claims, leeway=leeway)
    ~~~~~~~~~~~~~^^^^^^^^^^^^^^^^^^^^^^^
  File "C:\Users\Dhanush\FASTAPI\venv\Lib\site-packages\jose\jwt.py", line 331, in _validate_exp
    raise ExpiredSignatureError("Signature has expired.")
jose.exceptions.ExpiredSignatureError: Signature has expired.

During handling of the above exception, another exception occurred:

Traceback (most recent call last):
  File "C:\Users\Dhanush\FASTAPI\app\core\security.py", line 371, in get_user_from_service_or_user_token
    payload = decode_token(token)
  File "C:\Users\Dhanush\FASTAPI\app\core\security.py", line 98, in decode_token
    raise JWTError("Could not validate credentials")
jose.exceptions.JWTError: Could not validate credentials

During handling of the above exception, another exception occurred:

Traceback (most recent call last):
  File "C:\Users\Dhanush\FASTAPI\app\database\session.py", line 65, in get_db
    yield session
  File "C:\Users\Dhanush\FASTAPI\venv\Lib\site-packages\fastapi\routing.py", line 291, in app
    solved_result = await solve_dependencies(
                    ^^^^^^^^^^^^^^^^^^^^^^^^^
    ...<6 lines>...
    )
    ^
  File "C:\Users\Dhanush\FASTAPI\venv\Lib\site-packages\fastapi\dependencies\utils.py", line 638, in solve_dependencies
    solved = await call(**solved_result.values)
             ^^^^^^^^^^^^^^^^^^^^^^^^^^^^^^^^^^
  File "C:\Users\Dhanush\FASTAPI\app\core\security.py", line 424, in get_user_from_service_or_user_token
    raise HTTPException(
    ...<3 lines>...
    )
fastapi.exceptions.HTTPException: 401: Could not validate credentials
2025-06-28 04:37:11,874 - database - INFO - Session rolled back due to error
2025-06-28 04:37:11,875 - database - DEBUG - Closing database session
2025-06-28 04:37:11,907 - database - DEBUG - Creating new database session
2025-06-28 04:37:11,944 - database - ERROR - Error in database session: 401: Could not validate credentials
Traceback (most recent call last):
  File "C:\Users\Dhanush\FASTAPI\app\core\security.py", line 93, in decode_token
    payload = jwt.decode(token, settings.SECRET_KEY, algorithms=[settings.ALGORITHM])
  File "C:\Users\Dhanush\FASTAPI\venv\Lib\site-packages\jose\jwt.py", line 174, in decode
    _validate_claims(
    ~~~~~~~~~~~~~~~~^
        claims,
        ^^^^^^^
    ...<5 lines>...
        options=defaults,
        ^^^^^^^^^^^^^^^^^
    )
    ^
  File "C:\Users\Dhanush\FASTAPI\venv\Lib\site-packages\jose\jwt.py", line 497, in _validate_claims
    _validate_exp(claims, leeway=leeway)
    ~~~~~~~~~~~~~^^^^^^^^^^^^^^^^^^^^^^^
  File "C:\Users\Dhanush\FASTAPI\venv\Lib\site-packages\jose\jwt.py", line 331, in _validate_exp
    raise ExpiredSignatureError("Signature has expired.")
jose.exceptions.ExpiredSignatureError: Signature has expired.

During handling of the above exception, another exception occurred:

Traceback (most recent call last):
  File "C:\Users\Dhanush\FASTAPI\app\core\security.py", line 281, in get_current_user
    payload = decode_token(token)
  File "C:\Users\Dhanush\FASTAPI\app\core\security.py", line 98, in decode_token
    raise JWTError("Could not validate credentials")
jose.exceptions.JWTError: Could not validate credentials

During handling of the above exception, another exception occurred:

Traceback (most recent call last):
  File "C:\Users\Dhanush\FASTAPI\app\database\session.py", line 65, in get_db
    yield session
  File "C:\Users\Dhanush\FASTAPI\venv\Lib\site-packages\fastapi\routing.py", line 291, in app
    solved_result = await solve_dependencies(
                    ^^^^^^^^^^^^^^^^^^^^^^^^^
    ...<6 lines>...
    )
    ^
  File "C:\Users\Dhanush\FASTAPI\venv\Lib\site-packages\fastapi\dependencies\utils.py", line 638, in solve_dependencies
    solved = await call(**solved_result.values)
             ^^^^^^^^^^^^^^^^^^^^^^^^^^^^^^^^^^
  File "C:\Users\Dhanush\FASTAPI\app\core\security.py", line 326, in get_current_user
    raise credentials_exception
fastapi.exceptions.HTTPException: 401: Could not validate credentials
2025-06-28 04:37:11,955 - database - INFO - Session rolled back due to error
2025-06-28 04:37:11,955 - database - DEBUG - Closing database session
2025-06-28 04:37:11,984 - database - DEBUG - Creating new database session
2025-06-28 04:37:12,007 - database - ERROR - Error in database session: 401: Could not validate credentials
Traceback (most recent call last):
  File "C:\Users\Dhanush\FASTAPI\app\core\security.py", line 93, in decode_token
    payload = jwt.decode(token, settings.SECRET_KEY, algorithms=[settings.ALGORITHM])
  File "C:\Users\Dhanush\FASTAPI\venv\Lib\site-packages\jose\jwt.py", line 174, in decode
    _validate_claims(
    ~~~~~~~~~~~~~~~~^
        claims,
        ^^^^^^^
    ...<5 lines>...
        options=defaults,
        ^^^^^^^^^^^^^^^^^
    )
    ^
  File "C:\Users\Dhanush\FASTAPI\venv\Lib\site-packages\jose\jwt.py", line 497, in _validate_claims
    _validate_exp(claims, leeway=leeway)
    ~~~~~~~~~~~~~^^^^^^^^^^^^^^^^^^^^^^^
  File "C:\Users\Dhanush\FASTAPI\venv\Lib\site-packages\jose\jwt.py", line 331, in _validate_exp
    raise ExpiredSignatureError("Signature has expired.")
jose.exceptions.ExpiredSignatureError: Signature has expired.

During handling of the above exception, another exception occurred:

Traceback (most recent call last):
  File "C:\Users\Dhanush\FASTAPI\app\core\security.py", line 281, in get_current_user
    payload = decode_token(token)
  File "C:\Users\Dhanush\FASTAPI\app\core\security.py", line 98, in decode_token
    raise JWTError("Could not validate credentials")
jose.exceptions.JWTError: Could not validate credentials

During handling of the above exception, another exception occurred:

Traceback (most recent call last):
  File "C:\Users\Dhanush\FASTAPI\app\database\session.py", line 65, in get_db
    yield session
  File "C:\Users\Dhanush\FASTAPI\venv\Lib\site-packages\fastapi\routing.py", line 291, in app
    solved_result = await solve_dependencies(
                    ^^^^^^^^^^^^^^^^^^^^^^^^^
    ...<6 lines>...
    )
    ^
  File "C:\Users\Dhanush\FASTAPI\venv\Lib\site-packages\fastapi\dependencies\utils.py", line 638, in solve_dependencies
    solved = await call(**solved_result.values)
             ^^^^^^^^^^^^^^^^^^^^^^^^^^^^^^^^^^
  File "C:\Users\Dhanush\FASTAPI\app\core\security.py", line 326, in get_current_user
    raise credentials_exception
fastapi.exceptions.HTTPException: 401: Could not validate credentials
2025-06-28 04:37:12,030 - database - INFO - Session rolled back due to error
2025-06-28 04:37:12,031 - database - DEBUG - Closing database session
2025-06-28 04:37:31,787 - database - DEBUG - Creating new database session
2025-06-28 04:37:31,801 - database - ERROR - Error in database session: 401: Could not validate credentials
Traceback (most recent call last):
  File "C:\Users\Dhanush\FASTAPI\app\core\security.py", line 93, in decode_token
    payload = jwt.decode(token, settings.SECRET_KEY, algorithms=[settings.ALGORITHM])
  File "C:\Users\Dhanush\FASTAPI\venv\Lib\site-packages\jose\jwt.py", line 174, in decode
    _validate_claims(
    ~~~~~~~~~~~~~~~~^
        claims,
        ^^^^^^^
    ...<5 lines>...
        options=defaults,
        ^^^^^^^^^^^^^^^^^
    )
    ^
  File "C:\Users\Dhanush\FASTAPI\venv\Lib\site-packages\jose\jwt.py", line 497, in _validate_claims
    _validate_exp(claims, leeway=leeway)
    ~~~~~~~~~~~~~^^^^^^^^^^^^^^^^^^^^^^^
  File "C:\Users\Dhanush\FASTAPI\venv\Lib\site-packages\jose\jwt.py", line 331, in _validate_exp
    raise ExpiredSignatureError("Signature has expired.")
jose.exceptions.ExpiredSignatureError: Signature has expired.

During handling of the above exception, another exception occurred:

Traceback (most recent call last):
  File "C:\Users\Dhanush\FASTAPI\app\core\security.py", line 371, in get_user_from_service_or_user_token
    payload = decode_token(token)
  File "C:\Users\Dhanush\FASTAPI\app\core\security.py", line 98, in decode_token
    raise JWTError("Could not validate credentials")
jose.exceptions.JWTError: Could not validate credentials

During handling of the above exception, another exception occurred:

Traceback (most recent call last):
  File "C:\Users\Dhanush\FASTAPI\app\database\session.py", line 65, in get_db
    yield session
  File "C:\Users\Dhanush\FASTAPI\venv\Lib\site-packages\fastapi\routing.py", line 291, in app
    solved_result = await solve_dependencies(
                    ^^^^^^^^^^^^^^^^^^^^^^^^^
    ...<6 lines>...
    )
    ^
  File "C:\Users\Dhanush\FASTAPI\venv\Lib\site-packages\fastapi\dependencies\utils.py", line 638, in solve_dependencies
    solved = await call(**solved_result.values)
             ^^^^^^^^^^^^^^^^^^^^^^^^^^^^^^^^^^
  File "C:\Users\Dhanush\FASTAPI\app\core\security.py", line 424, in get_user_from_service_or_user_token
    raise HTTPException(
    ...<3 lines>...
    )
fastapi.exceptions.HTTPException: 401: Could not validate credentials
2025-06-28 04:37:31,813 - database - INFO - Session rolled back due to error
2025-06-28 04:37:31,816 - database - DEBUG - Closing database session
2025-06-28 04:37:31,879 - database - DEBUG - Creating new database session
2025-06-28 04:37:31,891 - database - ERROR - Error in database session: 401: Could not validate credentials
Traceback (most recent call last):
  File "C:\Users\Dhanush\FASTAPI\app\core\security.py", line 93, in decode_token
    payload = jwt.decode(token, settings.SECRET_KEY, algorithms=[settings.ALGORITHM])
  File "C:\Users\Dhanush\FASTAPI\venv\Lib\site-packages\jose\jwt.py", line 174, in decode
    _validate_claims(
    ~~~~~~~~~~~~~~~~^
        claims,
        ^^^^^^^
    ...<5 lines>...
        options=defaults,
        ^^^^^^^^^^^^^^^^^
    )
    ^
  File "C:\Users\Dhanush\FASTAPI\venv\Lib\site-packages\jose\jwt.py", line 497, in _validate_claims
    _validate_exp(claims, leeway=leeway)
    ~~~~~~~~~~~~~^^^^^^^^^^^^^^^^^^^^^^^
  File "C:\Users\Dhanush\FASTAPI\venv\Lib\site-packages\jose\jwt.py", line 331, in _validate_exp
    raise ExpiredSignatureError("Signature has expired.")
jose.exceptions.ExpiredSignatureError: Signature has expired.

During handling of the above exception, another exception occurred:

Traceback (most recent call last):
  File "C:\Users\Dhanush\FASTAPI\app\core\security.py", line 371, in get_user_from_service_or_user_token
    payload = decode_token(token)
  File "C:\Users\Dhanush\FASTAPI\app\core\security.py", line 98, in decode_token
    raise JWTError("Could not validate credentials")
jose.exceptions.JWTError: Could not validate credentials

During handling of the above exception, another exception occurred:

Traceback (most recent call last):
  File "C:\Users\Dhanush\FASTAPI\app\database\session.py", line 65, in get_db
    yield session
  File "C:\Users\Dhanush\FASTAPI\venv\Lib\site-packages\fastapi\routing.py", line 291, in app
    solved_result = await solve_dependencies(
                    ^^^^^^^^^^^^^^^^^^^^^^^^^
    ...<6 lines>...
    )
    ^
  File "C:\Users\Dhanush\FASTAPI\venv\Lib\site-packages\fastapi\dependencies\utils.py", line 638, in solve_dependencies
    solved = await call(**solved_result.values)
             ^^^^^^^^^^^^^^^^^^^^^^^^^^^^^^^^^^
  File "C:\Users\Dhanush\FASTAPI\app\core\security.py", line 424, in get_user_from_service_or_user_token
    raise HTTPException(
    ...<3 lines>...
    )
fastapi.exceptions.HTTPException: 401: Could not validate credentials
2025-06-28 04:37:31,898 - database - INFO - Session rolled back due to error
2025-06-28 04:37:31,898 - database - DEBUG - Closing database session
2025-06-28 04:37:31,917 - database - DEBUG - Creating new database session
2025-06-28 04:37:31,953 - database - ERROR - Error in database session: 401: Could not validate credentials
Traceback (most recent call last):
  File "C:\Users\Dhanush\FASTAPI\app\core\security.py", line 93, in decode_token
    payload = jwt.decode(token, settings.SECRET_KEY, algorithms=[settings.ALGORITHM])
  File "C:\Users\Dhanush\FASTAPI\venv\Lib\site-packages\jose\jwt.py", line 174, in decode
    _validate_claims(
    ~~~~~~~~~~~~~~~~^
        claims,
        ^^^^^^^
    ...<5 lines>...
        options=defaults,
        ^^^^^^^^^^^^^^^^^
    )
    ^
  File "C:\Users\Dhanush\FASTAPI\venv\Lib\site-packages\jose\jwt.py", line 497, in _validate_claims
    _validate_exp(claims, leeway=leeway)
    ~~~~~~~~~~~~~^^^^^^^^^^^^^^^^^^^^^^^
  File "C:\Users\Dhanush\FASTAPI\venv\Lib\site-packages\jose\jwt.py", line 331, in _validate_exp
    raise ExpiredSignatureError("Signature has expired.")
jose.exceptions.ExpiredSignatureError: Signature has expired.

During handling of the above exception, another exception occurred:

Traceback (most recent call last):
  File "C:\Users\Dhanush\FASTAPI\app\core\security.py", line 281, in get_current_user
    payload = decode_token(token)
  File "C:\Users\Dhanush\FASTAPI\app\core\security.py", line 98, in decode_token
    raise JWTError("Could not validate credentials")
jose.exceptions.JWTError: Could not validate credentials

During handling of the above exception, another exception occurred:

Traceback (most recent call last):
  File "C:\Users\Dhanush\FASTAPI\app\database\session.py", line 65, in get_db
    yield session
  File "C:\Users\Dhanush\FASTAPI\venv\Lib\site-packages\fastapi\routing.py", line 291, in app
    solved_result = await solve_dependencies(
                    ^^^^^^^^^^^^^^^^^^^^^^^^^
    ...<6 lines>...
    )
    ^
  File "C:\Users\Dhanush\FASTAPI\venv\Lib\site-packages\fastapi\dependencies\utils.py", line 638, in solve_dependencies
    solved = await call(**solved_result.values)
             ^^^^^^^^^^^^^^^^^^^^^^^^^^^^^^^^^^
  File "C:\Users\Dhanush\FASTAPI\app\core\security.py", line 326, in get_current_user
    raise credentials_exception
fastapi.exceptions.HTTPException: 401: Could not validate credentials
2025-06-28 04:37:31,981 - database - INFO - Session rolled back due to error
2025-06-28 04:37:31,983 - database - DEBUG - Closing database session
2025-06-28 04:37:32,018 - database - DEBUG - Creating new database session
2025-06-28 04:37:32,050 - database - ERROR - Error in database session: 401: Could not validate credentials
Traceback (most recent call last):
  File "C:\Users\Dhanush\FASTAPI\app\core\security.py", line 93, in decode_token
    payload = jwt.decode(token, settings.SECRET_KEY, algorithms=[settings.ALGORITHM])
  File "C:\Users\Dhanush\FASTAPI\venv\Lib\site-packages\jose\jwt.py", line 174, in decode
    _validate_claims(
    ~~~~~~~~~~~~~~~~^
        claims,
        ^^^^^^^
    ...<5 lines>...
        options=defaults,
        ^^^^^^^^^^^^^^^^^
    )
    ^
  File "C:\Users\Dhanush\FASTAPI\venv\Lib\site-packages\jose\jwt.py", line 497, in _validate_claims
    _validate_exp(claims, leeway=leeway)
    ~~~~~~~~~~~~~^^^^^^^^^^^^^^^^^^^^^^^
  File "C:\Users\Dhanush\FASTAPI\venv\Lib\site-packages\jose\jwt.py", line 331, in _validate_exp
    raise ExpiredSignatureError("Signature has expired.")
jose.exceptions.ExpiredSignatureError: Signature has expired.

During handling of the above exception, another exception occurred:

Traceback (most recent call last):
  File "C:\Users\Dhanush\FASTAPI\app\core\security.py", line 281, in get_current_user
    payload = decode_token(token)
  File "C:\Users\Dhanush\FASTAPI\app\core\security.py", line 98, in decode_token
    raise JWTError("Could not validate credentials")
jose.exceptions.JWTError: Could not validate credentials

During handling of the above exception, another exception occurred:

Traceback (most recent call last):
  File "C:\Users\Dhanush\FASTAPI\app\database\session.py", line 65, in get_db
    yield session
  File "C:\Users\Dhanush\FASTAPI\venv\Lib\site-packages\fastapi\routing.py", line 291, in app
    solved_result = await solve_dependencies(
                    ^^^^^^^^^^^^^^^^^^^^^^^^^
    ...<6 lines>...
    )
    ^
  File "C:\Users\Dhanush\FASTAPI\venv\Lib\site-packages\fastapi\dependencies\utils.py", line 638, in solve_dependencies
    solved = await call(**solved_result.values)
             ^^^^^^^^^^^^^^^^^^^^^^^^^^^^^^^^^^
  File "C:\Users\Dhanush\FASTAPI\app\core\security.py", line 326, in get_current_user
    raise credentials_exception
fastapi.exceptions.HTTPException: 401: Could not validate credentials
2025-06-28 04:37:32,057 - database - INFO - Session rolled back due to error
2025-06-28 04:37:32,062 - database - DEBUG - Closing database session
2025-06-28 04:37:32,121 - database - DEBUG - Creating new database session
2025-06-28 04:37:32,175 - database - ERROR - Error in database session: 401: Could not validate credentials
Traceback (most recent call last):
  File "C:\Users\Dhanush\FASTAPI\app\core\security.py", line 93, in decode_token
    payload = jwt.decode(token, settings.SECRET_KEY, algorithms=[settings.ALGORITHM])
  File "C:\Users\Dhanush\FASTAPI\venv\Lib\site-packages\jose\jwt.py", line 174, in decode
    _validate_claims(
    ~~~~~~~~~~~~~~~~^
        claims,
        ^^^^^^^
    ...<5 lines>...
        options=defaults,
        ^^^^^^^^^^^^^^^^^
    )
    ^
  File "C:\Users\Dhanush\FASTAPI\venv\Lib\site-packages\jose\jwt.py", line 497, in _validate_claims
    _validate_exp(claims, leeway=leeway)
    ~~~~~~~~~~~~~^^^^^^^^^^^^^^^^^^^^^^^
  File "C:\Users\Dhanush\FASTAPI\venv\Lib\site-packages\jose\jwt.py", line 331, in _validate_exp
    raise ExpiredSignatureError("Signature has expired.")
jose.exceptions.ExpiredSignatureError: Signature has expired.

During handling of the above exception, another exception occurred:

Traceback (most recent call last):
  File "C:\Users\Dhanush\FASTAPI\app\api\v1\endpoints\users.py", line 289, in refresh_access_token
    payload = decode_token(refresh_token)
  File "C:\Users\Dhanush\FASTAPI\app\core\security.py", line 98, in decode_token
    raise JWTError("Could not validate credentials")
jose.exceptions.JWTError: Could not validate credentials

During handling of the above exception, another exception occurred:

Traceback (most recent call last):
  File "C:\Users\Dhanush\FASTAPI\app\database\session.py", line 65, in get_db
    yield session
  File "C:\Users\Dhanush\FASTAPI\venv\Lib\site-packages\fastapi\routing.py", line 301, in app
    raw_response = await run_endpoint_function(
                   ^^^^^^^^^^^^^^^^^^^^^^^^^^^^
    ...<3 lines>...
    )
    ^
  File "C:\Users\Dhanush\FASTAPI\venv\Lib\site-packages\fastapi\routing.py", line 212, in run_endpoint_function
    return await dependant.call(**values)
           ^^^^^^^^^^^^^^^^^^^^^^^^^^^^^^
  File "C:\Users\Dhanush\FASTAPI\app\api\v1\endpoints\users.py", line 352, in refresh_access_token
    raise HTTPException(
    ...<3 lines>...
    )
fastapi.exceptions.HTTPException: 401: Could not validate credentials
2025-06-28 04:37:32,187 - database - INFO - Session rolled back due to error
2025-06-28 04:37:32,188 - database - DEBUG - Closing database session
2025-06-28 04:37:32,224 - database - DEBUG - Creating new database session
2025-06-28 04:37:32,246 - database - ERROR - Error in database session: 401: Could not validate credentials
Traceback (most recent call last):
  File "C:\Users\Dhanush\FASTAPI\app\core\security.py", line 93, in decode_token
    payload = jwt.decode(token, settings.SECRET_KEY, algorithms=[settings.ALGORITHM])
  File "C:\Users\Dhanush\FASTAPI\venv\Lib\site-packages\jose\jwt.py", line 174, in decode
    _validate_claims(
    ~~~~~~~~~~~~~~~~^
        claims,
        ^^^^^^^
    ...<5 lines>...
        options=defaults,
        ^^^^^^^^^^^^^^^^^
    )
    ^
  File "C:\Users\Dhanush\FASTAPI\venv\Lib\site-packages\jose\jwt.py", line 497, in _validate_claims
    _validate_exp(claims, leeway=leeway)
    ~~~~~~~~~~~~~^^^^^^^^^^^^^^^^^^^^^^^
  File "C:\Users\Dhanush\FASTAPI\venv\Lib\site-packages\jose\jwt.py", line 331, in _validate_exp
    raise ExpiredSignatureError("Signature has expired.")
jose.exceptions.ExpiredSignatureError: Signature has expired.

During handling of the above exception, another exception occurred:

Traceback (most recent call last):
  File "C:\Users\Dhanush\FASTAPI\app\api\v1\endpoints\users.py", line 289, in refresh_access_token
    payload = decode_token(refresh_token)
  File "C:\Users\Dhanush\FASTAPI\app\core\security.py", line 98, in decode_token
    raise JWTError("Could not validate credentials")
jose.exceptions.JWTError: Could not validate credentials

During handling of the above exception, another exception occurred:

Traceback (most recent call last):
  File "C:\Users\Dhanush\FASTAPI\app\database\session.py", line 65, in get_db
    yield session
  File "C:\Users\Dhanush\FASTAPI\venv\Lib\site-packages\fastapi\routing.py", line 301, in app
    raw_response = await run_endpoint_function(
                   ^^^^^^^^^^^^^^^^^^^^^^^^^^^^
    ...<3 lines>...
    )
    ^
  File "C:\Users\Dhanush\FASTAPI\venv\Lib\site-packages\fastapi\routing.py", line 212, in run_endpoint_function
    return await dependant.call(**values)
           ^^^^^^^^^^^^^^^^^^^^^^^^^^^^^^
  File "C:\Users\Dhanush\FASTAPI\app\api\v1\endpoints\users.py", line 352, in refresh_access_token
    raise HTTPException(
    ...<3 lines>...
    )
fastapi.exceptions.HTTPException: 401: Could not validate credentials
2025-06-28 04:37:32,266 - database - INFO - Session rolled back due to error
2025-06-28 04:37:32,272 - database - DEBUG - Closing database session
2025-06-28 04:37:38,706 - database - DEBUG - Creating new database session
2025-06-28 04:37:39,404 - database - DEBUG - Database session used successfully
2025-06-28 04:37:39,405 - database - DEBUG - Closing database session
2025-06-28 04:37:40,761 - database - DEBUG - Creating new database session
2025-06-28 04:37:40,852 - database - DEBUG - Database session used successfully
2025-06-28 04:37:40,853 - database - DEBUG - Closing database session
2025-06-28 04:37:40,864 - database - DEBUG - Creating new database session
2025-06-28 04:37:40,970 - database - DEBUG - Creating new database session
2025-06-28 04:37:41,072 - database - DEBUG - Database session used successfully
2025-06-28 04:37:41,083 - database - DEBUG - Closing database session
2025-06-28 04:37:41,455 - database - DEBUG - Creating new database session
2025-06-28 04:37:41,623 - database - DEBUG - Database session used successfully
2025-06-28 04:37:41,623 - database - DEBUG - Closing database session
2025-06-28 04:37:44,515 - database - DEBUG - Database session used successfully
2025-06-28 04:37:44,518 - database - DEBUG - Closing database session
2025-06-28 04:37:44,598 - database - DEBUG - Creating new database session
2025-06-28 04:37:44,963 - database - DEBUG - Creating new database session
2025-06-28 04:37:49,265 - database - DEBUG - Database session used successfully
2025-06-28 04:37:49,271 - database - DEBUG - Closing database session
2025-06-28 04:37:49,435 - database - DEBUG - Creating new database session
2025-06-28 04:37:49,547 - database - DEBUG - Database session used successfully
2025-06-28 04:37:49,549 - database - DEBUG - Closing database session
2025-06-28 04:38:14,575 - database - DEBUG - Creating new database session
2025-06-28 04:38:14,639 - database - DEBUG - Database session used successfully
2025-06-28 04:38:14,643 - database - DEBUG - Closing database session
2025-06-28 04:38:40,889 - database - DEBUG - Creating new database session
2025-06-28 04:38:40,903 - database - ERROR - Error in database session: 500: An error occurred while refreshing token.
Traceback (most recent call last):
  File "C:\Users\Dhanush\FASTAPI\app\api\v1\endpoints\users.py", line 310, in refresh_access_token
     raise HTTPException(
    ...<3 lines>...
    )
fastapi.exceptions.HTTPException: 401: Invalid or expired refresh token

During handling of the above exception, another exception occurred:

Traceback (most recent call last):
  File "C:\Users\Dhanush\FASTAPI\app\database\session.py", line 65, in get_db
    yield session
  File "C:\Users\Dhanush\FASTAPI\venv\Lib\site-packages\fastapi\routing.py", line 301, in app
    raw_response = await run_endpoint_function(
                   ^^^^^^^^^^^^^^^^^^^^^^^^^^^^
    ...<3 lines>...
    )
    ^
  File "C:\Users\Dhanush\FASTAPI\venv\Lib\site-packages\fastapi\routing.py", line 212, in run_endpoint_function
    return await dependant.call(**values)
           ^^^^^^^^^^^^^^^^^^^^^^^^^^^^^^
  File "C:\Users\Dhanush\FASTAPI\app\api\v1\endpoints\users.py", line 360, in refresh_access_token
    raise HTTPException(
    ...<2 lines>...
    )
fastapi.exceptions.HTTPException: 500: An error occurred while refreshing token.
2025-06-28 04:38:40,910 - database - INFO - Session rolled back due to error
2025-06-28 04:38:40,912 - database - DEBUG - Closing database session
2025-06-28 04:38:57,651 - database - DEBUG - Creating new database session
2025-06-28 04:38:57,718 - database - DEBUG - Database session used successfully
2025-06-28 04:38:57,719 - database - DEBUG - Closing database session
2025-06-28 04:39:19,613 - database - DEBUG - Creating new database session
2025-06-28 04:39:19,655 - database - DEBUG - Database session used successfully
2025-06-28 04:39:19,656 - database - DEBUG - Closing database session
2025-06-28 04:39:20,769 - database - DEBUG - Creating new database session
2025-06-28 04:39:20,820 - database - DEBUG - Database session used successfully
2025-06-28 04:39:20,821 - database - DEBUG - Closing database session
2025-06-28 04:39:25,588 - database - DEBUG - Creating new database session
2025-06-28 04:39:27,550 - database - DEBUG - Database session used successfully
2025-06-28 04:39:27,551 - database - DEBUG - Closing database session
2025-06-28 04:39:34,231 - database - DEBUG - Creating new database session
2025-06-28 04:39:34,264 - database - DEBUG - Database session used successfully
2025-06-28 04:39:34,266 - database - DEBUG - Closing database session
2025-06-28 04:39:34,336 - database - DEBUG - Database session used successfully
2025-06-28 04:39:34,339 - database - DEBUG - Closing database session
2025-06-28 23:31:46,929 - database - DEBUG - Creating new database session
2025-06-28 23:31:47,358 - database - DEBUG - Database session used successfully
2025-06-28 23:31:47,359 - database - DEBUG - Closing database session
2025-06-28 23:31:48,452 - database - DEBUG - Creating new database session
2025-06-28 23:31:48,486 - database - DEBUG - Database session used successfully
2025-06-28 23:31:48,486 - database - DEBUG - Closing database session
2025-06-28 23:31:48,535 - database - DEBUG - Creating new database session
2025-06-28 23:31:48,582 - database - DEBUG - Database session used successfully
2025-06-28 23:31:48,587 - database - DEBUG - Closing database session
2025-06-28 23:31:48,596 - database - DEBUG - Creating new database session
2025-06-28 23:31:50,231 - database - DEBUG - Database session used successfully
2025-06-28 23:31:50,235 - database - DEBUG - Closing database session
2025-06-28 23:31:50,265 - database - DEBUG - Creating new database session
2025-06-28 23:31:50,613 - database - DEBUG - Creating new database session
2025-06-28 23:31:51,019 - database - DEBUG - Creating new database session
2025-06-28 23:31:51,307 - database - DEBUG - Database session used successfully
2025-06-28 23:31:51,310 - database - DEBUG - Closing database session
2025-06-28 23:31:53,253 - database - DEBUG - Database session used successfully
2025-06-28 23:31:53,255 - database - DEBUG - Closing database session
2025-06-28 23:31:53,422 - database - DEBUG - Creating new database session
2025-06-28 23:31:53,499 - database - DEBUG - Database session used successfully
2025-06-28 23:31:53,500 - database - DEBUG - Closing database session
2025-06-28 23:31:59,828 - database - DEBUG - Creating new database session
2025-06-28 23:32:02,066 - database - DEBUG - Database session used successfully
2025-06-28 23:32:02,072 - database - DEBUG - Closing database session
2025-06-28 23:32:49,625 - database - DEBUG - Creating new database session
2025-06-28 23:32:49,630 - database - ERROR - Error in database session: 500: An error occurred while refreshing token.
Traceback (most recent call last):
  File "C:\Users\Dhanush\FASTAPI\app\api\v1\endpoints\users.py", line 310, in refresh_access_token
     raise HTTPException(
    ...<3 lines>...
    )
fastapi.exceptions.HTTPException: 401: Invalid or expired refresh token

During handling of the above exception, another exception occurred:

Traceback (most recent call last):
  File "C:\Users\Dhanush\FASTAPI\app\database\session.py", line 65, in get_db
    yield session
  File "C:\Users\Dhanush\FASTAPI\venv\Lib\site-packages\fastapi\routing.py", line 301, in app
    raw_response = await run_endpoint_function(
                   ^^^^^^^^^^^^^^^^^^^^^^^^^^^^
    ...<3 lines>...
    )
    ^
  File "C:\Users\Dhanush\FASTAPI\venv\Lib\site-packages\fastapi\routing.py", line 212, in run_endpoint_function
    return await dependant.call(**values)
           ^^^^^^^^^^^^^^^^^^^^^^^^^^^^^^
  File "C:\Users\Dhanush\FASTAPI\app\api\v1\endpoints\users.py", line 360, in refresh_access_token
    raise HTTPException(
    ...<2 lines>...
    )
fastapi.exceptions.HTTPException: 500: An error occurred while refreshing token.
2025-06-28 23:32:49,637 - database - INFO - Session rolled back due to error
2025-06-28 23:32:49,637 - database - DEBUG - Closing database session
2025-06-28 23:32:52,657 - database - DEBUG - Database session used successfully
2025-06-28 23:32:52,657 - database - DEBUG - Closing database session
2025-06-28 23:32:52,729 - database - DEBUG - Creating new database session
2025-06-28 23:32:52,745 - database - DEBUG - Database session used successfully
2025-06-28 23:32:52,747 - database - DEBUG - Closing database session
2025-06-28 23:32:52,767 - database - DEBUG - Creating new database session
2025-06-28 23:32:52,792 - database - DEBUG - Creating new database session
2025-06-28 23:32:52,814 - database - DEBUG - Database session used successfully
2025-06-28 23:32:52,816 - database - DEBUG - Closing database session
2025-06-28 23:32:53,238 - database - DEBUG - Creating new database session
2025-06-28 23:32:53,343 - database - DEBUG - Database session used successfully
2025-06-28 23:32:53,343 - database - DEBUG - Closing database session
2025-06-28 23:32:53,615 - database - DEBUG - Database session used successfully
2025-06-28 23:32:53,617 - database - DEBUG - Closing database session
2025-06-28 23:32:53,636 - database - DEBUG - Creating new database session
2025-06-28 23:32:54,270 - database - DEBUG - Creating new database session
2025-06-28 23:32:54,282 - database - DEBUG - Database session used successfully
2025-06-28 23:32:54,283 - database - DEBUG - Closing database session
2025-06-28 23:32:54,297 - database - DEBUG - Creating new database session
2025-06-28 23:32:54,316 - database - DEBUG - Database session used successfully
2025-06-28 23:32:54,317 - database - DEBUG - Closing database session
2025-06-28 23:33:09,265 - database - DEBUG - Creating new database session
2025-06-28 23:33:09,835 - database - DEBUG - Database session used successfully
2025-06-28 23:33:09,838 - database - DEBUG - Closing database session
2025-06-28 23:33:13,448 - database - DEBUG - Creating new database session
2025-06-28 23:33:15,238 - database - DEBUG - Database session used successfully
2025-06-28 23:33:15,239 - database - DEBUG - Closing database session
2025-06-28 23:33:18,083 - database - DEBUG - Creating new database session
2025-06-28 23:33:19,901 - database - DEBUG - Database session used successfully
2025-06-28 23:33:19,902 - database - DEBUG - Closing database session
2025-06-28 23:33:22,522 - database - DEBUG - Creating new database session
2025-06-28 23:33:24,089 - database - DEBUG - Database session used successfully
2025-06-28 23:33:24,090 - database - DEBUG - Closing database session
2025-06-28 23:34:10,553 - database - DEBUG - Creating new database session
2025-06-28 23:34:10,585 - database - DEBUG - Database session used successfully
2025-06-28 23:34:10,587 - database - DEBUG - Closing database session
2025-06-28 23:34:28,951 - database - DEBUG - Creating new database session
2025-06-28 23:34:28,956 - database - ERROR - Error in database session: 500: An error occurred while refreshing token.
Traceback (most recent call last):
  File "C:\Users\Dhanush\FASTAPI\app\api\v1\endpoints\users.py", line 310, in refresh_access_token
     raise HTTPException(
    ...<3 lines>...
    )
fastapi.exceptions.HTTPException: 401: Invalid or expired refresh token

During handling of the above exception, another exception occurred:

Traceback (most recent call last):
  File "C:\Users\Dhanush\FASTAPI\app\database\session.py", line 65, in get_db
    yield session
  File "C:\Users\Dhanush\FASTAPI\venv\Lib\site-packages\fastapi\routing.py", line 301, in app
    raw_response = await run_endpoint_function(
                   ^^^^^^^^^^^^^^^^^^^^^^^^^^^^
    ...<3 lines>...
    )
    ^
  File "C:\Users\Dhanush\FASTAPI\venv\Lib\site-packages\fastapi\routing.py", line 212, in run_endpoint_function
    return await dependant.call(**values)
           ^^^^^^^^^^^^^^^^^^^^^^^^^^^^^^
  File "C:\Users\Dhanush\FASTAPI\app\api\v1\endpoints\users.py", line 360, in refresh_access_token
    raise HTTPException(
    ...<2 lines>...
    )
fastapi.exceptions.HTTPException: 500: An error occurred while refreshing token.
2025-06-28 23:34:28,960 - database - INFO - Session rolled back due to error
2025-06-28 23:34:28,962 - database - DEBUG - Closing database session
2025-06-28 23:35:25,661 - database - DEBUG - Creating new database session
2025-06-28 23:35:25,681 - database - DEBUG - Database session used successfully
2025-06-28 23:35:25,682 - database - DEBUG - Closing database session
2025-06-28 23:36:42,518 - database - DEBUG - Creating new database session
2025-06-28 23:36:42,542 - database - DEBUG - Database session used successfully
2025-06-28 23:36:42,543 - database - DEBUG - Closing database session
2025-06-28 23:37:58,775 - database - DEBUG - Creating new database session
2025-06-28 23:37:58,792 - database - DEBUG - Database session used successfully
2025-06-28 23:37:58,793 - database - DEBUG - Closing database session
2025-06-28 23:39:15,694 - database - DEBUG - Creating new database session
2025-06-28 23:39:15,719 - database - DEBUG - Database session used successfully
2025-06-28 23:39:15,720 - database - DEBUG - Closing database session
2025-06-28 23:40:31,426 - database - DEBUG - Creating new database session
2025-06-28 23:40:31,453 - database - DEBUG - Database session used successfully
2025-06-28 23:40:31,454 - database - DEBUG - Closing database session
2025-06-28 23:41:48,163 - database - DEBUG - Creating new database session
2025-06-28 23:41:48,218 - database - DEBUG - Database session used successfully
2025-06-28 23:41:48,219 - database - DEBUG - Closing database session
2025-06-28 23:42:54,297 - database - DEBUG - Creating new database session
2025-06-28 23:42:54,331 - database - DEBUG - Database session used successfully
2025-06-28 23:42:54,332 - database - DEBUG - Closing database session
2025-06-28 23:43:05,873 - database - DEBUG - Creating new database session
2025-06-28 23:43:05,898 - database - DEBUG - Database session used successfully
2025-06-28 23:43:05,899 - database - DEBUG - Closing database session
2025-06-28 23:44:11,285 - database - DEBUG - Creating new database session
2025-06-28 23:44:11,300 - database - DEBUG - Database session used successfully
2025-06-28 23:44:11,311 - database - DEBUG - Closing database session
2025-06-28 23:44:22,761 - database - DEBUG - Creating new database session
2025-06-28 23:44:22,781 - database - DEBUG - Database session used successfully
2025-06-28 23:44:22,781 - database - DEBUG - Closing database session
2025-06-28 23:45:26,289 - database - DEBUG - Creating new database session
2025-06-28 23:45:26,319 - database - DEBUG - Database session used successfully
2025-06-28 23:45:26,322 - database - DEBUG - Closing database session
2025-06-28 23:45:39,802 - database - DEBUG - Creating new database session
2025-06-28 23:45:39,832 - database - DEBUG - Database session used successfully
2025-06-28 23:45:39,833 - database - DEBUG - Closing database session
2025-06-28 23:46:43,291 - database - DEBUG - Creating new database session
2025-06-28 23:46:43,309 - database - DEBUG - Database session used successfully
2025-06-28 23:46:43,309 - database - DEBUG - Closing database session
2025-06-28 23:46:58,434 - database - DEBUG - Creating new database session
2025-06-28 23:46:58,451 - database - DEBUG - Database session used successfully
2025-06-28 23:46:58,451 - database - DEBUG - Closing database session
2025-06-28 23:47:59,297 - database - DEBUG - Creating new database session
2025-06-28 23:47:59,335 - database - DEBUG - Database session used successfully
2025-06-28 23:47:59,336 - database - DEBUG - Closing database session
2025-06-28 23:48:14,203 - database - DEBUG - Creating new database session
2025-06-28 23:48:14,247 - database - DEBUG - Database session used successfully
2025-06-28 23:48:14,248 - database - DEBUG - Closing database session
2025-06-28 23:48:45,966 - database - DEBUG - Creating new database session
2025-06-28 23:48:45,972 - database - ERROR - Error in database session: 500: An error occurred while refreshing token.
Traceback (most recent call last):
  File "C:\Users\Dhanush\FASTAPI\app\api\v1\endpoints\users.py", line 310, in refresh_access_token
     raise HTTPException(
    ...<3 lines>...
    )
fastapi.exceptions.HTTPException: 401: Invalid or expired refresh token

During handling of the above exception, another exception occurred:

Traceback (most recent call last):
  File "C:\Users\Dhanush\FASTAPI\app\database\session.py", line 65, in get_db
    yield session
  File "C:\Users\Dhanush\FASTAPI\venv\Lib\site-packages\fastapi\routing.py", line 301, in app
    raw_response = await run_endpoint_function(
                   ^^^^^^^^^^^^^^^^^^^^^^^^^^^^
    ...<3 lines>...
    )
    ^
  File "C:\Users\Dhanush\FASTAPI\venv\Lib\site-packages\fastapi\routing.py", line 212, in run_endpoint_function
    return await dependant.call(**values)
           ^^^^^^^^^^^^^^^^^^^^^^^^^^^^^^
  File "C:\Users\Dhanush\FASTAPI\app\api\v1\endpoints\users.py", line 360, in refresh_access_token
    raise HTTPException(
    ...<2 lines>...
    )
fastapi.exceptions.HTTPException: 500: An error occurred while refreshing token.
2025-06-28 23:48:45,975 - database - INFO - Session rolled back due to error
2025-06-28 23:48:45,976 - database - DEBUG - Closing database session
2025-06-28 23:48:52,502 - database - DEBUG - Database session used successfully
2025-06-28 23:48:52,505 - database - DEBUG - Closing database session
